ERROR 2018-01-30 14:39:38,736 exception 26922 140588113236800 Internal Server Error: /xml/load
Traceback (most recent call last):
  File "/home/taoshu/anaconda3/lib/python3.5/site-packages/django/core/handlers/exception.py", line 41, in inner
    response = get_response(request)
  File "/home/taoshu/anaconda3/lib/python3.5/site-packages/django/utils/deprecation.py", line 138, in __call__
    response = self.process_request(request)
  File "/home/taoshu/anaconda3/lib/python3.5/site-packages/django/middleware/common.py", line 62, in process_request
    if self.should_redirect_with_slash(request):
  File "/home/taoshu/anaconda3/lib/python3.5/site-packages/django/middleware/common.py", line 80, in should_redirect_with_slash
    not is_valid_path(request.path_info, urlconf) and
  File "/home/taoshu/anaconda3/lib/python3.5/site-packages/django/urls/base.py", line 158, in is_valid_path
    resolve(path, urlconf)
  File "/home/taoshu/anaconda3/lib/python3.5/site-packages/django/urls/base.py", line 27, in resolve
    return get_resolver(urlconf).resolve(path)
  File "/home/taoshu/anaconda3/lib/python3.5/site-packages/django/urls/resolvers.py", line 362, in resolve
    for pattern in self.url_patterns:
  File "/home/taoshu/anaconda3/lib/python3.5/site-packages/django/utils/functional.py", line 35, in __get__
    res = instance.__dict__[self.name] = self.func(instance)
  File "/home/taoshu/anaconda3/lib/python3.5/site-packages/django/urls/resolvers.py", line 405, in url_patterns
    patterns = getattr(self.urlconf_module, "urlpatterns", self.urlconf_module)
  File "/home/taoshu/anaconda3/lib/python3.5/site-packages/django/utils/functional.py", line 35, in __get__
    res = instance.__dict__[self.name] = self.func(instance)
  File "/home/taoshu/anaconda3/lib/python3.5/site-packages/django/urls/resolvers.py", line 398, in urlconf_module
    return import_module(self.urlconf_name)
  File "/home/taoshu/anaconda3/lib/python3.5/importlib/__init__.py", line 126, in import_module
    return _bootstrap._gcd_import(name[level:], package, level)
  File "<frozen importlib._bootstrap>", line 986, in _gcd_import
  File "<frozen importlib._bootstrap>", line 969, in _find_and_load
  File "<frozen importlib._bootstrap>", line 958, in _find_and_load_unlocked
  File "<frozen importlib._bootstrap>", line 673, in _load_unlocked
  File "<frozen importlib._bootstrap_external>", line 662, in exec_module
  File "<frozen importlib._bootstrap>", line 222, in _call_with_frames_removed
  File "/home/taoshu/tzb_databrain/engine/db_engine/db_engine/urls.py", line 20, in <module>
    from db_engine import component, hive_reader, io, robotx_spark, xml, executor, self_defined_feature, feature_combine, \
  File "/home/taoshu/tzb_databrain/engine/db_engine/db_engine/component.py", line 11, in <module>
    from executor.components.RobotXSpark import RobotXSpark
  File "/home/taoshu/tzb_databrain/engine/db_engine/executor/components/RobotXSpark.py", line 6, in <module>
    from F_SETTING import HDFS_URL
ImportError: cannot import name 'HDFS_URL'
ERROR 2018-01-30 14:39:38,756 exception 26922 140588113236800 Internal Server Error: /xml/load
Traceback (most recent call last):
  File "/home/taoshu/anaconda3/lib/python3.5/site-packages/django/core/handlers/exception.py", line 41, in inner
    response = get_response(request)
  File "/home/taoshu/anaconda3/lib/python3.5/site-packages/django/utils/deprecation.py", line 138, in __call__
    response = self.process_request(request)
  File "/home/taoshu/anaconda3/lib/python3.5/site-packages/django/middleware/common.py", line 62, in process_request
    if self.should_redirect_with_slash(request):
  File "/home/taoshu/anaconda3/lib/python3.5/site-packages/django/middleware/common.py", line 80, in should_redirect_with_slash
    not is_valid_path(request.path_info, urlconf) and
  File "/home/taoshu/anaconda3/lib/python3.5/site-packages/django/urls/base.py", line 158, in is_valid_path
    resolve(path, urlconf)
  File "/home/taoshu/anaconda3/lib/python3.5/site-packages/django/urls/base.py", line 27, in resolve
    return get_resolver(urlconf).resolve(path)
  File "/home/taoshu/anaconda3/lib/python3.5/site-packages/django/urls/resolvers.py", line 362, in resolve
    for pattern in self.url_patterns:
  File "/home/taoshu/anaconda3/lib/python3.5/site-packages/django/utils/functional.py", line 35, in __get__
    res = instance.__dict__[self.name] = self.func(instance)
  File "/home/taoshu/anaconda3/lib/python3.5/site-packages/django/urls/resolvers.py", line 405, in url_patterns
    patterns = getattr(self.urlconf_module, "urlpatterns", self.urlconf_module)
  File "/home/taoshu/anaconda3/lib/python3.5/site-packages/django/utils/functional.py", line 35, in __get__
    res = instance.__dict__[self.name] = self.func(instance)
  File "/home/taoshu/anaconda3/lib/python3.5/site-packages/django/urls/resolvers.py", line 398, in urlconf_module
    return import_module(self.urlconf_name)
  File "/home/taoshu/anaconda3/lib/python3.5/importlib/__init__.py", line 126, in import_module
    return _bootstrap._gcd_import(name[level:], package, level)
  File "<frozen importlib._bootstrap>", line 986, in _gcd_import
  File "<frozen importlib._bootstrap>", line 969, in _find_and_load
  File "<frozen importlib._bootstrap>", line 958, in _find_and_load_unlocked
  File "<frozen importlib._bootstrap>", line 673, in _load_unlocked
  File "<frozen importlib._bootstrap_external>", line 662, in exec_module
  File "<frozen importlib._bootstrap>", line 222, in _call_with_frames_removed
  File "/home/taoshu/tzb_databrain/engine/db_engine/db_engine/urls.py", line 20, in <module>
    from db_engine import component, hive_reader, io, robotx_spark, xml, executor, self_defined_feature, feature_combine, \
  File "/home/taoshu/tzb_databrain/engine/db_engine/db_engine/component.py", line 11, in <module>
    from executor.components.RobotXSpark import RobotXSpark
  File "/home/taoshu/tzb_databrain/engine/db_engine/executor/components/RobotXSpark.py", line 6, in <module>
    from F_SETTING import HDFS_URL
ImportError: cannot import name 'HDFS_URL'

During handling of the above exception, another exception occurred:

Traceback (most recent call last):
  File "/home/taoshu/anaconda3/lib/python3.5/site-packages/django/core/handlers/exception.py", line 41, in inner
    response = get_response(request)
  File "/home/taoshu/anaconda3/lib/python3.5/site-packages/django/utils/deprecation.py", line 140, in __call__
    response = self.get_response(request)
  File "/home/taoshu/anaconda3/lib/python3.5/site-packages/django/core/handlers/exception.py", line 43, in inner
    response = response_for_exception(request, exc)
  File "/home/taoshu/anaconda3/lib/python3.5/site-packages/django/core/handlers/exception.py", line 93, in response_for_exception
    response = handle_uncaught_exception(request, get_resolver(get_urlconf()), sys.exc_info())
  File "/home/taoshu/anaconda3/lib/python3.5/site-packages/django/core/handlers/exception.py", line 142, in handle_uncaught_exception
    callback, param_dict = resolver.resolve_error_handler(500)
  File "/home/taoshu/anaconda3/lib/python3.5/site-packages/django/urls/resolvers.py", line 418, in resolve_error_handler
    callback = getattr(self.urlconf_module, 'handler%s' % view_type, None)
  File "/home/taoshu/anaconda3/lib/python3.5/site-packages/django/utils/functional.py", line 35, in __get__
    res = instance.__dict__[self.name] = self.func(instance)
  File "/home/taoshu/anaconda3/lib/python3.5/site-packages/django/urls/resolvers.py", line 398, in urlconf_module
    return import_module(self.urlconf_name)
  File "/home/taoshu/anaconda3/lib/python3.5/importlib/__init__.py", line 126, in import_module
    return _bootstrap._gcd_import(name[level:], package, level)
  File "<frozen importlib._bootstrap>", line 986, in _gcd_import
  File "<frozen importlib._bootstrap>", line 969, in _find_and_load
  File "<frozen importlib._bootstrap>", line 958, in _find_and_load_unlocked
  File "<frozen importlib._bootstrap>", line 673, in _load_unlocked
  File "<frozen importlib._bootstrap_external>", line 662, in exec_module
  File "<frozen importlib._bootstrap>", line 222, in _call_with_frames_removed
  File "/home/taoshu/tzb_databrain/engine/db_engine/db_engine/urls.py", line 20, in <module>
    from db_engine import component, hive_reader, io, robotx_spark, xml, executor, self_defined_feature, feature_combine, \
  File "/home/taoshu/tzb_databrain/engine/db_engine/db_engine/component.py", line 11, in <module>
    from executor.components.RobotXSpark import RobotXSpark
  File "/home/taoshu/tzb_databrain/engine/db_engine/executor/components/RobotXSpark.py", line 6, in <module>
    from F_SETTING import HDFS_URL
ImportError: cannot import name 'HDFS_URL'
ERROR 2018-01-30 14:39:38,758 exception 26922 140588113236800 Internal Server Error: /xml/load
Traceback (most recent call last):
  File "/home/taoshu/anaconda3/lib/python3.5/site-packages/django/core/handlers/exception.py", line 41, in inner
    response = get_response(request)
  File "/home/taoshu/anaconda3/lib/python3.5/site-packages/django/utils/deprecation.py", line 138, in __call__
    response = self.process_request(request)
  File "/home/taoshu/anaconda3/lib/python3.5/site-packages/django/middleware/common.py", line 62, in process_request
    if self.should_redirect_with_slash(request):
  File "/home/taoshu/anaconda3/lib/python3.5/site-packages/django/middleware/common.py", line 80, in should_redirect_with_slash
    not is_valid_path(request.path_info, urlconf) and
  File "/home/taoshu/anaconda3/lib/python3.5/site-packages/django/urls/base.py", line 158, in is_valid_path
    resolve(path, urlconf)
  File "/home/taoshu/anaconda3/lib/python3.5/site-packages/django/urls/base.py", line 27, in resolve
    return get_resolver(urlconf).resolve(path)
  File "/home/taoshu/anaconda3/lib/python3.5/site-packages/django/urls/resolvers.py", line 362, in resolve
    for pattern in self.url_patterns:
  File "/home/taoshu/anaconda3/lib/python3.5/site-packages/django/utils/functional.py", line 35, in __get__
    res = instance.__dict__[self.name] = self.func(instance)
  File "/home/taoshu/anaconda3/lib/python3.5/site-packages/django/urls/resolvers.py", line 405, in url_patterns
    patterns = getattr(self.urlconf_module, "urlpatterns", self.urlconf_module)
  File "/home/taoshu/anaconda3/lib/python3.5/site-packages/django/utils/functional.py", line 35, in __get__
    res = instance.__dict__[self.name] = self.func(instance)
  File "/home/taoshu/anaconda3/lib/python3.5/site-packages/django/urls/resolvers.py", line 398, in urlconf_module
    return import_module(self.urlconf_name)
  File "/home/taoshu/anaconda3/lib/python3.5/importlib/__init__.py", line 126, in import_module
    return _bootstrap._gcd_import(name[level:], package, level)
  File "<frozen importlib._bootstrap>", line 986, in _gcd_import
  File "<frozen importlib._bootstrap>", line 969, in _find_and_load
  File "<frozen importlib._bootstrap>", line 958, in _find_and_load_unlocked
  File "<frozen importlib._bootstrap>", line 673, in _load_unlocked
  File "<frozen importlib._bootstrap_external>", line 662, in exec_module
  File "<frozen importlib._bootstrap>", line 222, in _call_with_frames_removed
  File "/home/taoshu/tzb_databrain/engine/db_engine/db_engine/urls.py", line 20, in <module>
    from db_engine import component, hive_reader, io, robotx_spark, xml, executor, self_defined_feature, feature_combine, \
  File "/home/taoshu/tzb_databrain/engine/db_engine/db_engine/component.py", line 11, in <module>
    from executor.components.RobotXSpark import RobotXSpark
  File "/home/taoshu/tzb_databrain/engine/db_engine/executor/components/RobotXSpark.py", line 6, in <module>
    from F_SETTING import HDFS_URL
ImportError: cannot import name 'HDFS_URL'

During handling of the above exception, another exception occurred:

Traceback (most recent call last):
  File "/home/taoshu/anaconda3/lib/python3.5/site-packages/django/core/handlers/exception.py", line 41, in inner
    response = get_response(request)
  File "/home/taoshu/anaconda3/lib/python3.5/site-packages/django/utils/deprecation.py", line 140, in __call__
    response = self.get_response(request)
  File "/home/taoshu/anaconda3/lib/python3.5/site-packages/django/core/handlers/exception.py", line 43, in inner
    response = response_for_exception(request, exc)
  File "/home/taoshu/anaconda3/lib/python3.5/site-packages/django/core/handlers/exception.py", line 93, in response_for_exception
    response = handle_uncaught_exception(request, get_resolver(get_urlconf()), sys.exc_info())
  File "/home/taoshu/anaconda3/lib/python3.5/site-packages/django/core/handlers/exception.py", line 142, in handle_uncaught_exception
    callback, param_dict = resolver.resolve_error_handler(500)
  File "/home/taoshu/anaconda3/lib/python3.5/site-packages/django/urls/resolvers.py", line 418, in resolve_error_handler
    callback = getattr(self.urlconf_module, 'handler%s' % view_type, None)
  File "/home/taoshu/anaconda3/lib/python3.5/site-packages/django/utils/functional.py", line 35, in __get__
    res = instance.__dict__[self.name] = self.func(instance)
  File "/home/taoshu/anaconda3/lib/python3.5/site-packages/django/urls/resolvers.py", line 398, in urlconf_module
    return import_module(self.urlconf_name)
  File "/home/taoshu/anaconda3/lib/python3.5/importlib/__init__.py", line 126, in import_module
    return _bootstrap._gcd_import(name[level:], package, level)
  File "<frozen importlib._bootstrap>", line 986, in _gcd_import
  File "<frozen importlib._bootstrap>", line 969, in _find_and_load
  File "<frozen importlib._bootstrap>", line 958, in _find_and_load_unlocked
  File "<frozen importlib._bootstrap>", line 673, in _load_unlocked
  File "<frozen importlib._bootstrap_external>", line 662, in exec_module
  File "<frozen importlib._bootstrap>", line 222, in _call_with_frames_removed
  File "/home/taoshu/tzb_databrain/engine/db_engine/db_engine/urls.py", line 20, in <module>
    from db_engine import component, hive_reader, io, robotx_spark, xml, executor, self_defined_feature, feature_combine, \
  File "/home/taoshu/tzb_databrain/engine/db_engine/db_engine/component.py", line 11, in <module>
    from executor.components.RobotXSpark import RobotXSpark
  File "/home/taoshu/tzb_databrain/engine/db_engine/executor/components/RobotXSpark.py", line 6, in <module>
    from F_SETTING import HDFS_URL
ImportError: cannot import name 'HDFS_URL'

During handling of the above exception, another exception occurred:

Traceback (most recent call last):
  File "/home/taoshu/anaconda3/lib/python3.5/site-packages/django/core/handlers/exception.py", line 41, in inner
    response = get_response(request)
  File "/home/taoshu/anaconda3/lib/python3.5/site-packages/django/utils/deprecation.py", line 140, in __call__
    response = self.get_response(request)
  File "/home/taoshu/anaconda3/lib/python3.5/site-packages/django/core/handlers/exception.py", line 43, in inner
    response = response_for_exception(request, exc)
  File "/home/taoshu/anaconda3/lib/python3.5/site-packages/django/core/handlers/exception.py", line 93, in response_for_exception
    response = handle_uncaught_exception(request, get_resolver(get_urlconf()), sys.exc_info())
  File "/home/taoshu/anaconda3/lib/python3.5/site-packages/django/core/handlers/exception.py", line 142, in handle_uncaught_exception
    callback, param_dict = resolver.resolve_error_handler(500)
  File "/home/taoshu/anaconda3/lib/python3.5/site-packages/django/urls/resolvers.py", line 418, in resolve_error_handler
    callback = getattr(self.urlconf_module, 'handler%s' % view_type, None)
  File "/home/taoshu/anaconda3/lib/python3.5/site-packages/django/utils/functional.py", line 35, in __get__
    res = instance.__dict__[self.name] = self.func(instance)
  File "/home/taoshu/anaconda3/lib/python3.5/site-packages/django/urls/resolvers.py", line 398, in urlconf_module
    return import_module(self.urlconf_name)
  File "/home/taoshu/anaconda3/lib/python3.5/importlib/__init__.py", line 126, in import_module
    return _bootstrap._gcd_import(name[level:], package, level)
  File "<frozen importlib._bootstrap>", line 986, in _gcd_import
  File "<frozen importlib._bootstrap>", line 969, in _find_and_load
  File "<frozen importlib._bootstrap>", line 958, in _find_and_load_unlocked
  File "<frozen importlib._bootstrap>", line 673, in _load_unlocked
  File "<frozen importlib._bootstrap_external>", line 662, in exec_module
  File "<frozen importlib._bootstrap>", line 222, in _call_with_frames_removed
  File "/home/taoshu/tzb_databrain/engine/db_engine/db_engine/urls.py", line 20, in <module>
    from db_engine import component, hive_reader, io, robotx_spark, xml, executor, self_defined_feature, feature_combine, \
  File "/home/taoshu/tzb_databrain/engine/db_engine/db_engine/component.py", line 11, in <module>
    from executor.components.RobotXSpark import RobotXSpark
  File "/home/taoshu/tzb_databrain/engine/db_engine/executor/components/RobotXSpark.py", line 6, in <module>
    from F_SETTING import HDFS_URL
ImportError: cannot import name 'HDFS_URL'
ERROR 2018-01-30 14:39:38,760 exception 26922 140588113236800 Internal Server Error: /xml/load
Traceback (most recent call last):
  File "/home/taoshu/anaconda3/lib/python3.5/site-packages/django/core/handlers/exception.py", line 41, in inner
    response = get_response(request)
  File "/home/taoshu/anaconda3/lib/python3.5/site-packages/django/utils/deprecation.py", line 138, in __call__
    response = self.process_request(request)
  File "/home/taoshu/anaconda3/lib/python3.5/site-packages/django/middleware/common.py", line 62, in process_request
    if self.should_redirect_with_slash(request):
  File "/home/taoshu/anaconda3/lib/python3.5/site-packages/django/middleware/common.py", line 80, in should_redirect_with_slash
    not is_valid_path(request.path_info, urlconf) and
  File "/home/taoshu/anaconda3/lib/python3.5/site-packages/django/urls/base.py", line 158, in is_valid_path
    resolve(path, urlconf)
  File "/home/taoshu/anaconda3/lib/python3.5/site-packages/django/urls/base.py", line 27, in resolve
    return get_resolver(urlconf).resolve(path)
  File "/home/taoshu/anaconda3/lib/python3.5/site-packages/django/urls/resolvers.py", line 362, in resolve
    for pattern in self.url_patterns:
  File "/home/taoshu/anaconda3/lib/python3.5/site-packages/django/utils/functional.py", line 35, in __get__
    res = instance.__dict__[self.name] = self.func(instance)
  File "/home/taoshu/anaconda3/lib/python3.5/site-packages/django/urls/resolvers.py", line 405, in url_patterns
    patterns = getattr(self.urlconf_module, "urlpatterns", self.urlconf_module)
  File "/home/taoshu/anaconda3/lib/python3.5/site-packages/django/utils/functional.py", line 35, in __get__
    res = instance.__dict__[self.name] = self.func(instance)
  File "/home/taoshu/anaconda3/lib/python3.5/site-packages/django/urls/resolvers.py", line 398, in urlconf_module
    return import_module(self.urlconf_name)
  File "/home/taoshu/anaconda3/lib/python3.5/importlib/__init__.py", line 126, in import_module
    return _bootstrap._gcd_import(name[level:], package, level)
  File "<frozen importlib._bootstrap>", line 986, in _gcd_import
  File "<frozen importlib._bootstrap>", line 969, in _find_and_load
  File "<frozen importlib._bootstrap>", line 958, in _find_and_load_unlocked
  File "<frozen importlib._bootstrap>", line 673, in _load_unlocked
  File "<frozen importlib._bootstrap_external>", line 662, in exec_module
  File "<frozen importlib._bootstrap>", line 222, in _call_with_frames_removed
  File "/home/taoshu/tzb_databrain/engine/db_engine/db_engine/urls.py", line 20, in <module>
    from db_engine import component, hive_reader, io, robotx_spark, xml, executor, self_defined_feature, feature_combine, \
  File "/home/taoshu/tzb_databrain/engine/db_engine/db_engine/component.py", line 11, in <module>
    from executor.components.RobotXSpark import RobotXSpark
  File "/home/taoshu/tzb_databrain/engine/db_engine/executor/components/RobotXSpark.py", line 6, in <module>
    from F_SETTING import HDFS_URL
ImportError: cannot import name 'HDFS_URL'

During handling of the above exception, another exception occurred:

Traceback (most recent call last):
  File "/home/taoshu/anaconda3/lib/python3.5/site-packages/django/core/handlers/exception.py", line 41, in inner
    response = get_response(request)
  File "/home/taoshu/anaconda3/lib/python3.5/site-packages/django/utils/deprecation.py", line 140, in __call__
    response = self.get_response(request)
  File "/home/taoshu/anaconda3/lib/python3.5/site-packages/django/core/handlers/exception.py", line 43, in inner
    response = response_for_exception(request, exc)
  File "/home/taoshu/anaconda3/lib/python3.5/site-packages/django/core/handlers/exception.py", line 93, in response_for_exception
    response = handle_uncaught_exception(request, get_resolver(get_urlconf()), sys.exc_info())
  File "/home/taoshu/anaconda3/lib/python3.5/site-packages/django/core/handlers/exception.py", line 142, in handle_uncaught_exception
    callback, param_dict = resolver.resolve_error_handler(500)
  File "/home/taoshu/anaconda3/lib/python3.5/site-packages/django/urls/resolvers.py", line 418, in resolve_error_handler
    callback = getattr(self.urlconf_module, 'handler%s' % view_type, None)
  File "/home/taoshu/anaconda3/lib/python3.5/site-packages/django/utils/functional.py", line 35, in __get__
    res = instance.__dict__[self.name] = self.func(instance)
  File "/home/taoshu/anaconda3/lib/python3.5/site-packages/django/urls/resolvers.py", line 398, in urlconf_module
    return import_module(self.urlconf_name)
  File "/home/taoshu/anaconda3/lib/python3.5/importlib/__init__.py", line 126, in import_module
    return _bootstrap._gcd_import(name[level:], package, level)
  File "<frozen importlib._bootstrap>", line 986, in _gcd_import
  File "<frozen importlib._bootstrap>", line 969, in _find_and_load
  File "<frozen importlib._bootstrap>", line 958, in _find_and_load_unlocked
  File "<frozen importlib._bootstrap>", line 673, in _load_unlocked
  File "<frozen importlib._bootstrap_external>", line 662, in exec_module
  File "<frozen importlib._bootstrap>", line 222, in _call_with_frames_removed
  File "/home/taoshu/tzb_databrain/engine/db_engine/db_engine/urls.py", line 20, in <module>
    from db_engine import component, hive_reader, io, robotx_spark, xml, executor, self_defined_feature, feature_combine, \
  File "/home/taoshu/tzb_databrain/engine/db_engine/db_engine/component.py", line 11, in <module>
    from executor.components.RobotXSpark import RobotXSpark
  File "/home/taoshu/tzb_databrain/engine/db_engine/executor/components/RobotXSpark.py", line 6, in <module>
    from F_SETTING import HDFS_URL
ImportError: cannot import name 'HDFS_URL'

During handling of the above exception, another exception occurred:

Traceback (most recent call last):
  File "/home/taoshu/anaconda3/lib/python3.5/site-packages/django/core/handlers/exception.py", line 41, in inner
    response = get_response(request)
  File "/home/taoshu/anaconda3/lib/python3.5/site-packages/django/utils/deprecation.py", line 140, in __call__
    response = self.get_response(request)
  File "/home/taoshu/anaconda3/lib/python3.5/site-packages/django/core/handlers/exception.py", line 43, in inner
    response = response_for_exception(request, exc)
  File "/home/taoshu/anaconda3/lib/python3.5/site-packages/django/core/handlers/exception.py", line 93, in response_for_exception
    response = handle_uncaught_exception(request, get_resolver(get_urlconf()), sys.exc_info())
  File "/home/taoshu/anaconda3/lib/python3.5/site-packages/django/core/handlers/exception.py", line 142, in handle_uncaught_exception
    callback, param_dict = resolver.resolve_error_handler(500)
  File "/home/taoshu/anaconda3/lib/python3.5/site-packages/django/urls/resolvers.py", line 418, in resolve_error_handler
    callback = getattr(self.urlconf_module, 'handler%s' % view_type, None)
  File "/home/taoshu/anaconda3/lib/python3.5/site-packages/django/utils/functional.py", line 35, in __get__
    res = instance.__dict__[self.name] = self.func(instance)
  File "/home/taoshu/anaconda3/lib/python3.5/site-packages/django/urls/resolvers.py", line 398, in urlconf_module
    return import_module(self.urlconf_name)
  File "/home/taoshu/anaconda3/lib/python3.5/importlib/__init__.py", line 126, in import_module
    return _bootstrap._gcd_import(name[level:], package, level)
  File "<frozen importlib._bootstrap>", line 986, in _gcd_import
  File "<frozen importlib._bootstrap>", line 969, in _find_and_load
  File "<frozen importlib._bootstrap>", line 958, in _find_and_load_unlocked
  File "<frozen importlib._bootstrap>", line 673, in _load_unlocked
  File "<frozen importlib._bootstrap_external>", line 662, in exec_module
  File "<frozen importlib._bootstrap>", line 222, in _call_with_frames_removed
  File "/home/taoshu/tzb_databrain/engine/db_engine/db_engine/urls.py", line 20, in <module>
    from db_engine import component, hive_reader, io, robotx_spark, xml, executor, self_defined_feature, feature_combine, \
  File "/home/taoshu/tzb_databrain/engine/db_engine/db_engine/component.py", line 11, in <module>
    from executor.components.RobotXSpark import RobotXSpark
  File "/home/taoshu/tzb_databrain/engine/db_engine/executor/components/RobotXSpark.py", line 6, in <module>
    from F_SETTING import HDFS_URL
ImportError: cannot import name 'HDFS_URL'

During handling of the above exception, another exception occurred:

Traceback (most recent call last):
  File "/home/taoshu/anaconda3/lib/python3.5/site-packages/django/core/handlers/exception.py", line 41, in inner
    response = get_response(request)
  File "/home/taoshu/anaconda3/lib/python3.5/site-packages/django/utils/deprecation.py", line 140, in __call__
    response = self.get_response(request)
  File "/home/taoshu/anaconda3/lib/python3.5/site-packages/django/core/handlers/exception.py", line 43, in inner
    response = response_for_exception(request, exc)
  File "/home/taoshu/anaconda3/lib/python3.5/site-packages/django/core/handlers/exception.py", line 93, in response_for_exception
    response = handle_uncaught_exception(request, get_resolver(get_urlconf()), sys.exc_info())
  File "/home/taoshu/anaconda3/lib/python3.5/site-packages/django/core/handlers/exception.py", line 142, in handle_uncaught_exception
    callback, param_dict = resolver.resolve_error_handler(500)
  File "/home/taoshu/anaconda3/lib/python3.5/site-packages/django/urls/resolvers.py", line 418, in resolve_error_handler
    callback = getattr(self.urlconf_module, 'handler%s' % view_type, None)
  File "/home/taoshu/anaconda3/lib/python3.5/site-packages/django/utils/functional.py", line 35, in __get__
    res = instance.__dict__[self.name] = self.func(instance)
  File "/home/taoshu/anaconda3/lib/python3.5/site-packages/django/urls/resolvers.py", line 398, in urlconf_module
    return import_module(self.urlconf_name)
  File "/home/taoshu/anaconda3/lib/python3.5/importlib/__init__.py", line 126, in import_module
    return _bootstrap._gcd_import(name[level:], package, level)
  File "<frozen importlib._bootstrap>", line 986, in _gcd_import
  File "<frozen importlib._bootstrap>", line 969, in _find_and_load
  File "<frozen importlib._bootstrap>", line 958, in _find_and_load_unlocked
  File "<frozen importlib._bootstrap>", line 673, in _load_unlocked
  File "<frozen importlib._bootstrap_external>", line 662, in exec_module
  File "<frozen importlib._bootstrap>", line 222, in _call_with_frames_removed
  File "/home/taoshu/tzb_databrain/engine/db_engine/db_engine/urls.py", line 20, in <module>
    from db_engine import component, hive_reader, io, robotx_spark, xml, executor, self_defined_feature, feature_combine, \
  File "/home/taoshu/tzb_databrain/engine/db_engine/db_engine/component.py", line 11, in <module>
    from executor.components.RobotXSpark import RobotXSpark
  File "/home/taoshu/tzb_databrain/engine/db_engine/executor/components/RobotXSpark.py", line 6, in <module>
    from F_SETTING import HDFS_URL
ImportError: cannot import name 'HDFS_URL'
ERROR 2018-01-30 14:39:38,779 exception 26922 140588113236800 Internal Server Error: /executor/current_exec
Traceback (most recent call last):
  File "/home/taoshu/anaconda3/lib/python3.5/site-packages/django/core/handlers/exception.py", line 41, in inner
    response = get_response(request)
  File "/home/taoshu/anaconda3/lib/python3.5/site-packages/django/utils/deprecation.py", line 138, in __call__
    response = self.process_request(request)
  File "/home/taoshu/anaconda3/lib/python3.5/site-packages/django/middleware/common.py", line 62, in process_request
    if self.should_redirect_with_slash(request):
  File "/home/taoshu/anaconda3/lib/python3.5/site-packages/django/middleware/common.py", line 80, in should_redirect_with_slash
    not is_valid_path(request.path_info, urlconf) and
  File "/home/taoshu/anaconda3/lib/python3.5/site-packages/django/urls/base.py", line 158, in is_valid_path
    resolve(path, urlconf)
  File "/home/taoshu/anaconda3/lib/python3.5/site-packages/django/urls/base.py", line 27, in resolve
    return get_resolver(urlconf).resolve(path)
  File "/home/taoshu/anaconda3/lib/python3.5/site-packages/django/urls/resolvers.py", line 362, in resolve
    for pattern in self.url_patterns:
  File "/home/taoshu/anaconda3/lib/python3.5/site-packages/django/utils/functional.py", line 35, in __get__
    res = instance.__dict__[self.name] = self.func(instance)
  File "/home/taoshu/anaconda3/lib/python3.5/site-packages/django/urls/resolvers.py", line 405, in url_patterns
    patterns = getattr(self.urlconf_module, "urlpatterns", self.urlconf_module)
  File "/home/taoshu/anaconda3/lib/python3.5/site-packages/django/utils/functional.py", line 35, in __get__
    res = instance.__dict__[self.name] = self.func(instance)
  File "/home/taoshu/anaconda3/lib/python3.5/site-packages/django/urls/resolvers.py", line 398, in urlconf_module
    return import_module(self.urlconf_name)
  File "/home/taoshu/anaconda3/lib/python3.5/importlib/__init__.py", line 126, in import_module
    return _bootstrap._gcd_import(name[level:], package, level)
  File "<frozen importlib._bootstrap>", line 986, in _gcd_import
  File "<frozen importlib._bootstrap>", line 969, in _find_and_load
  File "<frozen importlib._bootstrap>", line 958, in _find_and_load_unlocked
  File "<frozen importlib._bootstrap>", line 673, in _load_unlocked
  File "<frozen importlib._bootstrap_external>", line 662, in exec_module
  File "<frozen importlib._bootstrap>", line 222, in _call_with_frames_removed
  File "/home/taoshu/tzb_databrain/engine/db_engine/db_engine/urls.py", line 20, in <module>
    from db_engine import component, hive_reader, io, robotx_spark, xml, executor, self_defined_feature, feature_combine, \
  File "/home/taoshu/tzb_databrain/engine/db_engine/db_engine/component.py", line 11, in <module>
    from executor.components.RobotXSpark import RobotXSpark
  File "/home/taoshu/tzb_databrain/engine/db_engine/executor/components/RobotXSpark.py", line 6, in <module>
    from F_SETTING import HDFS_URL
ImportError: cannot import name 'HDFS_URL'
ERROR 2018-01-30 14:39:38,780 exception 26922 140588113236800 Internal Server Error: /executor/current_exec
Traceback (most recent call last):
  File "/home/taoshu/anaconda3/lib/python3.5/site-packages/django/core/handlers/exception.py", line 41, in inner
    response = get_response(request)
  File "/home/taoshu/anaconda3/lib/python3.5/site-packages/django/utils/deprecation.py", line 138, in __call__
    response = self.process_request(request)
  File "/home/taoshu/anaconda3/lib/python3.5/site-packages/django/middleware/common.py", line 62, in process_request
    if self.should_redirect_with_slash(request):
  File "/home/taoshu/anaconda3/lib/python3.5/site-packages/django/middleware/common.py", line 80, in should_redirect_with_slash
    not is_valid_path(request.path_info, urlconf) and
  File "/home/taoshu/anaconda3/lib/python3.5/site-packages/django/urls/base.py", line 158, in is_valid_path
    resolve(path, urlconf)
  File "/home/taoshu/anaconda3/lib/python3.5/site-packages/django/urls/base.py", line 27, in resolve
    return get_resolver(urlconf).resolve(path)
  File "/home/taoshu/anaconda3/lib/python3.5/site-packages/django/urls/resolvers.py", line 362, in resolve
    for pattern in self.url_patterns:
  File "/home/taoshu/anaconda3/lib/python3.5/site-packages/django/utils/functional.py", line 35, in __get__
    res = instance.__dict__[self.name] = self.func(instance)
  File "/home/taoshu/anaconda3/lib/python3.5/site-packages/django/urls/resolvers.py", line 405, in url_patterns
    patterns = getattr(self.urlconf_module, "urlpatterns", self.urlconf_module)
  File "/home/taoshu/anaconda3/lib/python3.5/site-packages/django/utils/functional.py", line 35, in __get__
    res = instance.__dict__[self.name] = self.func(instance)
  File "/home/taoshu/anaconda3/lib/python3.5/site-packages/django/urls/resolvers.py", line 398, in urlconf_module
    return import_module(self.urlconf_name)
  File "/home/taoshu/anaconda3/lib/python3.5/importlib/__init__.py", line 126, in import_module
    return _bootstrap._gcd_import(name[level:], package, level)
  File "<frozen importlib._bootstrap>", line 986, in _gcd_import
  File "<frozen importlib._bootstrap>", line 969, in _find_and_load
  File "<frozen importlib._bootstrap>", line 958, in _find_and_load_unlocked
  File "<frozen importlib._bootstrap>", line 673, in _load_unlocked
  File "<frozen importlib._bootstrap_external>", line 662, in exec_module
  File "<frozen importlib._bootstrap>", line 222, in _call_with_frames_removed
  File "/home/taoshu/tzb_databrain/engine/db_engine/db_engine/urls.py", line 20, in <module>
    from db_engine import component, hive_reader, io, robotx_spark, xml, executor, self_defined_feature, feature_combine, \
  File "/home/taoshu/tzb_databrain/engine/db_engine/db_engine/component.py", line 11, in <module>
    from executor.components.RobotXSpark import RobotXSpark
  File "/home/taoshu/tzb_databrain/engine/db_engine/executor/components/RobotXSpark.py", line 6, in <module>
    from F_SETTING import HDFS_URL
ImportError: cannot import name 'HDFS_URL'

During handling of the above exception, another exception occurred:

Traceback (most recent call last):
  File "/home/taoshu/anaconda3/lib/python3.5/site-packages/django/core/handlers/exception.py", line 41, in inner
    response = get_response(request)
  File "/home/taoshu/anaconda3/lib/python3.5/site-packages/django/utils/deprecation.py", line 140, in __call__
    response = self.get_response(request)
  File "/home/taoshu/anaconda3/lib/python3.5/site-packages/django/core/handlers/exception.py", line 43, in inner
    response = response_for_exception(request, exc)
  File "/home/taoshu/anaconda3/lib/python3.5/site-packages/django/core/handlers/exception.py", line 93, in response_for_exception
    response = handle_uncaught_exception(request, get_resolver(get_urlconf()), sys.exc_info())
  File "/home/taoshu/anaconda3/lib/python3.5/site-packages/django/core/handlers/exception.py", line 142, in handle_uncaught_exception
    callback, param_dict = resolver.resolve_error_handler(500)
  File "/home/taoshu/anaconda3/lib/python3.5/site-packages/django/urls/resolvers.py", line 418, in resolve_error_handler
    callback = getattr(self.urlconf_module, 'handler%s' % view_type, None)
  File "/home/taoshu/anaconda3/lib/python3.5/site-packages/django/utils/functional.py", line 35, in __get__
    res = instance.__dict__[self.name] = self.func(instance)
  File "/home/taoshu/anaconda3/lib/python3.5/site-packages/django/urls/resolvers.py", line 398, in urlconf_module
    return import_module(self.urlconf_name)
  File "/home/taoshu/anaconda3/lib/python3.5/importlib/__init__.py", line 126, in import_module
    return _bootstrap._gcd_import(name[level:], package, level)
  File "<frozen importlib._bootstrap>", line 986, in _gcd_import
  File "<frozen importlib._bootstrap>", line 969, in _find_and_load
  File "<frozen importlib._bootstrap>", line 958, in _find_and_load_unlocked
  File "<frozen importlib._bootstrap>", line 673, in _load_unlocked
  File "<frozen importlib._bootstrap_external>", line 662, in exec_module
  File "<frozen importlib._bootstrap>", line 222, in _call_with_frames_removed
  File "/home/taoshu/tzb_databrain/engine/db_engine/db_engine/urls.py", line 20, in <module>
    from db_engine import component, hive_reader, io, robotx_spark, xml, executor, self_defined_feature, feature_combine, \
  File "/home/taoshu/tzb_databrain/engine/db_engine/db_engine/component.py", line 11, in <module>
    from executor.components.RobotXSpark import RobotXSpark
  File "/home/taoshu/tzb_databrain/engine/db_engine/executor/components/RobotXSpark.py", line 6, in <module>
    from F_SETTING import HDFS_URL
ImportError: cannot import name 'HDFS_URL'
ERROR 2018-01-30 14:39:38,782 exception 26922 140588113236800 Internal Server Error: /executor/current_exec
Traceback (most recent call last):
  File "/home/taoshu/anaconda3/lib/python3.5/site-packages/django/core/handlers/exception.py", line 41, in inner
    response = get_response(request)
  File "/home/taoshu/anaconda3/lib/python3.5/site-packages/django/utils/deprecation.py", line 138, in __call__
    response = self.process_request(request)
  File "/home/taoshu/anaconda3/lib/python3.5/site-packages/django/middleware/common.py", line 62, in process_request
    if self.should_redirect_with_slash(request):
  File "/home/taoshu/anaconda3/lib/python3.5/site-packages/django/middleware/common.py", line 80, in should_redirect_with_slash
    not is_valid_path(request.path_info, urlconf) and
  File "/home/taoshu/anaconda3/lib/python3.5/site-packages/django/urls/base.py", line 158, in is_valid_path
    resolve(path, urlconf)
  File "/home/taoshu/anaconda3/lib/python3.5/site-packages/django/urls/base.py", line 27, in resolve
    return get_resolver(urlconf).resolve(path)
  File "/home/taoshu/anaconda3/lib/python3.5/site-packages/django/urls/resolvers.py", line 362, in resolve
    for pattern in self.url_patterns:
  File "/home/taoshu/anaconda3/lib/python3.5/site-packages/django/utils/functional.py", line 35, in __get__
    res = instance.__dict__[self.name] = self.func(instance)
  File "/home/taoshu/anaconda3/lib/python3.5/site-packages/django/urls/resolvers.py", line 405, in url_patterns
    patterns = getattr(self.urlconf_module, "urlpatterns", self.urlconf_module)
  File "/home/taoshu/anaconda3/lib/python3.5/site-packages/django/utils/functional.py", line 35, in __get__
    res = instance.__dict__[self.name] = self.func(instance)
  File "/home/taoshu/anaconda3/lib/python3.5/site-packages/django/urls/resolvers.py", line 398, in urlconf_module
    return import_module(self.urlconf_name)
  File "/home/taoshu/anaconda3/lib/python3.5/importlib/__init__.py", line 126, in import_module
    return _bootstrap._gcd_import(name[level:], package, level)
  File "<frozen importlib._bootstrap>", line 986, in _gcd_import
  File "<frozen importlib._bootstrap>", line 969, in _find_and_load
  File "<frozen importlib._bootstrap>", line 958, in _find_and_load_unlocked
  File "<frozen importlib._bootstrap>", line 673, in _load_unlocked
  File "<frozen importlib._bootstrap_external>", line 662, in exec_module
  File "<frozen importlib._bootstrap>", line 222, in _call_with_frames_removed
  File "/home/taoshu/tzb_databrain/engine/db_engine/db_engine/urls.py", line 20, in <module>
    from db_engine import component, hive_reader, io, robotx_spark, xml, executor, self_defined_feature, feature_combine, \
  File "/home/taoshu/tzb_databrain/engine/db_engine/db_engine/component.py", line 11, in <module>
    from executor.components.RobotXSpark import RobotXSpark
  File "/home/taoshu/tzb_databrain/engine/db_engine/executor/components/RobotXSpark.py", line 6, in <module>
    from F_SETTING import HDFS_URL
ImportError: cannot import name 'HDFS_URL'

During handling of the above exception, another exception occurred:

Traceback (most recent call last):
  File "/home/taoshu/anaconda3/lib/python3.5/site-packages/django/core/handlers/exception.py", line 41, in inner
    response = get_response(request)
  File "/home/taoshu/anaconda3/lib/python3.5/site-packages/django/utils/deprecation.py", line 140, in __call__
    response = self.get_response(request)
  File "/home/taoshu/anaconda3/lib/python3.5/site-packages/django/core/handlers/exception.py", line 43, in inner
    response = response_for_exception(request, exc)
  File "/home/taoshu/anaconda3/lib/python3.5/site-packages/django/core/handlers/exception.py", line 93, in response_for_exception
    response = handle_uncaught_exception(request, get_resolver(get_urlconf()), sys.exc_info())
  File "/home/taoshu/anaconda3/lib/python3.5/site-packages/django/core/handlers/exception.py", line 142, in handle_uncaught_exception
    callback, param_dict = resolver.resolve_error_handler(500)
  File "/home/taoshu/anaconda3/lib/python3.5/site-packages/django/urls/resolvers.py", line 418, in resolve_error_handler
    callback = getattr(self.urlconf_module, 'handler%s' % view_type, None)
  File "/home/taoshu/anaconda3/lib/python3.5/site-packages/django/utils/functional.py", line 35, in __get__
    res = instance.__dict__[self.name] = self.func(instance)
  File "/home/taoshu/anaconda3/lib/python3.5/site-packages/django/urls/resolvers.py", line 398, in urlconf_module
    return import_module(self.urlconf_name)
  File "/home/taoshu/anaconda3/lib/python3.5/importlib/__init__.py", line 126, in import_module
    return _bootstrap._gcd_import(name[level:], package, level)
  File "<frozen importlib._bootstrap>", line 986, in _gcd_import
  File "<frozen importlib._bootstrap>", line 969, in _find_and_load
  File "<frozen importlib._bootstrap>", line 958, in _find_and_load_unlocked
  File "<frozen importlib._bootstrap>", line 673, in _load_unlocked
  File "<frozen importlib._bootstrap_external>", line 662, in exec_module
  File "<frozen importlib._bootstrap>", line 222, in _call_with_frames_removed
  File "/home/taoshu/tzb_databrain/engine/db_engine/db_engine/urls.py", line 20, in <module>
    from db_engine import component, hive_reader, io, robotx_spark, xml, executor, self_defined_feature, feature_combine, \
  File "/home/taoshu/tzb_databrain/engine/db_engine/db_engine/component.py", line 11, in <module>
    from executor.components.RobotXSpark import RobotXSpark
  File "/home/taoshu/tzb_databrain/engine/db_engine/executor/components/RobotXSpark.py", line 6, in <module>
    from F_SETTING import HDFS_URL
ImportError: cannot import name 'HDFS_URL'

During handling of the above exception, another exception occurred:

Traceback (most recent call last):
  File "/home/taoshu/anaconda3/lib/python3.5/site-packages/django/core/handlers/exception.py", line 41, in inner
    response = get_response(request)
  File "/home/taoshu/anaconda3/lib/python3.5/site-packages/django/utils/deprecation.py", line 140, in __call__
    response = self.get_response(request)
  File "/home/taoshu/anaconda3/lib/python3.5/site-packages/django/core/handlers/exception.py", line 43, in inner
    response = response_for_exception(request, exc)
  File "/home/taoshu/anaconda3/lib/python3.5/site-packages/django/core/handlers/exception.py", line 93, in response_for_exception
    response = handle_uncaught_exception(request, get_resolver(get_urlconf()), sys.exc_info())
  File "/home/taoshu/anaconda3/lib/python3.5/site-packages/django/core/handlers/exception.py", line 142, in handle_uncaught_exception
    callback, param_dict = resolver.resolve_error_handler(500)
  File "/home/taoshu/anaconda3/lib/python3.5/site-packages/django/urls/resolvers.py", line 418, in resolve_error_handler
    callback = getattr(self.urlconf_module, 'handler%s' % view_type, None)
  File "/home/taoshu/anaconda3/lib/python3.5/site-packages/django/utils/functional.py", line 35, in __get__
    res = instance.__dict__[self.name] = self.func(instance)
  File "/home/taoshu/anaconda3/lib/python3.5/site-packages/django/urls/resolvers.py", line 398, in urlconf_module
    return import_module(self.urlconf_name)
  File "/home/taoshu/anaconda3/lib/python3.5/importlib/__init__.py", line 126, in import_module
    return _bootstrap._gcd_import(name[level:], package, level)
  File "<frozen importlib._bootstrap>", line 986, in _gcd_import
  File "<frozen importlib._bootstrap>", line 969, in _find_and_load
  File "<frozen importlib._bootstrap>", line 958, in _find_and_load_unlocked
  File "<frozen importlib._bootstrap>", line 673, in _load_unlocked
  File "<frozen importlib._bootstrap_external>", line 662, in exec_module
  File "<frozen importlib._bootstrap>", line 222, in _call_with_frames_removed
  File "/home/taoshu/tzb_databrain/engine/db_engine/db_engine/urls.py", line 20, in <module>
    from db_engine import component, hive_reader, io, robotx_spark, xml, executor, self_defined_feature, feature_combine, \
  File "/home/taoshu/tzb_databrain/engine/db_engine/db_engine/component.py", line 11, in <module>
    from executor.components.RobotXSpark import RobotXSpark
  File "/home/taoshu/tzb_databrain/engine/db_engine/executor/components/RobotXSpark.py", line 6, in <module>
    from F_SETTING import HDFS_URL
ImportError: cannot import name 'HDFS_URL'
ERROR 2018-01-30 14:39:38,784 exception 26922 140588113236800 Internal Server Error: /executor/current_exec
Traceback (most recent call last):
  File "/home/taoshu/anaconda3/lib/python3.5/site-packages/django/core/handlers/exception.py", line 41, in inner
    response = get_response(request)
  File "/home/taoshu/anaconda3/lib/python3.5/site-packages/django/utils/deprecation.py", line 138, in __call__
    response = self.process_request(request)
  File "/home/taoshu/anaconda3/lib/python3.5/site-packages/django/middleware/common.py", line 62, in process_request
    if self.should_redirect_with_slash(request):
  File "/home/taoshu/anaconda3/lib/python3.5/site-packages/django/middleware/common.py", line 80, in should_redirect_with_slash
    not is_valid_path(request.path_info, urlconf) and
  File "/home/taoshu/anaconda3/lib/python3.5/site-packages/django/urls/base.py", line 158, in is_valid_path
    resolve(path, urlconf)
  File "/home/taoshu/anaconda3/lib/python3.5/site-packages/django/urls/base.py", line 27, in resolve
    return get_resolver(urlconf).resolve(path)
  File "/home/taoshu/anaconda3/lib/python3.5/site-packages/django/urls/resolvers.py", line 362, in resolve
    for pattern in self.url_patterns:
  File "/home/taoshu/anaconda3/lib/python3.5/site-packages/django/utils/functional.py", line 35, in __get__
    res = instance.__dict__[self.name] = self.func(instance)
  File "/home/taoshu/anaconda3/lib/python3.5/site-packages/django/urls/resolvers.py", line 405, in url_patterns
    patterns = getattr(self.urlconf_module, "urlpatterns", self.urlconf_module)
  File "/home/taoshu/anaconda3/lib/python3.5/site-packages/django/utils/functional.py", line 35, in __get__
    res = instance.__dict__[self.name] = self.func(instance)
  File "/home/taoshu/anaconda3/lib/python3.5/site-packages/django/urls/resolvers.py", line 398, in urlconf_module
    return import_module(self.urlconf_name)
  File "/home/taoshu/anaconda3/lib/python3.5/importlib/__init__.py", line 126, in import_module
    return _bootstrap._gcd_import(name[level:], package, level)
  File "<frozen importlib._bootstrap>", line 986, in _gcd_import
  File "<frozen importlib._bootstrap>", line 969, in _find_and_load
  File "<frozen importlib._bootstrap>", line 958, in _find_and_load_unlocked
  File "<frozen importlib._bootstrap>", line 673, in _load_unlocked
  File "<frozen importlib._bootstrap_external>", line 662, in exec_module
  File "<frozen importlib._bootstrap>", line 222, in _call_with_frames_removed
  File "/home/taoshu/tzb_databrain/engine/db_engine/db_engine/urls.py", line 20, in <module>
    from db_engine import component, hive_reader, io, robotx_spark, xml, executor, self_defined_feature, feature_combine, \
  File "/home/taoshu/tzb_databrain/engine/db_engine/db_engine/component.py", line 11, in <module>
    from executor.components.RobotXSpark import RobotXSpark
  File "/home/taoshu/tzb_databrain/engine/db_engine/executor/components/RobotXSpark.py", line 6, in <module>
    from F_SETTING import HDFS_URL
ImportError: cannot import name 'HDFS_URL'

During handling of the above exception, another exception occurred:

Traceback (most recent call last):
  File "/home/taoshu/anaconda3/lib/python3.5/site-packages/django/core/handlers/exception.py", line 41, in inner
    response = get_response(request)
  File "/home/taoshu/anaconda3/lib/python3.5/site-packages/django/utils/deprecation.py", line 140, in __call__
    response = self.get_response(request)
  File "/home/taoshu/anaconda3/lib/python3.5/site-packages/django/core/handlers/exception.py", line 43, in inner
    response = response_for_exception(request, exc)
  File "/home/taoshu/anaconda3/lib/python3.5/site-packages/django/core/handlers/exception.py", line 93, in response_for_exception
    response = handle_uncaught_exception(request, get_resolver(get_urlconf()), sys.exc_info())
  File "/home/taoshu/anaconda3/lib/python3.5/site-packages/django/core/handlers/exception.py", line 142, in handle_uncaught_exception
    callback, param_dict = resolver.resolve_error_handler(500)
  File "/home/taoshu/anaconda3/lib/python3.5/site-packages/django/urls/resolvers.py", line 418, in resolve_error_handler
    callback = getattr(self.urlconf_module, 'handler%s' % view_type, None)
  File "/home/taoshu/anaconda3/lib/python3.5/site-packages/django/utils/functional.py", line 35, in __get__
    res = instance.__dict__[self.name] = self.func(instance)
  File "/home/taoshu/anaconda3/lib/python3.5/site-packages/django/urls/resolvers.py", line 398, in urlconf_module
    return import_module(self.urlconf_name)
  File "/home/taoshu/anaconda3/lib/python3.5/importlib/__init__.py", line 126, in import_module
    return _bootstrap._gcd_import(name[level:], package, level)
  File "<frozen importlib._bootstrap>", line 986, in _gcd_import
  File "<frozen importlib._bootstrap>", line 969, in _find_and_load
  File "<frozen importlib._bootstrap>", line 958, in _find_and_load_unlocked
  File "<frozen importlib._bootstrap>", line 673, in _load_unlocked
  File "<frozen importlib._bootstrap_external>", line 662, in exec_module
  File "<frozen importlib._bootstrap>", line 222, in _call_with_frames_removed
  File "/home/taoshu/tzb_databrain/engine/db_engine/db_engine/urls.py", line 20, in <module>
    from db_engine import component, hive_reader, io, robotx_spark, xml, executor, self_defined_feature, feature_combine, \
  File "/home/taoshu/tzb_databrain/engine/db_engine/db_engine/component.py", line 11, in <module>
    from executor.components.RobotXSpark import RobotXSpark
  File "/home/taoshu/tzb_databrain/engine/db_engine/executor/components/RobotXSpark.py", line 6, in <module>
    from F_SETTING import HDFS_URL
ImportError: cannot import name 'HDFS_URL'

During handling of the above exception, another exception occurred:

Traceback (most recent call last):
  File "/home/taoshu/anaconda3/lib/python3.5/site-packages/django/core/handlers/exception.py", line 41, in inner
    response = get_response(request)
  File "/home/taoshu/anaconda3/lib/python3.5/site-packages/django/utils/deprecation.py", line 140, in __call__
    response = self.get_response(request)
  File "/home/taoshu/anaconda3/lib/python3.5/site-packages/django/core/handlers/exception.py", line 43, in inner
    response = response_for_exception(request, exc)
  File "/home/taoshu/anaconda3/lib/python3.5/site-packages/django/core/handlers/exception.py", line 93, in response_for_exception
    response = handle_uncaught_exception(request, get_resolver(get_urlconf()), sys.exc_info())
  File "/home/taoshu/anaconda3/lib/python3.5/site-packages/django/core/handlers/exception.py", line 142, in handle_uncaught_exception
    callback, param_dict = resolver.resolve_error_handler(500)
  File "/home/taoshu/anaconda3/lib/python3.5/site-packages/django/urls/resolvers.py", line 418, in resolve_error_handler
    callback = getattr(self.urlconf_module, 'handler%s' % view_type, None)
  File "/home/taoshu/anaconda3/lib/python3.5/site-packages/django/utils/functional.py", line 35, in __get__
    res = instance.__dict__[self.name] = self.func(instance)
  File "/home/taoshu/anaconda3/lib/python3.5/site-packages/django/urls/resolvers.py", line 398, in urlconf_module
    return import_module(self.urlconf_name)
  File "/home/taoshu/anaconda3/lib/python3.5/importlib/__init__.py", line 126, in import_module
    return _bootstrap._gcd_import(name[level:], package, level)
  File "<frozen importlib._bootstrap>", line 986, in _gcd_import
  File "<frozen importlib._bootstrap>", line 969, in _find_and_load
  File "<frozen importlib._bootstrap>", line 958, in _find_and_load_unlocked
  File "<frozen importlib._bootstrap>", line 673, in _load_unlocked
  File "<frozen importlib._bootstrap_external>", line 662, in exec_module
  File "<frozen importlib._bootstrap>", line 222, in _call_with_frames_removed
  File "/home/taoshu/tzb_databrain/engine/db_engine/db_engine/urls.py", line 20, in <module>
    from db_engine import component, hive_reader, io, robotx_spark, xml, executor, self_defined_feature, feature_combine, \
  File "/home/taoshu/tzb_databrain/engine/db_engine/db_engine/component.py", line 11, in <module>
    from executor.components.RobotXSpark import RobotXSpark
  File "/home/taoshu/tzb_databrain/engine/db_engine/executor/components/RobotXSpark.py", line 6, in <module>
    from F_SETTING import HDFS_URL
ImportError: cannot import name 'HDFS_URL'

During handling of the above exception, another exception occurred:

Traceback (most recent call last):
  File "/home/taoshu/anaconda3/lib/python3.5/site-packages/django/core/handlers/exception.py", line 41, in inner
    response = get_response(request)
  File "/home/taoshu/anaconda3/lib/python3.5/site-packages/django/utils/deprecation.py", line 140, in __call__
    response = self.get_response(request)
  File "/home/taoshu/anaconda3/lib/python3.5/site-packages/django/core/handlers/exception.py", line 43, in inner
    response = response_for_exception(request, exc)
  File "/home/taoshu/anaconda3/lib/python3.5/site-packages/django/core/handlers/exception.py", line 93, in response_for_exception
    response = handle_uncaught_exception(request, get_resolver(get_urlconf()), sys.exc_info())
  File "/home/taoshu/anaconda3/lib/python3.5/site-packages/django/core/handlers/exception.py", line 142, in handle_uncaught_exception
    callback, param_dict = resolver.resolve_error_handler(500)
  File "/home/taoshu/anaconda3/lib/python3.5/site-packages/django/urls/resolvers.py", line 418, in resolve_error_handler
    callback = getattr(self.urlconf_module, 'handler%s' % view_type, None)
  File "/home/taoshu/anaconda3/lib/python3.5/site-packages/django/utils/functional.py", line 35, in __get__
    res = instance.__dict__[self.name] = self.func(instance)
  File "/home/taoshu/anaconda3/lib/python3.5/site-packages/django/urls/resolvers.py", line 398, in urlconf_module
    return import_module(self.urlconf_name)
  File "/home/taoshu/anaconda3/lib/python3.5/importlib/__init__.py", line 126, in import_module
    return _bootstrap._gcd_import(name[level:], package, level)
  File "<frozen importlib._bootstrap>", line 986, in _gcd_import
  File "<frozen importlib._bootstrap>", line 969, in _find_and_load
  File "<frozen importlib._bootstrap>", line 958, in _find_and_load_unlocked
  File "<frozen importlib._bootstrap>", line 673, in _load_unlocked
  File "<frozen importlib._bootstrap_external>", line 662, in exec_module
  File "<frozen importlib._bootstrap>", line 222, in _call_with_frames_removed
  File "/home/taoshu/tzb_databrain/engine/db_engine/db_engine/urls.py", line 20, in <module>
    from db_engine import component, hive_reader, io, robotx_spark, xml, executor, self_defined_feature, feature_combine, \
  File "/home/taoshu/tzb_databrain/engine/db_engine/db_engine/component.py", line 11, in <module>
    from executor.components.RobotXSpark import RobotXSpark
  File "/home/taoshu/tzb_databrain/engine/db_engine/executor/components/RobotXSpark.py", line 6, in <module>
    from F_SETTING import HDFS_URL
ImportError: cannot import name 'HDFS_URL'
