ERROR 2018-03-21 15:00:03,610 exception 2017 140483420955608 Internal Server Error: /mydata/csv_upload
Traceback (most recent call last):
  File "/home/taoshu/anaconda3/lib/python3.5/site-packages/django/core/handlers/exception.py", line 41, in inner
    response = get_response(request)
  File "/home/taoshu/anaconda3/lib/python3.5/site-packages/django/utils/deprecation.py", line 138, in __call__
    response = self.process_request(request)
  File "/home/taoshu/anaconda3/lib/python3.5/site-packages/django/middleware/common.py", line 62, in process_request
    if self.should_redirect_with_slash(request):
  File "/home/taoshu/anaconda3/lib/python3.5/site-packages/django/middleware/common.py", line 80, in should_redirect_with_slash
    not is_valid_path(request.path_info, urlconf) and
  File "/home/taoshu/anaconda3/lib/python3.5/site-packages/django/urls/base.py", line 158, in is_valid_path
    resolve(path, urlconf)
  File "/home/taoshu/anaconda3/lib/python3.5/site-packages/django/urls/base.py", line 27, in resolve
    return get_resolver(urlconf).resolve(path)
  File "/home/taoshu/anaconda3/lib/python3.5/site-packages/django/urls/resolvers.py", line 362, in resolve
    for pattern in self.url_patterns:
  File "/home/taoshu/anaconda3/lib/python3.5/site-packages/django/utils/functional.py", line 35, in __get__
    res = instance.__dict__[self.name] = self.func(instance)
  File "/home/taoshu/anaconda3/lib/python3.5/site-packages/django/urls/resolvers.py", line 405, in url_patterns
    patterns = getattr(self.urlconf_module, "urlpatterns", self.urlconf_module)
  File "/home/taoshu/anaconda3/lib/python3.5/site-packages/django/utils/functional.py", line 35, in __get__
    res = instance.__dict__[self.name] = self.func(instance)
  File "/home/taoshu/anaconda3/lib/python3.5/site-packages/django/urls/resolvers.py", line 398, in urlconf_module
    return import_module(self.urlconf_name)
  File "/home/taoshu/anaconda3/lib/python3.5/importlib/__init__.py", line 126, in import_module
    return _bootstrap._gcd_import(name[level:], package, level)
  File "<frozen importlib._bootstrap>", line 986, in _gcd_import
  File "<frozen importlib._bootstrap>", line 969, in _find_and_load
  File "<frozen importlib._bootstrap>", line 958, in _find_and_load_unlocked
  File "<frozen importlib._bootstrap>", line 673, in _load_unlocked
  File "<frozen importlib._bootstrap_external>", line 662, in exec_module
  File "<frozen importlib._bootstrap>", line 222, in _call_with_frames_removed
  File "/home/taoshu/tzb_databrain/engine/db_engine/db_engine/urls.py", line 20, in <module>
    from db_engine import component, hive_reader, io, robotx_spark, xml, executor, self_defined_feature, feature_combine, \
  File "/home/taoshu/tzb_databrain/engine/db_engine/db_engine/component.py", line 11, in <module>
    from executor.components.RobotXSpark import RobotXSpark
  File "/home/taoshu/tzb_databrain/engine/db_engine/executor/components/RobotXSpark.py", line 6, in <module>
    from F_SETTING import HDFS_URL
ImportError: cannot import name 'HDFS_URL'
ERROR 2018-03-21 15:00:03,697 exception 2017 140483420955608 Internal Server Error: /mydata/csv_upload
Traceback (most recent call last):
  File "/home/taoshu/anaconda3/lib/python3.5/site-packages/django/core/handlers/exception.py", line 41, in inner
    response = get_response(request)
  File "/home/taoshu/anaconda3/lib/python3.5/site-packages/django/utils/deprecation.py", line 138, in __call__
    response = self.process_request(request)
  File "/home/taoshu/anaconda3/lib/python3.5/site-packages/django/middleware/common.py", line 62, in process_request
    if self.should_redirect_with_slash(request):
  File "/home/taoshu/anaconda3/lib/python3.5/site-packages/django/middleware/common.py", line 80, in should_redirect_with_slash
    not is_valid_path(request.path_info, urlconf) and
  File "/home/taoshu/anaconda3/lib/python3.5/site-packages/django/urls/base.py", line 158, in is_valid_path
    resolve(path, urlconf)
  File "/home/taoshu/anaconda3/lib/python3.5/site-packages/django/urls/base.py", line 27, in resolve
    return get_resolver(urlconf).resolve(path)
  File "/home/taoshu/anaconda3/lib/python3.5/site-packages/django/urls/resolvers.py", line 362, in resolve
    for pattern in self.url_patterns:
  File "/home/taoshu/anaconda3/lib/python3.5/site-packages/django/utils/functional.py", line 35, in __get__
    res = instance.__dict__[self.name] = self.func(instance)
  File "/home/taoshu/anaconda3/lib/python3.5/site-packages/django/urls/resolvers.py", line 405, in url_patterns
    patterns = getattr(self.urlconf_module, "urlpatterns", self.urlconf_module)
  File "/home/taoshu/anaconda3/lib/python3.5/site-packages/django/utils/functional.py", line 35, in __get__
    res = instance.__dict__[self.name] = self.func(instance)
  File "/home/taoshu/anaconda3/lib/python3.5/site-packages/django/urls/resolvers.py", line 398, in urlconf_module
    return import_module(self.urlconf_name)
  File "/home/taoshu/anaconda3/lib/python3.5/importlib/__init__.py", line 126, in import_module
    return _bootstrap._gcd_import(name[level:], package, level)
  File "<frozen importlib._bootstrap>", line 986, in _gcd_import
  File "<frozen importlib._bootstrap>", line 969, in _find_and_load
  File "<frozen importlib._bootstrap>", line 958, in _find_and_load_unlocked
  File "<frozen importlib._bootstrap>", line 673, in _load_unlocked
  File "<frozen importlib._bootstrap_external>", line 662, in exec_module
  File "<frozen importlib._bootstrap>", line 222, in _call_with_frames_removed
  File "/home/taoshu/tzb_databrain/engine/db_engine/db_engine/urls.py", line 20, in <module>
    from db_engine import component, hive_reader, io, robotx_spark, xml, executor, self_defined_feature, feature_combine, \
  File "/home/taoshu/tzb_databrain/engine/db_engine/db_engine/component.py", line 11, in <module>
    from executor.components.RobotXSpark import RobotXSpark
  File "/home/taoshu/tzb_databrain/engine/db_engine/executor/components/RobotXSpark.py", line 6, in <module>
    from F_SETTING import HDFS_URL
ImportError: cannot import name 'HDFS_URL'

During handling of the above exception, another exception occurred:

Traceback (most recent call last):
  File "/home/taoshu/anaconda3/lib/python3.5/site-packages/django/core/handlers/exception.py", line 41, in inner
    response = get_response(request)
  File "/home/taoshu/anaconda3/lib/python3.5/site-packages/django/utils/deprecation.py", line 140, in __call__
    response = self.get_response(request)
  File "/home/taoshu/anaconda3/lib/python3.5/site-packages/django/core/handlers/exception.py", line 43, in inner
    response = response_for_exception(request, exc)
  File "/home/taoshu/anaconda3/lib/python3.5/site-packages/django/core/handlers/exception.py", line 93, in response_for_exception
    response = handle_uncaught_exception(request, get_resolver(get_urlconf()), sys.exc_info())
  File "/home/taoshu/anaconda3/lib/python3.5/site-packages/django/core/handlers/exception.py", line 142, in handle_uncaught_exception
    callback, param_dict = resolver.resolve_error_handler(500)
  File "/home/taoshu/anaconda3/lib/python3.5/site-packages/django/urls/resolvers.py", line 418, in resolve_error_handler
    callback = getattr(self.urlconf_module, 'handler%s' % view_type, None)
  File "/home/taoshu/anaconda3/lib/python3.5/site-packages/django/utils/functional.py", line 35, in __get__
    res = instance.__dict__[self.name] = self.func(instance)
  File "/home/taoshu/anaconda3/lib/python3.5/site-packages/django/urls/resolvers.py", line 398, in urlconf_module
    return import_module(self.urlconf_name)
  File "/home/taoshu/anaconda3/lib/python3.5/importlib/__init__.py", line 126, in import_module
    return _bootstrap._gcd_import(name[level:], package, level)
  File "<frozen importlib._bootstrap>", line 986, in _gcd_import
  File "<frozen importlib._bootstrap>", line 969, in _find_and_load
  File "<frozen importlib._bootstrap>", line 958, in _find_and_load_unlocked
  File "<frozen importlib._bootstrap>", line 673, in _load_unlocked
  File "<frozen importlib._bootstrap_external>", line 662, in exec_module
  File "<frozen importlib._bootstrap>", line 222, in _call_with_frames_removed
  File "/home/taoshu/tzb_databrain/engine/db_engine/db_engine/urls.py", line 20, in <module>
    from db_engine import component, hive_reader, io, robotx_spark, xml, executor, self_defined_feature, feature_combine, \
  File "/home/taoshu/tzb_databrain/engine/db_engine/db_engine/component.py", line 11, in <module>
    from executor.components.RobotXSpark import RobotXSpark
  File "/home/taoshu/tzb_databrain/engine/db_engine/executor/components/RobotXSpark.py", line 6, in <module>
    from F_SETTING import HDFS_URL
ImportError: cannot import name 'HDFS_URL'
ERROR 2018-03-21 15:00:03,699 exception 2017 140483420955608 Internal Server Error: /mydata/csv_upload
Traceback (most recent call last):
  File "/home/taoshu/anaconda3/lib/python3.5/site-packages/django/core/handlers/exception.py", line 41, in inner
    response = get_response(request)
  File "/home/taoshu/anaconda3/lib/python3.5/site-packages/django/utils/deprecation.py", line 138, in __call__
    response = self.process_request(request)
  File "/home/taoshu/anaconda3/lib/python3.5/site-packages/django/middleware/common.py", line 62, in process_request
    if self.should_redirect_with_slash(request):
  File "/home/taoshu/anaconda3/lib/python3.5/site-packages/django/middleware/common.py", line 80, in should_redirect_with_slash
    not is_valid_path(request.path_info, urlconf) and
  File "/home/taoshu/anaconda3/lib/python3.5/site-packages/django/urls/base.py", line 158, in is_valid_path
    resolve(path, urlconf)
  File "/home/taoshu/anaconda3/lib/python3.5/site-packages/django/urls/base.py", line 27, in resolve
    return get_resolver(urlconf).resolve(path)
  File "/home/taoshu/anaconda3/lib/python3.5/site-packages/django/urls/resolvers.py", line 362, in resolve
    for pattern in self.url_patterns:
  File "/home/taoshu/anaconda3/lib/python3.5/site-packages/django/utils/functional.py", line 35, in __get__
    res = instance.__dict__[self.name] = self.func(instance)
  File "/home/taoshu/anaconda3/lib/python3.5/site-packages/django/urls/resolvers.py", line 405, in url_patterns
    patterns = getattr(self.urlconf_module, "urlpatterns", self.urlconf_module)
  File "/home/taoshu/anaconda3/lib/python3.5/site-packages/django/utils/functional.py", line 35, in __get__
    res = instance.__dict__[self.name] = self.func(instance)
  File "/home/taoshu/anaconda3/lib/python3.5/site-packages/django/urls/resolvers.py", line 398, in urlconf_module
    return import_module(self.urlconf_name)
  File "/home/taoshu/anaconda3/lib/python3.5/importlib/__init__.py", line 126, in import_module
    return _bootstrap._gcd_import(name[level:], package, level)
  File "<frozen importlib._bootstrap>", line 986, in _gcd_import
  File "<frozen importlib._bootstrap>", line 969, in _find_and_load
  File "<frozen importlib._bootstrap>", line 958, in _find_and_load_unlocked
  File "<frozen importlib._bootstrap>", line 673, in _load_unlocked
  File "<frozen importlib._bootstrap_external>", line 662, in exec_module
  File "<frozen importlib._bootstrap>", line 222, in _call_with_frames_removed
  File "/home/taoshu/tzb_databrain/engine/db_engine/db_engine/urls.py", line 20, in <module>
    from db_engine import component, hive_reader, io, robotx_spark, xml, executor, self_defined_feature, feature_combine, \
  File "/home/taoshu/tzb_databrain/engine/db_engine/db_engine/component.py", line 11, in <module>
    from executor.components.RobotXSpark import RobotXSpark
  File "/home/taoshu/tzb_databrain/engine/db_engine/executor/components/RobotXSpark.py", line 6, in <module>
    from F_SETTING import HDFS_URL
ImportError: cannot import name 'HDFS_URL'

During handling of the above exception, another exception occurred:

Traceback (most recent call last):
  File "/home/taoshu/anaconda3/lib/python3.5/site-packages/django/core/handlers/exception.py", line 41, in inner
    response = get_response(request)
  File "/home/taoshu/anaconda3/lib/python3.5/site-packages/django/utils/deprecation.py", line 140, in __call__
    response = self.get_response(request)
  File "/home/taoshu/anaconda3/lib/python3.5/site-packages/django/core/handlers/exception.py", line 43, in inner
    response = response_for_exception(request, exc)
  File "/home/taoshu/anaconda3/lib/python3.5/site-packages/django/core/handlers/exception.py", line 93, in response_for_exception
    response = handle_uncaught_exception(request, get_resolver(get_urlconf()), sys.exc_info())
  File "/home/taoshu/anaconda3/lib/python3.5/site-packages/django/core/handlers/exception.py", line 142, in handle_uncaught_exception
    callback, param_dict = resolver.resolve_error_handler(500)
  File "/home/taoshu/anaconda3/lib/python3.5/site-packages/django/urls/resolvers.py", line 418, in resolve_error_handler
    callback = getattr(self.urlconf_module, 'handler%s' % view_type, None)
  File "/home/taoshu/anaconda3/lib/python3.5/site-packages/django/utils/functional.py", line 35, in __get__
    res = instance.__dict__[self.name] = self.func(instance)
  File "/home/taoshu/anaconda3/lib/python3.5/site-packages/django/urls/resolvers.py", line 398, in urlconf_module
    return import_module(self.urlconf_name)
  File "/home/taoshu/anaconda3/lib/python3.5/importlib/__init__.py", line 126, in import_module
    return _bootstrap._gcd_import(name[level:], package, level)
  File "<frozen importlib._bootstrap>", line 986, in _gcd_import
  File "<frozen importlib._bootstrap>", line 969, in _find_and_load
  File "<frozen importlib._bootstrap>", line 958, in _find_and_load_unlocked
  File "<frozen importlib._bootstrap>", line 673, in _load_unlocked
  File "<frozen importlib._bootstrap_external>", line 662, in exec_module
  File "<frozen importlib._bootstrap>", line 222, in _call_with_frames_removed
  File "/home/taoshu/tzb_databrain/engine/db_engine/db_engine/urls.py", line 20, in <module>
    from db_engine import component, hive_reader, io, robotx_spark, xml, executor, self_defined_feature, feature_combine, \
  File "/home/taoshu/tzb_databrain/engine/db_engine/db_engine/component.py", line 11, in <module>
    from executor.components.RobotXSpark import RobotXSpark
  File "/home/taoshu/tzb_databrain/engine/db_engine/executor/components/RobotXSpark.py", line 6, in <module>
    from F_SETTING import HDFS_URL
ImportError: cannot import name 'HDFS_URL'

During handling of the above exception, another exception occurred:

Traceback (most recent call last):
  File "/home/taoshu/anaconda3/lib/python3.5/site-packages/django/core/handlers/exception.py", line 41, in inner
    response = get_response(request)
  File "/home/taoshu/anaconda3/lib/python3.5/site-packages/django/utils/deprecation.py", line 140, in __call__
    response = self.get_response(request)
  File "/home/taoshu/anaconda3/lib/python3.5/site-packages/django/core/handlers/exception.py", line 43, in inner
    response = response_for_exception(request, exc)
  File "/home/taoshu/anaconda3/lib/python3.5/site-packages/django/core/handlers/exception.py", line 93, in response_for_exception
    response = handle_uncaught_exception(request, get_resolver(get_urlconf()), sys.exc_info())
  File "/home/taoshu/anaconda3/lib/python3.5/site-packages/django/core/handlers/exception.py", line 142, in handle_uncaught_exception
    callback, param_dict = resolver.resolve_error_handler(500)
  File "/home/taoshu/anaconda3/lib/python3.5/site-packages/django/urls/resolvers.py", line 418, in resolve_error_handler
    callback = getattr(self.urlconf_module, 'handler%s' % view_type, None)
  File "/home/taoshu/anaconda3/lib/python3.5/site-packages/django/utils/functional.py", line 35, in __get__
    res = instance.__dict__[self.name] = self.func(instance)
  File "/home/taoshu/anaconda3/lib/python3.5/site-packages/django/urls/resolvers.py", line 398, in urlconf_module
    return import_module(self.urlconf_name)
  File "/home/taoshu/anaconda3/lib/python3.5/importlib/__init__.py", line 126, in import_module
    return _bootstrap._gcd_import(name[level:], package, level)
  File "<frozen importlib._bootstrap>", line 986, in _gcd_import
  File "<frozen importlib._bootstrap>", line 969, in _find_and_load
  File "<frozen importlib._bootstrap>", line 958, in _find_and_load_unlocked
  File "<frozen importlib._bootstrap>", line 673, in _load_unlocked
  File "<frozen importlib._bootstrap_external>", line 662, in exec_module
  File "<frozen importlib._bootstrap>", line 222, in _call_with_frames_removed
  File "/home/taoshu/tzb_databrain/engine/db_engine/db_engine/urls.py", line 20, in <module>
    from db_engine import component, hive_reader, io, robotx_spark, xml, executor, self_defined_feature, feature_combine, \
  File "/home/taoshu/tzb_databrain/engine/db_engine/db_engine/component.py", line 11, in <module>
    from executor.components.RobotXSpark import RobotXSpark
  File "/home/taoshu/tzb_databrain/engine/db_engine/executor/components/RobotXSpark.py", line 6, in <module>
    from F_SETTING import HDFS_URL
ImportError: cannot import name 'HDFS_URL'
ERROR 2018-03-21 15:00:03,702 exception 2017 140483420955608 Internal Server Error: /mydata/csv_upload
Traceback (most recent call last):
  File "/home/taoshu/anaconda3/lib/python3.5/site-packages/django/core/handlers/exception.py", line 41, in inner
    response = get_response(request)
  File "/home/taoshu/anaconda3/lib/python3.5/site-packages/django/utils/deprecation.py", line 138, in __call__
    response = self.process_request(request)
  File "/home/taoshu/anaconda3/lib/python3.5/site-packages/django/middleware/common.py", line 62, in process_request
    if self.should_redirect_with_slash(request):
  File "/home/taoshu/anaconda3/lib/python3.5/site-packages/django/middleware/common.py", line 80, in should_redirect_with_slash
    not is_valid_path(request.path_info, urlconf) and
  File "/home/taoshu/anaconda3/lib/python3.5/site-packages/django/urls/base.py", line 158, in is_valid_path
    resolve(path, urlconf)
  File "/home/taoshu/anaconda3/lib/python3.5/site-packages/django/urls/base.py", line 27, in resolve
    return get_resolver(urlconf).resolve(path)
  File "/home/taoshu/anaconda3/lib/python3.5/site-packages/django/urls/resolvers.py", line 362, in resolve
    for pattern in self.url_patterns:
  File "/home/taoshu/anaconda3/lib/python3.5/site-packages/django/utils/functional.py", line 35, in __get__
    res = instance.__dict__[self.name] = self.func(instance)
  File "/home/taoshu/anaconda3/lib/python3.5/site-packages/django/urls/resolvers.py", line 405, in url_patterns
    patterns = getattr(self.urlconf_module, "urlpatterns", self.urlconf_module)
  File "/home/taoshu/anaconda3/lib/python3.5/site-packages/django/utils/functional.py", line 35, in __get__
    res = instance.__dict__[self.name] = self.func(instance)
  File "/home/taoshu/anaconda3/lib/python3.5/site-packages/django/urls/resolvers.py", line 398, in urlconf_module
    return import_module(self.urlconf_name)
  File "/home/taoshu/anaconda3/lib/python3.5/importlib/__init__.py", line 126, in import_module
    return _bootstrap._gcd_import(name[level:], package, level)
  File "<frozen importlib._bootstrap>", line 986, in _gcd_import
  File "<frozen importlib._bootstrap>", line 969, in _find_and_load
  File "<frozen importlib._bootstrap>", line 958, in _find_and_load_unlocked
  File "<frozen importlib._bootstrap>", line 673, in _load_unlocked
  File "<frozen importlib._bootstrap_external>", line 662, in exec_module
  File "<frozen importlib._bootstrap>", line 222, in _call_with_frames_removed
  File "/home/taoshu/tzb_databrain/engine/db_engine/db_engine/urls.py", line 20, in <module>
    from db_engine import component, hive_reader, io, robotx_spark, xml, executor, self_defined_feature, feature_combine, \
  File "/home/taoshu/tzb_databrain/engine/db_engine/db_engine/component.py", line 11, in <module>
    from executor.components.RobotXSpark import RobotXSpark
  File "/home/taoshu/tzb_databrain/engine/db_engine/executor/components/RobotXSpark.py", line 6, in <module>
    from F_SETTING import HDFS_URL
ImportError: cannot import name 'HDFS_URL'

During handling of the above exception, another exception occurred:

Traceback (most recent call last):
  File "/home/taoshu/anaconda3/lib/python3.5/site-packages/django/core/handlers/exception.py", line 41, in inner
    response = get_response(request)
  File "/home/taoshu/anaconda3/lib/python3.5/site-packages/django/utils/deprecation.py", line 140, in __call__
    response = self.get_response(request)
  File "/home/taoshu/anaconda3/lib/python3.5/site-packages/django/core/handlers/exception.py", line 43, in inner
    response = response_for_exception(request, exc)
  File "/home/taoshu/anaconda3/lib/python3.5/site-packages/django/core/handlers/exception.py", line 93, in response_for_exception
    response = handle_uncaught_exception(request, get_resolver(get_urlconf()), sys.exc_info())
  File "/home/taoshu/anaconda3/lib/python3.5/site-packages/django/core/handlers/exception.py", line 142, in handle_uncaught_exception
    callback, param_dict = resolver.resolve_error_handler(500)
  File "/home/taoshu/anaconda3/lib/python3.5/site-packages/django/urls/resolvers.py", line 418, in resolve_error_handler
    callback = getattr(self.urlconf_module, 'handler%s' % view_type, None)
  File "/home/taoshu/anaconda3/lib/python3.5/site-packages/django/utils/functional.py", line 35, in __get__
    res = instance.__dict__[self.name] = self.func(instance)
  File "/home/taoshu/anaconda3/lib/python3.5/site-packages/django/urls/resolvers.py", line 398, in urlconf_module
    return import_module(self.urlconf_name)
  File "/home/taoshu/anaconda3/lib/python3.5/importlib/__init__.py", line 126, in import_module
    return _bootstrap._gcd_import(name[level:], package, level)
  File "<frozen importlib._bootstrap>", line 986, in _gcd_import
  File "<frozen importlib._bootstrap>", line 969, in _find_and_load
  File "<frozen importlib._bootstrap>", line 958, in _find_and_load_unlocked
  File "<frozen importlib._bootstrap>", line 673, in _load_unlocked
  File "<frozen importlib._bootstrap_external>", line 662, in exec_module
  File "<frozen importlib._bootstrap>", line 222, in _call_with_frames_removed
  File "/home/taoshu/tzb_databrain/engine/db_engine/db_engine/urls.py", line 20, in <module>
    from db_engine import component, hive_reader, io, robotx_spark, xml, executor, self_defined_feature, feature_combine, \
  File "/home/taoshu/tzb_databrain/engine/db_engine/db_engine/component.py", line 11, in <module>
    from executor.components.RobotXSpark import RobotXSpark
  File "/home/taoshu/tzb_databrain/engine/db_engine/executor/components/RobotXSpark.py", line 6, in <module>
    from F_SETTING import HDFS_URL
ImportError: cannot import name 'HDFS_URL'

During handling of the above exception, another exception occurred:

Traceback (most recent call last):
  File "/home/taoshu/anaconda3/lib/python3.5/site-packages/django/core/handlers/exception.py", line 41, in inner
    response = get_response(request)
  File "/home/taoshu/anaconda3/lib/python3.5/site-packages/django/utils/deprecation.py", line 140, in __call__
    response = self.get_response(request)
  File "/home/taoshu/anaconda3/lib/python3.5/site-packages/django/core/handlers/exception.py", line 43, in inner
    response = response_for_exception(request, exc)
  File "/home/taoshu/anaconda3/lib/python3.5/site-packages/django/core/handlers/exception.py", line 93, in response_for_exception
    response = handle_uncaught_exception(request, get_resolver(get_urlconf()), sys.exc_info())
  File "/home/taoshu/anaconda3/lib/python3.5/site-packages/django/core/handlers/exception.py", line 142, in handle_uncaught_exception
    callback, param_dict = resolver.resolve_error_handler(500)
  File "/home/taoshu/anaconda3/lib/python3.5/site-packages/django/urls/resolvers.py", line 418, in resolve_error_handler
    callback = getattr(self.urlconf_module, 'handler%s' % view_type, None)
  File "/home/taoshu/anaconda3/lib/python3.5/site-packages/django/utils/functional.py", line 35, in __get__
    res = instance.__dict__[self.name] = self.func(instance)
  File "/home/taoshu/anaconda3/lib/python3.5/site-packages/django/urls/resolvers.py", line 398, in urlconf_module
    return import_module(self.urlconf_name)
  File "/home/taoshu/anaconda3/lib/python3.5/importlib/__init__.py", line 126, in import_module
    return _bootstrap._gcd_import(name[level:], package, level)
  File "<frozen importlib._bootstrap>", line 986, in _gcd_import
  File "<frozen importlib._bootstrap>", line 969, in _find_and_load
  File "<frozen importlib._bootstrap>", line 958, in _find_and_load_unlocked
  File "<frozen importlib._bootstrap>", line 673, in _load_unlocked
  File "<frozen importlib._bootstrap_external>", line 662, in exec_module
  File "<frozen importlib._bootstrap>", line 222, in _call_with_frames_removed
  File "/home/taoshu/tzb_databrain/engine/db_engine/db_engine/urls.py", line 20, in <module>
    from db_engine import component, hive_reader, io, robotx_spark, xml, executor, self_defined_feature, feature_combine, \
  File "/home/taoshu/tzb_databrain/engine/db_engine/db_engine/component.py", line 11, in <module>
    from executor.components.RobotXSpark import RobotXSpark
  File "/home/taoshu/tzb_databrain/engine/db_engine/executor/components/RobotXSpark.py", line 6, in <module>
    from F_SETTING import HDFS_URL
ImportError: cannot import name 'HDFS_URL'

During handling of the above exception, another exception occurred:

Traceback (most recent call last):
  File "/home/taoshu/anaconda3/lib/python3.5/site-packages/django/core/handlers/exception.py", line 41, in inner
    response = get_response(request)
  File "/home/taoshu/anaconda3/lib/python3.5/site-packages/django/utils/deprecation.py", line 140, in __call__
    response = self.get_response(request)
  File "/home/taoshu/anaconda3/lib/python3.5/site-packages/django/core/handlers/exception.py", line 43, in inner
    response = response_for_exception(request, exc)
  File "/home/taoshu/anaconda3/lib/python3.5/site-packages/django/core/handlers/exception.py", line 93, in response_for_exception
    response = handle_uncaught_exception(request, get_resolver(get_urlconf()), sys.exc_info())
  File "/home/taoshu/anaconda3/lib/python3.5/site-packages/django/core/handlers/exception.py", line 142, in handle_uncaught_exception
    callback, param_dict = resolver.resolve_error_handler(500)
  File "/home/taoshu/anaconda3/lib/python3.5/site-packages/django/urls/resolvers.py", line 418, in resolve_error_handler
    callback = getattr(self.urlconf_module, 'handler%s' % view_type, None)
  File "/home/taoshu/anaconda3/lib/python3.5/site-packages/django/utils/functional.py", line 35, in __get__
    res = instance.__dict__[self.name] = self.func(instance)
  File "/home/taoshu/anaconda3/lib/python3.5/site-packages/django/urls/resolvers.py", line 398, in urlconf_module
    return import_module(self.urlconf_name)
  File "/home/taoshu/anaconda3/lib/python3.5/importlib/__init__.py", line 126, in import_module
    return _bootstrap._gcd_import(name[level:], package, level)
  File "<frozen importlib._bootstrap>", line 986, in _gcd_import
  File "<frozen importlib._bootstrap>", line 969, in _find_and_load
  File "<frozen importlib._bootstrap>", line 958, in _find_and_load_unlocked
  File "<frozen importlib._bootstrap>", line 673, in _load_unlocked
  File "<frozen importlib._bootstrap_external>", line 662, in exec_module
  File "<frozen importlib._bootstrap>", line 222, in _call_with_frames_removed
  File "/home/taoshu/tzb_databrain/engine/db_engine/db_engine/urls.py", line 20, in <module>
    from db_engine import component, hive_reader, io, robotx_spark, xml, executor, self_defined_feature, feature_combine, \
  File "/home/taoshu/tzb_databrain/engine/db_engine/db_engine/component.py", line 11, in <module>
    from executor.components.RobotXSpark import RobotXSpark
  File "/home/taoshu/tzb_databrain/engine/db_engine/executor/components/RobotXSpark.py", line 6, in <module>
    from F_SETTING import HDFS_URL
ImportError: cannot import name 'HDFS_URL'
ERROR 2018-03-21 15:00:29,855 exception 2017 140483420955608 Internal Server Error: /mydata/list_table
Traceback (most recent call last):
  File "/home/taoshu/anaconda3/lib/python3.5/site-packages/django/core/handlers/exception.py", line 41, in inner
    response = get_response(request)
  File "/home/taoshu/anaconda3/lib/python3.5/site-packages/django/utils/deprecation.py", line 138, in __call__
    response = self.process_request(request)
  File "/home/taoshu/anaconda3/lib/python3.5/site-packages/django/middleware/common.py", line 62, in process_request
    if self.should_redirect_with_slash(request):
  File "/home/taoshu/anaconda3/lib/python3.5/site-packages/django/middleware/common.py", line 80, in should_redirect_with_slash
    not is_valid_path(request.path_info, urlconf) and
  File "/home/taoshu/anaconda3/lib/python3.5/site-packages/django/urls/base.py", line 158, in is_valid_path
    resolve(path, urlconf)
  File "/home/taoshu/anaconda3/lib/python3.5/site-packages/django/urls/base.py", line 27, in resolve
    return get_resolver(urlconf).resolve(path)
  File "/home/taoshu/anaconda3/lib/python3.5/site-packages/django/urls/resolvers.py", line 362, in resolve
    for pattern in self.url_patterns:
  File "/home/taoshu/anaconda3/lib/python3.5/site-packages/django/utils/functional.py", line 35, in __get__
    res = instance.__dict__[self.name] = self.func(instance)
  File "/home/taoshu/anaconda3/lib/python3.5/site-packages/django/urls/resolvers.py", line 405, in url_patterns
    patterns = getattr(self.urlconf_module, "urlpatterns", self.urlconf_module)
  File "/home/taoshu/anaconda3/lib/python3.5/site-packages/django/utils/functional.py", line 35, in __get__
    res = instance.__dict__[self.name] = self.func(instance)
  File "/home/taoshu/anaconda3/lib/python3.5/site-packages/django/urls/resolvers.py", line 398, in urlconf_module
    return import_module(self.urlconf_name)
  File "/home/taoshu/anaconda3/lib/python3.5/importlib/__init__.py", line 126, in import_module
    return _bootstrap._gcd_import(name[level:], package, level)
  File "<frozen importlib._bootstrap>", line 986, in _gcd_import
  File "<frozen importlib._bootstrap>", line 969, in _find_and_load
  File "<frozen importlib._bootstrap>", line 958, in _find_and_load_unlocked
  File "<frozen importlib._bootstrap>", line 673, in _load_unlocked
  File "<frozen importlib._bootstrap_external>", line 662, in exec_module
  File "<frozen importlib._bootstrap>", line 222, in _call_with_frames_removed
  File "/home/taoshu/tzb_databrain/engine/db_engine/db_engine/urls.py", line 20, in <module>
    from db_engine import component, hive_reader, io, robotx_spark, xml, executor, self_defined_feature, feature_combine, \
  File "/home/taoshu/tzb_databrain/engine/db_engine/db_engine/component.py", line 11, in <module>
    from executor.components.RobotXSpark import RobotXSpark
  File "/home/taoshu/tzb_databrain/engine/db_engine/executor/components/RobotXSpark.py", line 6, in <module>
    from F_SETTING import HDFS_URL
ImportError: cannot import name 'HDFS_URL'
ERROR 2018-03-21 15:00:29,858 exception 2017 140483420955608 Internal Server Error: /mydata/list_table
Traceback (most recent call last):
  File "/home/taoshu/anaconda3/lib/python3.5/site-packages/django/core/handlers/exception.py", line 41, in inner
    response = get_response(request)
  File "/home/taoshu/anaconda3/lib/python3.5/site-packages/django/utils/deprecation.py", line 138, in __call__
    response = self.process_request(request)
  File "/home/taoshu/anaconda3/lib/python3.5/site-packages/django/middleware/common.py", line 62, in process_request
    if self.should_redirect_with_slash(request):
  File "/home/taoshu/anaconda3/lib/python3.5/site-packages/django/middleware/common.py", line 80, in should_redirect_with_slash
    not is_valid_path(request.path_info, urlconf) and
  File "/home/taoshu/anaconda3/lib/python3.5/site-packages/django/urls/base.py", line 158, in is_valid_path
    resolve(path, urlconf)
  File "/home/taoshu/anaconda3/lib/python3.5/site-packages/django/urls/base.py", line 27, in resolve
    return get_resolver(urlconf).resolve(path)
  File "/home/taoshu/anaconda3/lib/python3.5/site-packages/django/urls/resolvers.py", line 362, in resolve
    for pattern in self.url_patterns:
  File "/home/taoshu/anaconda3/lib/python3.5/site-packages/django/utils/functional.py", line 35, in __get__
    res = instance.__dict__[self.name] = self.func(instance)
  File "/home/taoshu/anaconda3/lib/python3.5/site-packages/django/urls/resolvers.py", line 405, in url_patterns
    patterns = getattr(self.urlconf_module, "urlpatterns", self.urlconf_module)
  File "/home/taoshu/anaconda3/lib/python3.5/site-packages/django/utils/functional.py", line 35, in __get__
    res = instance.__dict__[self.name] = self.func(instance)
  File "/home/taoshu/anaconda3/lib/python3.5/site-packages/django/urls/resolvers.py", line 398, in urlconf_module
    return import_module(self.urlconf_name)
  File "/home/taoshu/anaconda3/lib/python3.5/importlib/__init__.py", line 126, in import_module
    return _bootstrap._gcd_import(name[level:], package, level)
  File "<frozen importlib._bootstrap>", line 986, in _gcd_import
  File "<frozen importlib._bootstrap>", line 969, in _find_and_load
  File "<frozen importlib._bootstrap>", line 958, in _find_and_load_unlocked
  File "<frozen importlib._bootstrap>", line 673, in _load_unlocked
  File "<frozen importlib._bootstrap_external>", line 662, in exec_module
  File "<frozen importlib._bootstrap>", line 222, in _call_with_frames_removed
  File "/home/taoshu/tzb_databrain/engine/db_engine/db_engine/urls.py", line 20, in <module>
    from db_engine import component, hive_reader, io, robotx_spark, xml, executor, self_defined_feature, feature_combine, \
  File "/home/taoshu/tzb_databrain/engine/db_engine/db_engine/component.py", line 11, in <module>
    from executor.components.RobotXSpark import RobotXSpark
  File "/home/taoshu/tzb_databrain/engine/db_engine/executor/components/RobotXSpark.py", line 6, in <module>
    from F_SETTING import HDFS_URL
ImportError: cannot import name 'HDFS_URL'

During handling of the above exception, another exception occurred:

Traceback (most recent call last):
  File "/home/taoshu/anaconda3/lib/python3.5/site-packages/django/core/handlers/exception.py", line 41, in inner
    response = get_response(request)
  File "/home/taoshu/anaconda3/lib/python3.5/site-packages/django/utils/deprecation.py", line 140, in __call__
    response = self.get_response(request)
  File "/home/taoshu/anaconda3/lib/python3.5/site-packages/django/core/handlers/exception.py", line 43, in inner
    response = response_for_exception(request, exc)
  File "/home/taoshu/anaconda3/lib/python3.5/site-packages/django/core/handlers/exception.py", line 93, in response_for_exception
    response = handle_uncaught_exception(request, get_resolver(get_urlconf()), sys.exc_info())
  File "/home/taoshu/anaconda3/lib/python3.5/site-packages/django/core/handlers/exception.py", line 142, in handle_uncaught_exception
    callback, param_dict = resolver.resolve_error_handler(500)
  File "/home/taoshu/anaconda3/lib/python3.5/site-packages/django/urls/resolvers.py", line 418, in resolve_error_handler
    callback = getattr(self.urlconf_module, 'handler%s' % view_type, None)
  File "/home/taoshu/anaconda3/lib/python3.5/site-packages/django/utils/functional.py", line 35, in __get__
    res = instance.__dict__[self.name] = self.func(instance)
  File "/home/taoshu/anaconda3/lib/python3.5/site-packages/django/urls/resolvers.py", line 398, in urlconf_module
    return import_module(self.urlconf_name)
  File "/home/taoshu/anaconda3/lib/python3.5/importlib/__init__.py", line 126, in import_module
    return _bootstrap._gcd_import(name[level:], package, level)
  File "<frozen importlib._bootstrap>", line 986, in _gcd_import
  File "<frozen importlib._bootstrap>", line 969, in _find_and_load
  File "<frozen importlib._bootstrap>", line 958, in _find_and_load_unlocked
  File "<frozen importlib._bootstrap>", line 673, in _load_unlocked
  File "<frozen importlib._bootstrap_external>", line 662, in exec_module
  File "<frozen importlib._bootstrap>", line 222, in _call_with_frames_removed
  File "/home/taoshu/tzb_databrain/engine/db_engine/db_engine/urls.py", line 20, in <module>
    from db_engine import component, hive_reader, io, robotx_spark, xml, executor, self_defined_feature, feature_combine, \
  File "/home/taoshu/tzb_databrain/engine/db_engine/db_engine/component.py", line 11, in <module>
    from executor.components.RobotXSpark import RobotXSpark
  File "/home/taoshu/tzb_databrain/engine/db_engine/executor/components/RobotXSpark.py", line 6, in <module>
    from F_SETTING import HDFS_URL
ImportError: cannot import name 'HDFS_URL'
ERROR 2018-03-21 15:00:29,861 exception 2017 140483420955608 Internal Server Error: /mydata/list_table
Traceback (most recent call last):
  File "/home/taoshu/anaconda3/lib/python3.5/site-packages/django/core/handlers/exception.py", line 41, in inner
    response = get_response(request)
  File "/home/taoshu/anaconda3/lib/python3.5/site-packages/django/utils/deprecation.py", line 138, in __call__
    response = self.process_request(request)
  File "/home/taoshu/anaconda3/lib/python3.5/site-packages/django/middleware/common.py", line 62, in process_request
    if self.should_redirect_with_slash(request):
  File "/home/taoshu/anaconda3/lib/python3.5/site-packages/django/middleware/common.py", line 80, in should_redirect_with_slash
    not is_valid_path(request.path_info, urlconf) and
  File "/home/taoshu/anaconda3/lib/python3.5/site-packages/django/urls/base.py", line 158, in is_valid_path
    resolve(path, urlconf)
  File "/home/taoshu/anaconda3/lib/python3.5/site-packages/django/urls/base.py", line 27, in resolve
    return get_resolver(urlconf).resolve(path)
  File "/home/taoshu/anaconda3/lib/python3.5/site-packages/django/urls/resolvers.py", line 362, in resolve
    for pattern in self.url_patterns:
  File "/home/taoshu/anaconda3/lib/python3.5/site-packages/django/utils/functional.py", line 35, in __get__
    res = instance.__dict__[self.name] = self.func(instance)
  File "/home/taoshu/anaconda3/lib/python3.5/site-packages/django/urls/resolvers.py", line 405, in url_patterns
    patterns = getattr(self.urlconf_module, "urlpatterns", self.urlconf_module)
  File "/home/taoshu/anaconda3/lib/python3.5/site-packages/django/utils/functional.py", line 35, in __get__
    res = instance.__dict__[self.name] = self.func(instance)
  File "/home/taoshu/anaconda3/lib/python3.5/site-packages/django/urls/resolvers.py", line 398, in urlconf_module
    return import_module(self.urlconf_name)
  File "/home/taoshu/anaconda3/lib/python3.5/importlib/__init__.py", line 126, in import_module
    return _bootstrap._gcd_import(name[level:], package, level)
  File "<frozen importlib._bootstrap>", line 986, in _gcd_import
  File "<frozen importlib._bootstrap>", line 969, in _find_and_load
  File "<frozen importlib._bootstrap>", line 958, in _find_and_load_unlocked
  File "<frozen importlib._bootstrap>", line 673, in _load_unlocked
  File "<frozen importlib._bootstrap_external>", line 662, in exec_module
  File "<frozen importlib._bootstrap>", line 222, in _call_with_frames_removed
  File "/home/taoshu/tzb_databrain/engine/db_engine/db_engine/urls.py", line 20, in <module>
    from db_engine import component, hive_reader, io, robotx_spark, xml, executor, self_defined_feature, feature_combine, \
  File "/home/taoshu/tzb_databrain/engine/db_engine/db_engine/component.py", line 11, in <module>
    from executor.components.RobotXSpark import RobotXSpark
  File "/home/taoshu/tzb_databrain/engine/db_engine/executor/components/RobotXSpark.py", line 6, in <module>
    from F_SETTING import HDFS_URL
ImportError: cannot import name 'HDFS_URL'

During handling of the above exception, another exception occurred:

Traceback (most recent call last):
  File "/home/taoshu/anaconda3/lib/python3.5/site-packages/django/core/handlers/exception.py", line 41, in inner
    response = get_response(request)
  File "/home/taoshu/anaconda3/lib/python3.5/site-packages/django/utils/deprecation.py", line 140, in __call__
    response = self.get_response(request)
  File "/home/taoshu/anaconda3/lib/python3.5/site-packages/django/core/handlers/exception.py", line 43, in inner
    response = response_for_exception(request, exc)
  File "/home/taoshu/anaconda3/lib/python3.5/site-packages/django/core/handlers/exception.py", line 93, in response_for_exception
    response = handle_uncaught_exception(request, get_resolver(get_urlconf()), sys.exc_info())
  File "/home/taoshu/anaconda3/lib/python3.5/site-packages/django/core/handlers/exception.py", line 142, in handle_uncaught_exception
    callback, param_dict = resolver.resolve_error_handler(500)
  File "/home/taoshu/anaconda3/lib/python3.5/site-packages/django/urls/resolvers.py", line 418, in resolve_error_handler
    callback = getattr(self.urlconf_module, 'handler%s' % view_type, None)
  File "/home/taoshu/anaconda3/lib/python3.5/site-packages/django/utils/functional.py", line 35, in __get__
    res = instance.__dict__[self.name] = self.func(instance)
  File "/home/taoshu/anaconda3/lib/python3.5/site-packages/django/urls/resolvers.py", line 398, in urlconf_module
    return import_module(self.urlconf_name)
  File "/home/taoshu/anaconda3/lib/python3.5/importlib/__init__.py", line 126, in import_module
    return _bootstrap._gcd_import(name[level:], package, level)
  File "<frozen importlib._bootstrap>", line 986, in _gcd_import
  File "<frozen importlib._bootstrap>", line 969, in _find_and_load
  File "<frozen importlib._bootstrap>", line 958, in _find_and_load_unlocked
  File "<frozen importlib._bootstrap>", line 673, in _load_unlocked
  File "<frozen importlib._bootstrap_external>", line 662, in exec_module
  File "<frozen importlib._bootstrap>", line 222, in _call_with_frames_removed
  File "/home/taoshu/tzb_databrain/engine/db_engine/db_engine/urls.py", line 20, in <module>
    from db_engine import component, hive_reader, io, robotx_spark, xml, executor, self_defined_feature, feature_combine, \
  File "/home/taoshu/tzb_databrain/engine/db_engine/db_engine/component.py", line 11, in <module>
    from executor.components.RobotXSpark import RobotXSpark
  File "/home/taoshu/tzb_databrain/engine/db_engine/executor/components/RobotXSpark.py", line 6, in <module>
    from F_SETTING import HDFS_URL
ImportError: cannot import name 'HDFS_URL'

During handling of the above exception, another exception occurred:

Traceback (most recent call last):
  File "/home/taoshu/anaconda3/lib/python3.5/site-packages/django/core/handlers/exception.py", line 41, in inner
    response = get_response(request)
  File "/home/taoshu/anaconda3/lib/python3.5/site-packages/django/utils/deprecation.py", line 140, in __call__
    response = self.get_response(request)
  File "/home/taoshu/anaconda3/lib/python3.5/site-packages/django/core/handlers/exception.py", line 43, in inner
    response = response_for_exception(request, exc)
  File "/home/taoshu/anaconda3/lib/python3.5/site-packages/django/core/handlers/exception.py", line 93, in response_for_exception
    response = handle_uncaught_exception(request, get_resolver(get_urlconf()), sys.exc_info())
  File "/home/taoshu/anaconda3/lib/python3.5/site-packages/django/core/handlers/exception.py", line 142, in handle_uncaught_exception
    callback, param_dict = resolver.resolve_error_handler(500)
  File "/home/taoshu/anaconda3/lib/python3.5/site-packages/django/urls/resolvers.py", line 418, in resolve_error_handler
    callback = getattr(self.urlconf_module, 'handler%s' % view_type, None)
  File "/home/taoshu/anaconda3/lib/python3.5/site-packages/django/utils/functional.py", line 35, in __get__
    res = instance.__dict__[self.name] = self.func(instance)
  File "/home/taoshu/anaconda3/lib/python3.5/site-packages/django/urls/resolvers.py", line 398, in urlconf_module
    return import_module(self.urlconf_name)
  File "/home/taoshu/anaconda3/lib/python3.5/importlib/__init__.py", line 126, in import_module
    return _bootstrap._gcd_import(name[level:], package, level)
  File "<frozen importlib._bootstrap>", line 986, in _gcd_import
  File "<frozen importlib._bootstrap>", line 969, in _find_and_load
  File "<frozen importlib._bootstrap>", line 958, in _find_and_load_unlocked
  File "<frozen importlib._bootstrap>", line 673, in _load_unlocked
  File "<frozen importlib._bootstrap_external>", line 662, in exec_module
  File "<frozen importlib._bootstrap>", line 222, in _call_with_frames_removed
  File "/home/taoshu/tzb_databrain/engine/db_engine/db_engine/urls.py", line 20, in <module>
    from db_engine import component, hive_reader, io, robotx_spark, xml, executor, self_defined_feature, feature_combine, \
  File "/home/taoshu/tzb_databrain/engine/db_engine/db_engine/component.py", line 11, in <module>
    from executor.components.RobotXSpark import RobotXSpark
  File "/home/taoshu/tzb_databrain/engine/db_engine/executor/components/RobotXSpark.py", line 6, in <module>
    from F_SETTING import HDFS_URL
ImportError: cannot import name 'HDFS_URL'
ERROR 2018-03-21 15:00:29,862 exception 2017 140483420955608 Internal Server Error: /mydata/list_table
Traceback (most recent call last):
  File "/home/taoshu/anaconda3/lib/python3.5/site-packages/django/core/handlers/exception.py", line 41, in inner
    response = get_response(request)
  File "/home/taoshu/anaconda3/lib/python3.5/site-packages/django/utils/deprecation.py", line 138, in __call__
    response = self.process_request(request)
  File "/home/taoshu/anaconda3/lib/python3.5/site-packages/django/middleware/common.py", line 62, in process_request
    if self.should_redirect_with_slash(request):
  File "/home/taoshu/anaconda3/lib/python3.5/site-packages/django/middleware/common.py", line 80, in should_redirect_with_slash
    not is_valid_path(request.path_info, urlconf) and
  File "/home/taoshu/anaconda3/lib/python3.5/site-packages/django/urls/base.py", line 158, in is_valid_path
    resolve(path, urlconf)
  File "/home/taoshu/anaconda3/lib/python3.5/site-packages/django/urls/base.py", line 27, in resolve
    return get_resolver(urlconf).resolve(path)
  File "/home/taoshu/anaconda3/lib/python3.5/site-packages/django/urls/resolvers.py", line 362, in resolve
    for pattern in self.url_patterns:
  File "/home/taoshu/anaconda3/lib/python3.5/site-packages/django/utils/functional.py", line 35, in __get__
    res = instance.__dict__[self.name] = self.func(instance)
  File "/home/taoshu/anaconda3/lib/python3.5/site-packages/django/urls/resolvers.py", line 405, in url_patterns
    patterns = getattr(self.urlconf_module, "urlpatterns", self.urlconf_module)
  File "/home/taoshu/anaconda3/lib/python3.5/site-packages/django/utils/functional.py", line 35, in __get__
    res = instance.__dict__[self.name] = self.func(instance)
  File "/home/taoshu/anaconda3/lib/python3.5/site-packages/django/urls/resolvers.py", line 398, in urlconf_module
    return import_module(self.urlconf_name)
  File "/home/taoshu/anaconda3/lib/python3.5/importlib/__init__.py", line 126, in import_module
    return _bootstrap._gcd_import(name[level:], package, level)
  File "<frozen importlib._bootstrap>", line 986, in _gcd_import
  File "<frozen importlib._bootstrap>", line 969, in _find_and_load
  File "<frozen importlib._bootstrap>", line 958, in _find_and_load_unlocked
  File "<frozen importlib._bootstrap>", line 673, in _load_unlocked
  File "<frozen importlib._bootstrap_external>", line 662, in exec_module
  File "<frozen importlib._bootstrap>", line 222, in _call_with_frames_removed
  File "/home/taoshu/tzb_databrain/engine/db_engine/db_engine/urls.py", line 20, in <module>
    from db_engine import component, hive_reader, io, robotx_spark, xml, executor, self_defined_feature, feature_combine, \
  File "/home/taoshu/tzb_databrain/engine/db_engine/db_engine/component.py", line 11, in <module>
    from executor.components.RobotXSpark import RobotXSpark
  File "/home/taoshu/tzb_databrain/engine/db_engine/executor/components/RobotXSpark.py", line 6, in <module>
    from F_SETTING import HDFS_URL
ImportError: cannot import name 'HDFS_URL'

During handling of the above exception, another exception occurred:

Traceback (most recent call last):
  File "/home/taoshu/anaconda3/lib/python3.5/site-packages/django/core/handlers/exception.py", line 41, in inner
    response = get_response(request)
  File "/home/taoshu/anaconda3/lib/python3.5/site-packages/django/utils/deprecation.py", line 140, in __call__
    response = self.get_response(request)
  File "/home/taoshu/anaconda3/lib/python3.5/site-packages/django/core/handlers/exception.py", line 43, in inner
    response = response_for_exception(request, exc)
  File "/home/taoshu/anaconda3/lib/python3.5/site-packages/django/core/handlers/exception.py", line 93, in response_for_exception
    response = handle_uncaught_exception(request, get_resolver(get_urlconf()), sys.exc_info())
  File "/home/taoshu/anaconda3/lib/python3.5/site-packages/django/core/handlers/exception.py", line 142, in handle_uncaught_exception
    callback, param_dict = resolver.resolve_error_handler(500)
  File "/home/taoshu/anaconda3/lib/python3.5/site-packages/django/urls/resolvers.py", line 418, in resolve_error_handler
    callback = getattr(self.urlconf_module, 'handler%s' % view_type, None)
  File "/home/taoshu/anaconda3/lib/python3.5/site-packages/django/utils/functional.py", line 35, in __get__
    res = instance.__dict__[self.name] = self.func(instance)
  File "/home/taoshu/anaconda3/lib/python3.5/site-packages/django/urls/resolvers.py", line 398, in urlconf_module
    return import_module(self.urlconf_name)
  File "/home/taoshu/anaconda3/lib/python3.5/importlib/__init__.py", line 126, in import_module
    return _bootstrap._gcd_import(name[level:], package, level)
  File "<frozen importlib._bootstrap>", line 986, in _gcd_import
  File "<frozen importlib._bootstrap>", line 969, in _find_and_load
  File "<frozen importlib._bootstrap>", line 958, in _find_and_load_unlocked
  File "<frozen importlib._bootstrap>", line 673, in _load_unlocked
  File "<frozen importlib._bootstrap_external>", line 662, in exec_module
  File "<frozen importlib._bootstrap>", line 222, in _call_with_frames_removed
  File "/home/taoshu/tzb_databrain/engine/db_engine/db_engine/urls.py", line 20, in <module>
    from db_engine import component, hive_reader, io, robotx_spark, xml, executor, self_defined_feature, feature_combine, \
  File "/home/taoshu/tzb_databrain/engine/db_engine/db_engine/component.py", line 11, in <module>
    from executor.components.RobotXSpark import RobotXSpark
  File "/home/taoshu/tzb_databrain/engine/db_engine/executor/components/RobotXSpark.py", line 6, in <module>
    from F_SETTING import HDFS_URL
ImportError: cannot import name 'HDFS_URL'

During handling of the above exception, another exception occurred:

Traceback (most recent call last):
  File "/home/taoshu/anaconda3/lib/python3.5/site-packages/django/core/handlers/exception.py", line 41, in inner
    response = get_response(request)
  File "/home/taoshu/anaconda3/lib/python3.5/site-packages/django/utils/deprecation.py", line 140, in __call__
    response = self.get_response(request)
  File "/home/taoshu/anaconda3/lib/python3.5/site-packages/django/core/handlers/exception.py", line 43, in inner
    response = response_for_exception(request, exc)
  File "/home/taoshu/anaconda3/lib/python3.5/site-packages/django/core/handlers/exception.py", line 93, in response_for_exception
    response = handle_uncaught_exception(request, get_resolver(get_urlconf()), sys.exc_info())
  File "/home/taoshu/anaconda3/lib/python3.5/site-packages/django/core/handlers/exception.py", line 142, in handle_uncaught_exception
    callback, param_dict = resolver.resolve_error_handler(500)
  File "/home/taoshu/anaconda3/lib/python3.5/site-packages/django/urls/resolvers.py", line 418, in resolve_error_handler
    callback = getattr(self.urlconf_module, 'handler%s' % view_type, None)
  File "/home/taoshu/anaconda3/lib/python3.5/site-packages/django/utils/functional.py", line 35, in __get__
    res = instance.__dict__[self.name] = self.func(instance)
  File "/home/taoshu/anaconda3/lib/python3.5/site-packages/django/urls/resolvers.py", line 398, in urlconf_module
    return import_module(self.urlconf_name)
  File "/home/taoshu/anaconda3/lib/python3.5/importlib/__init__.py", line 126, in import_module
    return _bootstrap._gcd_import(name[level:], package, level)
  File "<frozen importlib._bootstrap>", line 986, in _gcd_import
  File "<frozen importlib._bootstrap>", line 969, in _find_and_load
  File "<frozen importlib._bootstrap>", line 958, in _find_and_load_unlocked
  File "<frozen importlib._bootstrap>", line 673, in _load_unlocked
  File "<frozen importlib._bootstrap_external>", line 662, in exec_module
  File "<frozen importlib._bootstrap>", line 222, in _call_with_frames_removed
  File "/home/taoshu/tzb_databrain/engine/db_engine/db_engine/urls.py", line 20, in <module>
    from db_engine import component, hive_reader, io, robotx_spark, xml, executor, self_defined_feature, feature_combine, \
  File "/home/taoshu/tzb_databrain/engine/db_engine/db_engine/component.py", line 11, in <module>
    from executor.components.RobotXSpark import RobotXSpark
  File "/home/taoshu/tzb_databrain/engine/db_engine/executor/components/RobotXSpark.py", line 6, in <module>
    from F_SETTING import HDFS_URL
ImportError: cannot import name 'HDFS_URL'

During handling of the above exception, another exception occurred:

Traceback (most recent call last):
  File "/home/taoshu/anaconda3/lib/python3.5/site-packages/django/core/handlers/exception.py", line 41, in inner
    response = get_response(request)
  File "/home/taoshu/anaconda3/lib/python3.5/site-packages/django/utils/deprecation.py", line 140, in __call__
    response = self.get_response(request)
  File "/home/taoshu/anaconda3/lib/python3.5/site-packages/django/core/handlers/exception.py", line 43, in inner
    response = response_for_exception(request, exc)
  File "/home/taoshu/anaconda3/lib/python3.5/site-packages/django/core/handlers/exception.py", line 93, in response_for_exception
    response = handle_uncaught_exception(request, get_resolver(get_urlconf()), sys.exc_info())
  File "/home/taoshu/anaconda3/lib/python3.5/site-packages/django/core/handlers/exception.py", line 142, in handle_uncaught_exception
    callback, param_dict = resolver.resolve_error_handler(500)
  File "/home/taoshu/anaconda3/lib/python3.5/site-packages/django/urls/resolvers.py", line 418, in resolve_error_handler
    callback = getattr(self.urlconf_module, 'handler%s' % view_type, None)
  File "/home/taoshu/anaconda3/lib/python3.5/site-packages/django/utils/functional.py", line 35, in __get__
    res = instance.__dict__[self.name] = self.func(instance)
  File "/home/taoshu/anaconda3/lib/python3.5/site-packages/django/urls/resolvers.py", line 398, in urlconf_module
    return import_module(self.urlconf_name)
  File "/home/taoshu/anaconda3/lib/python3.5/importlib/__init__.py", line 126, in import_module
    return _bootstrap._gcd_import(name[level:], package, level)
  File "<frozen importlib._bootstrap>", line 986, in _gcd_import
  File "<frozen importlib._bootstrap>", line 969, in _find_and_load
  File "<frozen importlib._bootstrap>", line 958, in _find_and_load_unlocked
  File "<frozen importlib._bootstrap>", line 673, in _load_unlocked
  File "<frozen importlib._bootstrap_external>", line 662, in exec_module
  File "<frozen importlib._bootstrap>", line 222, in _call_with_frames_removed
  File "/home/taoshu/tzb_databrain/engine/db_engine/db_engine/urls.py", line 20, in <module>
    from db_engine import component, hive_reader, io, robotx_spark, xml, executor, self_defined_feature, feature_combine, \
  File "/home/taoshu/tzb_databrain/engine/db_engine/db_engine/component.py", line 11, in <module>
    from executor.components.RobotXSpark import RobotXSpark
  File "/home/taoshu/tzb_databrain/engine/db_engine/executor/components/RobotXSpark.py", line 6, in <module>
    from F_SETTING import HDFS_URL
ImportError: cannot import name 'HDFS_URL'
ERROR 2018-03-21 15:00:31,628 exception 2017 140483419978944 Internal Server Error: /mydata/list_table
Traceback (most recent call last):
  File "/home/taoshu/anaconda3/lib/python3.5/site-packages/django/core/handlers/exception.py", line 41, in inner
    response = get_response(request)
  File "/home/taoshu/anaconda3/lib/python3.5/site-packages/django/utils/deprecation.py", line 138, in __call__
    response = self.process_request(request)
  File "/home/taoshu/anaconda3/lib/python3.5/site-packages/django/middleware/common.py", line 62, in process_request
    if self.should_redirect_with_slash(request):
  File "/home/taoshu/anaconda3/lib/python3.5/site-packages/django/middleware/common.py", line 80, in should_redirect_with_slash
    not is_valid_path(request.path_info, urlconf) and
  File "/home/taoshu/anaconda3/lib/python3.5/site-packages/django/urls/base.py", line 158, in is_valid_path
    resolve(path, urlconf)
  File "/home/taoshu/anaconda3/lib/python3.5/site-packages/django/urls/base.py", line 27, in resolve
    return get_resolver(urlconf).resolve(path)
  File "/home/taoshu/anaconda3/lib/python3.5/site-packages/django/urls/resolvers.py", line 362, in resolve
    for pattern in self.url_patterns:
  File "/home/taoshu/anaconda3/lib/python3.5/site-packages/django/utils/functional.py", line 35, in __get__
    res = instance.__dict__[self.name] = self.func(instance)
  File "/home/taoshu/anaconda3/lib/python3.5/site-packages/django/urls/resolvers.py", line 405, in url_patterns
    patterns = getattr(self.urlconf_module, "urlpatterns", self.urlconf_module)
  File "/home/taoshu/anaconda3/lib/python3.5/site-packages/django/utils/functional.py", line 35, in __get__
    res = instance.__dict__[self.name] = self.func(instance)
  File "/home/taoshu/anaconda3/lib/python3.5/site-packages/django/urls/resolvers.py", line 398, in urlconf_module
    return import_module(self.urlconf_name)
  File "/home/taoshu/anaconda3/lib/python3.5/importlib/__init__.py", line 126, in import_module
    return _bootstrap._gcd_import(name[level:], package, level)
  File "<frozen importlib._bootstrap>", line 986, in _gcd_import
  File "<frozen importlib._bootstrap>", line 969, in _find_and_load
  File "<frozen importlib._bootstrap>", line 958, in _find_and_load_unlocked
  File "<frozen importlib._bootstrap>", line 673, in _load_unlocked
  File "<frozen importlib._bootstrap_external>", line 662, in exec_module
  File "<frozen importlib._bootstrap>", line 222, in _call_with_frames_removed
  File "/home/taoshu/tzb_databrain/engine/db_engine/db_engine/urls.py", line 20, in <module>
    from db_engine import component, hive_reader, io, robotx_spark, xml, executor, self_defined_feature, feature_combine, \
  File "/home/taoshu/tzb_databrain/engine/db_engine/db_engine/component.py", line 11, in <module>
    from executor.components.RobotXSpark import RobotXSpark
  File "/home/taoshu/tzb_databrain/engine/db_engine/executor/components/RobotXSpark.py", line 6, in <module>
    from F_SETTING import HDFS_URL
ImportError: cannot import name 'HDFS_URL'
ERROR 2018-03-21 15:00:31,631 exception 2017 140483419978944 Internal Server Error: /mydata/list_table
Traceback (most recent call last):
  File "/home/taoshu/anaconda3/lib/python3.5/site-packages/django/core/handlers/exception.py", line 41, in inner
    response = get_response(request)
  File "/home/taoshu/anaconda3/lib/python3.5/site-packages/django/utils/deprecation.py", line 138, in __call__
    response = self.process_request(request)
  File "/home/taoshu/anaconda3/lib/python3.5/site-packages/django/middleware/common.py", line 62, in process_request
    if self.should_redirect_with_slash(request):
  File "/home/taoshu/anaconda3/lib/python3.5/site-packages/django/middleware/common.py", line 80, in should_redirect_with_slash
    not is_valid_path(request.path_info, urlconf) and
  File "/home/taoshu/anaconda3/lib/python3.5/site-packages/django/urls/base.py", line 158, in is_valid_path
    resolve(path, urlconf)
  File "/home/taoshu/anaconda3/lib/python3.5/site-packages/django/urls/base.py", line 27, in resolve
    return get_resolver(urlconf).resolve(path)
  File "/home/taoshu/anaconda3/lib/python3.5/site-packages/django/urls/resolvers.py", line 362, in resolve
    for pattern in self.url_patterns:
  File "/home/taoshu/anaconda3/lib/python3.5/site-packages/django/utils/functional.py", line 35, in __get__
    res = instance.__dict__[self.name] = self.func(instance)
  File "/home/taoshu/anaconda3/lib/python3.5/site-packages/django/urls/resolvers.py", line 405, in url_patterns
    patterns = getattr(self.urlconf_module, "urlpatterns", self.urlconf_module)
  File "/home/taoshu/anaconda3/lib/python3.5/site-packages/django/utils/functional.py", line 35, in __get__
    res = instance.__dict__[self.name] = self.func(instance)
  File "/home/taoshu/anaconda3/lib/python3.5/site-packages/django/urls/resolvers.py", line 398, in urlconf_module
    return import_module(self.urlconf_name)
  File "/home/taoshu/anaconda3/lib/python3.5/importlib/__init__.py", line 126, in import_module
    return _bootstrap._gcd_import(name[level:], package, level)
  File "<frozen importlib._bootstrap>", line 986, in _gcd_import
  File "<frozen importlib._bootstrap>", line 969, in _find_and_load
  File "<frozen importlib._bootstrap>", line 958, in _find_and_load_unlocked
  File "<frozen importlib._bootstrap>", line 673, in _load_unlocked
  File "<frozen importlib._bootstrap_external>", line 662, in exec_module
  File "<frozen importlib._bootstrap>", line 222, in _call_with_frames_removed
  File "/home/taoshu/tzb_databrain/engine/db_engine/db_engine/urls.py", line 20, in <module>
    from db_engine import component, hive_reader, io, robotx_spark, xml, executor, self_defined_feature, feature_combine, \
  File "/home/taoshu/tzb_databrain/engine/db_engine/db_engine/component.py", line 11, in <module>
    from executor.components.RobotXSpark import RobotXSpark
  File "/home/taoshu/tzb_databrain/engine/db_engine/executor/components/RobotXSpark.py", line 6, in <module>
    from F_SETTING import HDFS_URL
ImportError: cannot import name 'HDFS_URL'

During handling of the above exception, another exception occurred:

Traceback (most recent call last):
  File "/home/taoshu/anaconda3/lib/python3.5/site-packages/django/core/handlers/exception.py", line 41, in inner
    response = get_response(request)
  File "/home/taoshu/anaconda3/lib/python3.5/site-packages/django/utils/deprecation.py", line 140, in __call__
    response = self.get_response(request)
  File "/home/taoshu/anaconda3/lib/python3.5/site-packages/django/core/handlers/exception.py", line 43, in inner
    response = response_for_exception(request, exc)
  File "/home/taoshu/anaconda3/lib/python3.5/site-packages/django/core/handlers/exception.py", line 93, in response_for_exception
    response = handle_uncaught_exception(request, get_resolver(get_urlconf()), sys.exc_info())
  File "/home/taoshu/anaconda3/lib/python3.5/site-packages/django/core/handlers/exception.py", line 142, in handle_uncaught_exception
    callback, param_dict = resolver.resolve_error_handler(500)
  File "/home/taoshu/anaconda3/lib/python3.5/site-packages/django/urls/resolvers.py", line 418, in resolve_error_handler
    callback = getattr(self.urlconf_module, 'handler%s' % view_type, None)
  File "/home/taoshu/anaconda3/lib/python3.5/site-packages/django/utils/functional.py", line 35, in __get__
    res = instance.__dict__[self.name] = self.func(instance)
  File "/home/taoshu/anaconda3/lib/python3.5/site-packages/django/urls/resolvers.py", line 398, in urlconf_module
    return import_module(self.urlconf_name)
  File "/home/taoshu/anaconda3/lib/python3.5/importlib/__init__.py", line 126, in import_module
    return _bootstrap._gcd_import(name[level:], package, level)
  File "<frozen importlib._bootstrap>", line 986, in _gcd_import
  File "<frozen importlib._bootstrap>", line 969, in _find_and_load
  File "<frozen importlib._bootstrap>", line 958, in _find_and_load_unlocked
  File "<frozen importlib._bootstrap>", line 673, in _load_unlocked
  File "<frozen importlib._bootstrap_external>", line 662, in exec_module
  File "<frozen importlib._bootstrap>", line 222, in _call_with_frames_removed
  File "/home/taoshu/tzb_databrain/engine/db_engine/db_engine/urls.py", line 20, in <module>
    from db_engine import component, hive_reader, io, robotx_spark, xml, executor, self_defined_feature, feature_combine, \
  File "/home/taoshu/tzb_databrain/engine/db_engine/db_engine/component.py", line 11, in <module>
    from executor.components.RobotXSpark import RobotXSpark
  File "/home/taoshu/tzb_databrain/engine/db_engine/executor/components/RobotXSpark.py", line 6, in <module>
    from F_SETTING import HDFS_URL
ImportError: cannot import name 'HDFS_URL'
ERROR 2018-03-21 15:00:31,632 exception 2017 140483419978944 Internal Server Error: /mydata/list_table
Traceback (most recent call last):
  File "/home/taoshu/anaconda3/lib/python3.5/site-packages/django/core/handlers/exception.py", line 41, in inner
    response = get_response(request)
  File "/home/taoshu/anaconda3/lib/python3.5/site-packages/django/utils/deprecation.py", line 138, in __call__
    response = self.process_request(request)
  File "/home/taoshu/anaconda3/lib/python3.5/site-packages/django/middleware/common.py", line 62, in process_request
    if self.should_redirect_with_slash(request):
  File "/home/taoshu/anaconda3/lib/python3.5/site-packages/django/middleware/common.py", line 80, in should_redirect_with_slash
    not is_valid_path(request.path_info, urlconf) and
  File "/home/taoshu/anaconda3/lib/python3.5/site-packages/django/urls/base.py", line 158, in is_valid_path
    resolve(path, urlconf)
  File "/home/taoshu/anaconda3/lib/python3.5/site-packages/django/urls/base.py", line 27, in resolve
    return get_resolver(urlconf).resolve(path)
  File "/home/taoshu/anaconda3/lib/python3.5/site-packages/django/urls/resolvers.py", line 362, in resolve
    for pattern in self.url_patterns:
  File "/home/taoshu/anaconda3/lib/python3.5/site-packages/django/utils/functional.py", line 35, in __get__
    res = instance.__dict__[self.name] = self.func(instance)
  File "/home/taoshu/anaconda3/lib/python3.5/site-packages/django/urls/resolvers.py", line 405, in url_patterns
    patterns = getattr(self.urlconf_module, "urlpatterns", self.urlconf_module)
  File "/home/taoshu/anaconda3/lib/python3.5/site-packages/django/utils/functional.py", line 35, in __get__
    res = instance.__dict__[self.name] = self.func(instance)
  File "/home/taoshu/anaconda3/lib/python3.5/site-packages/django/urls/resolvers.py", line 398, in urlconf_module
    return import_module(self.urlconf_name)
  File "/home/taoshu/anaconda3/lib/python3.5/importlib/__init__.py", line 126, in import_module
    return _bootstrap._gcd_import(name[level:], package, level)
  File "<frozen importlib._bootstrap>", line 986, in _gcd_import
  File "<frozen importlib._bootstrap>", line 969, in _find_and_load
  File "<frozen importlib._bootstrap>", line 958, in _find_and_load_unlocked
  File "<frozen importlib._bootstrap>", line 673, in _load_unlocked
  File "<frozen importlib._bootstrap_external>", line 662, in exec_module
  File "<frozen importlib._bootstrap>", line 222, in _call_with_frames_removed
  File "/home/taoshu/tzb_databrain/engine/db_engine/db_engine/urls.py", line 20, in <module>
    from db_engine import component, hive_reader, io, robotx_spark, xml, executor, self_defined_feature, feature_combine, \
  File "/home/taoshu/tzb_databrain/engine/db_engine/db_engine/component.py", line 11, in <module>
    from executor.components.RobotXSpark import RobotXSpark
  File "/home/taoshu/tzb_databrain/engine/db_engine/executor/components/RobotXSpark.py", line 6, in <module>
    from F_SETTING import HDFS_URL
ImportError: cannot import name 'HDFS_URL'

During handling of the above exception, another exception occurred:

Traceback (most recent call last):
  File "/home/taoshu/anaconda3/lib/python3.5/site-packages/django/core/handlers/exception.py", line 41, in inner
    response = get_response(request)
  File "/home/taoshu/anaconda3/lib/python3.5/site-packages/django/utils/deprecation.py", line 140, in __call__
    response = self.get_response(request)
  File "/home/taoshu/anaconda3/lib/python3.5/site-packages/django/core/handlers/exception.py", line 43, in inner
    response = response_for_exception(request, exc)
  File "/home/taoshu/anaconda3/lib/python3.5/site-packages/django/core/handlers/exception.py", line 93, in response_for_exception
    response = handle_uncaught_exception(request, get_resolver(get_urlconf()), sys.exc_info())
  File "/home/taoshu/anaconda3/lib/python3.5/site-packages/django/core/handlers/exception.py", line 142, in handle_uncaught_exception
    callback, param_dict = resolver.resolve_error_handler(500)
  File "/home/taoshu/anaconda3/lib/python3.5/site-packages/django/urls/resolvers.py", line 418, in resolve_error_handler
    callback = getattr(self.urlconf_module, 'handler%s' % view_type, None)
  File "/home/taoshu/anaconda3/lib/python3.5/site-packages/django/utils/functional.py", line 35, in __get__
    res = instance.__dict__[self.name] = self.func(instance)
  File "/home/taoshu/anaconda3/lib/python3.5/site-packages/django/urls/resolvers.py", line 398, in urlconf_module
    return import_module(self.urlconf_name)
  File "/home/taoshu/anaconda3/lib/python3.5/importlib/__init__.py", line 126, in import_module
    return _bootstrap._gcd_import(name[level:], package, level)
  File "<frozen importlib._bootstrap>", line 986, in _gcd_import
  File "<frozen importlib._bootstrap>", line 969, in _find_and_load
  File "<frozen importlib._bootstrap>", line 958, in _find_and_load_unlocked
  File "<frozen importlib._bootstrap>", line 673, in _load_unlocked
  File "<frozen importlib._bootstrap_external>", line 662, in exec_module
  File "<frozen importlib._bootstrap>", line 222, in _call_with_frames_removed
  File "/home/taoshu/tzb_databrain/engine/db_engine/db_engine/urls.py", line 20, in <module>
    from db_engine import component, hive_reader, io, robotx_spark, xml, executor, self_defined_feature, feature_combine, \
  File "/home/taoshu/tzb_databrain/engine/db_engine/db_engine/component.py", line 11, in <module>
    from executor.components.RobotXSpark import RobotXSpark
  File "/home/taoshu/tzb_databrain/engine/db_engine/executor/components/RobotXSpark.py", line 6, in <module>
    from F_SETTING import HDFS_URL
ImportError: cannot import name 'HDFS_URL'

During handling of the above exception, another exception occurred:

Traceback (most recent call last):
  File "/home/taoshu/anaconda3/lib/python3.5/site-packages/django/core/handlers/exception.py", line 41, in inner
    response = get_response(request)
  File "/home/taoshu/anaconda3/lib/python3.5/site-packages/django/utils/deprecation.py", line 140, in __call__
    response = self.get_response(request)
  File "/home/taoshu/anaconda3/lib/python3.5/site-packages/django/core/handlers/exception.py", line 43, in inner
    response = response_for_exception(request, exc)
  File "/home/taoshu/anaconda3/lib/python3.5/site-packages/django/core/handlers/exception.py", line 93, in response_for_exception
    response = handle_uncaught_exception(request, get_resolver(get_urlconf()), sys.exc_info())
  File "/home/taoshu/anaconda3/lib/python3.5/site-packages/django/core/handlers/exception.py", line 142, in handle_uncaught_exception
    callback, param_dict = resolver.resolve_error_handler(500)
  File "/home/taoshu/anaconda3/lib/python3.5/site-packages/django/urls/resolvers.py", line 418, in resolve_error_handler
    callback = getattr(self.urlconf_module, 'handler%s' % view_type, None)
  File "/home/taoshu/anaconda3/lib/python3.5/site-packages/django/utils/functional.py", line 35, in __get__
    res = instance.__dict__[self.name] = self.func(instance)
  File "/home/taoshu/anaconda3/lib/python3.5/site-packages/django/urls/resolvers.py", line 398, in urlconf_module
    return import_module(self.urlconf_name)
  File "/home/taoshu/anaconda3/lib/python3.5/importlib/__init__.py", line 126, in import_module
    return _bootstrap._gcd_import(name[level:], package, level)
  File "<frozen importlib._bootstrap>", line 986, in _gcd_import
  File "<frozen importlib._bootstrap>", line 969, in _find_and_load
  File "<frozen importlib._bootstrap>", line 958, in _find_and_load_unlocked
  File "<frozen importlib._bootstrap>", line 673, in _load_unlocked
  File "<frozen importlib._bootstrap_external>", line 662, in exec_module
  File "<frozen importlib._bootstrap>", line 222, in _call_with_frames_removed
  File "/home/taoshu/tzb_databrain/engine/db_engine/db_engine/urls.py", line 20, in <module>
    from db_engine import component, hive_reader, io, robotx_spark, xml, executor, self_defined_feature, feature_combine, \
  File "/home/taoshu/tzb_databrain/engine/db_engine/db_engine/component.py", line 11, in <module>
    from executor.components.RobotXSpark import RobotXSpark
  File "/home/taoshu/tzb_databrain/engine/db_engine/executor/components/RobotXSpark.py", line 6, in <module>
    from F_SETTING import HDFS_URL
ImportError: cannot import name 'HDFS_URL'
ERROR 2018-03-21 15:00:31,634 exception 2017 140483419978944 Internal Server Error: /mydata/list_table
Traceback (most recent call last):
  File "/home/taoshu/anaconda3/lib/python3.5/site-packages/django/core/handlers/exception.py", line 41, in inner
    response = get_response(request)
  File "/home/taoshu/anaconda3/lib/python3.5/site-packages/django/utils/deprecation.py", line 138, in __call__
    response = self.process_request(request)
  File "/home/taoshu/anaconda3/lib/python3.5/site-packages/django/middleware/common.py", line 62, in process_request
    if self.should_redirect_with_slash(request):
  File "/home/taoshu/anaconda3/lib/python3.5/site-packages/django/middleware/common.py", line 80, in should_redirect_with_slash
    not is_valid_path(request.path_info, urlconf) and
  File "/home/taoshu/anaconda3/lib/python3.5/site-packages/django/urls/base.py", line 158, in is_valid_path
    resolve(path, urlconf)
  File "/home/taoshu/anaconda3/lib/python3.5/site-packages/django/urls/base.py", line 27, in resolve
    return get_resolver(urlconf).resolve(path)
  File "/home/taoshu/anaconda3/lib/python3.5/site-packages/django/urls/resolvers.py", line 362, in resolve
    for pattern in self.url_patterns:
  File "/home/taoshu/anaconda3/lib/python3.5/site-packages/django/utils/functional.py", line 35, in __get__
    res = instance.__dict__[self.name] = self.func(instance)
  File "/home/taoshu/anaconda3/lib/python3.5/site-packages/django/urls/resolvers.py", line 405, in url_patterns
    patterns = getattr(self.urlconf_module, "urlpatterns", self.urlconf_module)
  File "/home/taoshu/anaconda3/lib/python3.5/site-packages/django/utils/functional.py", line 35, in __get__
    res = instance.__dict__[self.name] = self.func(instance)
  File "/home/taoshu/anaconda3/lib/python3.5/site-packages/django/urls/resolvers.py", line 398, in urlconf_module
    return import_module(self.urlconf_name)
  File "/home/taoshu/anaconda3/lib/python3.5/importlib/__init__.py", line 126, in import_module
    return _bootstrap._gcd_import(name[level:], package, level)
  File "<frozen importlib._bootstrap>", line 986, in _gcd_import
  File "<frozen importlib._bootstrap>", line 969, in _find_and_load
  File "<frozen importlib._bootstrap>", line 958, in _find_and_load_unlocked
  File "<frozen importlib._bootstrap>", line 673, in _load_unlocked
  File "<frozen importlib._bootstrap_external>", line 662, in exec_module
  File "<frozen importlib._bootstrap>", line 222, in _call_with_frames_removed
  File "/home/taoshu/tzb_databrain/engine/db_engine/db_engine/urls.py", line 20, in <module>
    from db_engine import component, hive_reader, io, robotx_spark, xml, executor, self_defined_feature, feature_combine, \
  File "/home/taoshu/tzb_databrain/engine/db_engine/db_engine/component.py", line 11, in <module>
    from executor.components.RobotXSpark import RobotXSpark
  File "/home/taoshu/tzb_databrain/engine/db_engine/executor/components/RobotXSpark.py", line 6, in <module>
    from F_SETTING import HDFS_URL
ImportError: cannot import name 'HDFS_URL'

During handling of the above exception, another exception occurred:

Traceback (most recent call last):
  File "/home/taoshu/anaconda3/lib/python3.5/site-packages/django/core/handlers/exception.py", line 41, in inner
    response = get_response(request)
  File "/home/taoshu/anaconda3/lib/python3.5/site-packages/django/utils/deprecation.py", line 140, in __call__
    response = self.get_response(request)
  File "/home/taoshu/anaconda3/lib/python3.5/site-packages/django/core/handlers/exception.py", line 43, in inner
    response = response_for_exception(request, exc)
  File "/home/taoshu/anaconda3/lib/python3.5/site-packages/django/core/handlers/exception.py", line 93, in response_for_exception
    response = handle_uncaught_exception(request, get_resolver(get_urlconf()), sys.exc_info())
  File "/home/taoshu/anaconda3/lib/python3.5/site-packages/django/core/handlers/exception.py", line 142, in handle_uncaught_exception
    callback, param_dict = resolver.resolve_error_handler(500)
  File "/home/taoshu/anaconda3/lib/python3.5/site-packages/django/urls/resolvers.py", line 418, in resolve_error_handler
    callback = getattr(self.urlconf_module, 'handler%s' % view_type, None)
  File "/home/taoshu/anaconda3/lib/python3.5/site-packages/django/utils/functional.py", line 35, in __get__
    res = instance.__dict__[self.name] = self.func(instance)
  File "/home/taoshu/anaconda3/lib/python3.5/site-packages/django/urls/resolvers.py", line 398, in urlconf_module
    return import_module(self.urlconf_name)
  File "/home/taoshu/anaconda3/lib/python3.5/importlib/__init__.py", line 126, in import_module
    return _bootstrap._gcd_import(name[level:], package, level)
  File "<frozen importlib._bootstrap>", line 986, in _gcd_import
  File "<frozen importlib._bootstrap>", line 969, in _find_and_load
  File "<frozen importlib._bootstrap>", line 958, in _find_and_load_unlocked
  File "<frozen importlib._bootstrap>", line 673, in _load_unlocked
  File "<frozen importlib._bootstrap_external>", line 662, in exec_module
  File "<frozen importlib._bootstrap>", line 222, in _call_with_frames_removed
  File "/home/taoshu/tzb_databrain/engine/db_engine/db_engine/urls.py", line 20, in <module>
    from db_engine import component, hive_reader, io, robotx_spark, xml, executor, self_defined_feature, feature_combine, \
  File "/home/taoshu/tzb_databrain/engine/db_engine/db_engine/component.py", line 11, in <module>
    from executor.components.RobotXSpark import RobotXSpark
  File "/home/taoshu/tzb_databrain/engine/db_engine/executor/components/RobotXSpark.py", line 6, in <module>
    from F_SETTING import HDFS_URL
ImportError: cannot import name 'HDFS_URL'

During handling of the above exception, another exception occurred:

Traceback (most recent call last):
  File "/home/taoshu/anaconda3/lib/python3.5/site-packages/django/core/handlers/exception.py", line 41, in inner
    response = get_response(request)
  File "/home/taoshu/anaconda3/lib/python3.5/site-packages/django/utils/deprecation.py", line 140, in __call__
    response = self.get_response(request)
  File "/home/taoshu/anaconda3/lib/python3.5/site-packages/django/core/handlers/exception.py", line 43, in inner
    response = response_for_exception(request, exc)
  File "/home/taoshu/anaconda3/lib/python3.5/site-packages/django/core/handlers/exception.py", line 93, in response_for_exception
    response = handle_uncaught_exception(request, get_resolver(get_urlconf()), sys.exc_info())
  File "/home/taoshu/anaconda3/lib/python3.5/site-packages/django/core/handlers/exception.py", line 142, in handle_uncaught_exception
    callback, param_dict = resolver.resolve_error_handler(500)
  File "/home/taoshu/anaconda3/lib/python3.5/site-packages/django/urls/resolvers.py", line 418, in resolve_error_handler
    callback = getattr(self.urlconf_module, 'handler%s' % view_type, None)
  File "/home/taoshu/anaconda3/lib/python3.5/site-packages/django/utils/functional.py", line 35, in __get__
    res = instance.__dict__[self.name] = self.func(instance)
  File "/home/taoshu/anaconda3/lib/python3.5/site-packages/django/urls/resolvers.py", line 398, in urlconf_module
    return import_module(self.urlconf_name)
  File "/home/taoshu/anaconda3/lib/python3.5/importlib/__init__.py", line 126, in import_module
    return _bootstrap._gcd_import(name[level:], package, level)
  File "<frozen importlib._bootstrap>", line 986, in _gcd_import
  File "<frozen importlib._bootstrap>", line 969, in _find_and_load
  File "<frozen importlib._bootstrap>", line 958, in _find_and_load_unlocked
  File "<frozen importlib._bootstrap>", line 673, in _load_unlocked
  File "<frozen importlib._bootstrap_external>", line 662, in exec_module
  File "<frozen importlib._bootstrap>", line 222, in _call_with_frames_removed
  File "/home/taoshu/tzb_databrain/engine/db_engine/db_engine/urls.py", line 20, in <module>
    from db_engine import component, hive_reader, io, robotx_spark, xml, executor, self_defined_feature, feature_combine, \
  File "/home/taoshu/tzb_databrain/engine/db_engine/db_engine/component.py", line 11, in <module>
    from executor.components.RobotXSpark import RobotXSpark
  File "/home/taoshu/tzb_databrain/engine/db_engine/executor/components/RobotXSpark.py", line 6, in <module>
    from F_SETTING import HDFS_URL
ImportError: cannot import name 'HDFS_URL'

During handling of the above exception, another exception occurred:

Traceback (most recent call last):
  File "/home/taoshu/anaconda3/lib/python3.5/site-packages/django/core/handlers/exception.py", line 41, in inner
    response = get_response(request)
  File "/home/taoshu/anaconda3/lib/python3.5/site-packages/django/utils/deprecation.py", line 140, in __call__
    response = self.get_response(request)
  File "/home/taoshu/anaconda3/lib/python3.5/site-packages/django/core/handlers/exception.py", line 43, in inner
    response = response_for_exception(request, exc)
  File "/home/taoshu/anaconda3/lib/python3.5/site-packages/django/core/handlers/exception.py", line 93, in response_for_exception
    response = handle_uncaught_exception(request, get_resolver(get_urlconf()), sys.exc_info())
  File "/home/taoshu/anaconda3/lib/python3.5/site-packages/django/core/handlers/exception.py", line 142, in handle_uncaught_exception
    callback, param_dict = resolver.resolve_error_handler(500)
  File "/home/taoshu/anaconda3/lib/python3.5/site-packages/django/urls/resolvers.py", line 418, in resolve_error_handler
    callback = getattr(self.urlconf_module, 'handler%s' % view_type, None)
  File "/home/taoshu/anaconda3/lib/python3.5/site-packages/django/utils/functional.py", line 35, in __get__
    res = instance.__dict__[self.name] = self.func(instance)
  File "/home/taoshu/anaconda3/lib/python3.5/site-packages/django/urls/resolvers.py", line 398, in urlconf_module
    return import_module(self.urlconf_name)
  File "/home/taoshu/anaconda3/lib/python3.5/importlib/__init__.py", line 126, in import_module
    return _bootstrap._gcd_import(name[level:], package, level)
  File "<frozen importlib._bootstrap>", line 986, in _gcd_import
  File "<frozen importlib._bootstrap>", line 969, in _find_and_load
  File "<frozen importlib._bootstrap>", line 958, in _find_and_load_unlocked
  File "<frozen importlib._bootstrap>", line 673, in _load_unlocked
  File "<frozen importlib._bootstrap_external>", line 662, in exec_module
  File "<frozen importlib._bootstrap>", line 222, in _call_with_frames_removed
  File "/home/taoshu/tzb_databrain/engine/db_engine/db_engine/urls.py", line 20, in <module>
    from db_engine import component, hive_reader, io, robotx_spark, xml, executor, self_defined_feature, feature_combine, \
  File "/home/taoshu/tzb_databrain/engine/db_engine/db_engine/component.py", line 11, in <module>
    from executor.components.RobotXSpark import RobotXSpark
  File "/home/taoshu/tzb_databrain/engine/db_engine/executor/components/RobotXSpark.py", line 6, in <module>
    from F_SETTING import HDFS_URL
ImportError: cannot import name 'HDFS_URL'
ERROR 2018-03-21 15:00:32,302 exception 2017 140483409185832 Internal Server Error: /mydata/list_table
Traceback (most recent call last):
  File "/home/taoshu/anaconda3/lib/python3.5/site-packages/django/core/handlers/exception.py", line 41, in inner
    response = get_response(request)
  File "/home/taoshu/anaconda3/lib/python3.5/site-packages/django/utils/deprecation.py", line 138, in __call__
    response = self.process_request(request)
  File "/home/taoshu/anaconda3/lib/python3.5/site-packages/django/middleware/common.py", line 62, in process_request
    if self.should_redirect_with_slash(request):
  File "/home/taoshu/anaconda3/lib/python3.5/site-packages/django/middleware/common.py", line 80, in should_redirect_with_slash
    not is_valid_path(request.path_info, urlconf) and
  File "/home/taoshu/anaconda3/lib/python3.5/site-packages/django/urls/base.py", line 158, in is_valid_path
    resolve(path, urlconf)
  File "/home/taoshu/anaconda3/lib/python3.5/site-packages/django/urls/base.py", line 27, in resolve
    return get_resolver(urlconf).resolve(path)
  File "/home/taoshu/anaconda3/lib/python3.5/site-packages/django/urls/resolvers.py", line 362, in resolve
    for pattern in self.url_patterns:
  File "/home/taoshu/anaconda3/lib/python3.5/site-packages/django/utils/functional.py", line 35, in __get__
    res = instance.__dict__[self.name] = self.func(instance)
  File "/home/taoshu/anaconda3/lib/python3.5/site-packages/django/urls/resolvers.py", line 405, in url_patterns
    patterns = getattr(self.urlconf_module, "urlpatterns", self.urlconf_module)
  File "/home/taoshu/anaconda3/lib/python3.5/site-packages/django/utils/functional.py", line 35, in __get__
    res = instance.__dict__[self.name] = self.func(instance)
  File "/home/taoshu/anaconda3/lib/python3.5/site-packages/django/urls/resolvers.py", line 398, in urlconf_module
    return import_module(self.urlconf_name)
  File "/home/taoshu/anaconda3/lib/python3.5/importlib/__init__.py", line 126, in import_module
    return _bootstrap._gcd_import(name[level:], package, level)
  File "<frozen importlib._bootstrap>", line 986, in _gcd_import
  File "<frozen importlib._bootstrap>", line 969, in _find_and_load
  File "<frozen importlib._bootstrap>", line 958, in _find_and_load_unlocked
  File "<frozen importlib._bootstrap>", line 673, in _load_unlocked
  File "<frozen importlib._bootstrap_external>", line 662, in exec_module
  File "<frozen importlib._bootstrap>", line 222, in _call_with_frames_removed
  File "/home/taoshu/tzb_databrain/engine/db_engine/db_engine/urls.py", line 20, in <module>
    from db_engine import component, hive_reader, io, robotx_spark, xml, executor, self_defined_feature, feature_combine, \
  File "/home/taoshu/tzb_databrain/engine/db_engine/db_engine/component.py", line 11, in <module>
    from executor.components.RobotXSpark import RobotXSpark
  File "/home/taoshu/tzb_databrain/engine/db_engine/executor/components/RobotXSpark.py", line 6, in <module>
    from F_SETTING import HDFS_URL
ImportError: cannot import name 'HDFS_URL'
ERROR 2018-03-21 15:00:32,305 exception 2017 140483409185832 Internal Server Error: /mydata/list_table
Traceback (most recent call last):
  File "/home/taoshu/anaconda3/lib/python3.5/site-packages/django/core/handlers/exception.py", line 41, in inner
    response = get_response(request)
  File "/home/taoshu/anaconda3/lib/python3.5/site-packages/django/utils/deprecation.py", line 138, in __call__
    response = self.process_request(request)
  File "/home/taoshu/anaconda3/lib/python3.5/site-packages/django/middleware/common.py", line 62, in process_request
    if self.should_redirect_with_slash(request):
  File "/home/taoshu/anaconda3/lib/python3.5/site-packages/django/middleware/common.py", line 80, in should_redirect_with_slash
    not is_valid_path(request.path_info, urlconf) and
  File "/home/taoshu/anaconda3/lib/python3.5/site-packages/django/urls/base.py", line 158, in is_valid_path
    resolve(path, urlconf)
  File "/home/taoshu/anaconda3/lib/python3.5/site-packages/django/urls/base.py", line 27, in resolve
    return get_resolver(urlconf).resolve(path)
  File "/home/taoshu/anaconda3/lib/python3.5/site-packages/django/urls/resolvers.py", line 362, in resolve
    for pattern in self.url_patterns:
  File "/home/taoshu/anaconda3/lib/python3.5/site-packages/django/utils/functional.py", line 35, in __get__
    res = instance.__dict__[self.name] = self.func(instance)
  File "/home/taoshu/anaconda3/lib/python3.5/site-packages/django/urls/resolvers.py", line 405, in url_patterns
    patterns = getattr(self.urlconf_module, "urlpatterns", self.urlconf_module)
  File "/home/taoshu/anaconda3/lib/python3.5/site-packages/django/utils/functional.py", line 35, in __get__
    res = instance.__dict__[self.name] = self.func(instance)
  File "/home/taoshu/anaconda3/lib/python3.5/site-packages/django/urls/resolvers.py", line 398, in urlconf_module
    return import_module(self.urlconf_name)
  File "/home/taoshu/anaconda3/lib/python3.5/importlib/__init__.py", line 126, in import_module
    return _bootstrap._gcd_import(name[level:], package, level)
  File "<frozen importlib._bootstrap>", line 986, in _gcd_import
  File "<frozen importlib._bootstrap>", line 969, in _find_and_load
  File "<frozen importlib._bootstrap>", line 958, in _find_and_load_unlocked
  File "<frozen importlib._bootstrap>", line 673, in _load_unlocked
  File "<frozen importlib._bootstrap_external>", line 662, in exec_module
  File "<frozen importlib._bootstrap>", line 222, in _call_with_frames_removed
  File "/home/taoshu/tzb_databrain/engine/db_engine/db_engine/urls.py", line 20, in <module>
    from db_engine import component, hive_reader, io, robotx_spark, xml, executor, self_defined_feature, feature_combine, \
  File "/home/taoshu/tzb_databrain/engine/db_engine/db_engine/component.py", line 11, in <module>
    from executor.components.RobotXSpark import RobotXSpark
  File "/home/taoshu/tzb_databrain/engine/db_engine/executor/components/RobotXSpark.py", line 6, in <module>
    from F_SETTING import HDFS_URL
ImportError: cannot import name 'HDFS_URL'

During handling of the above exception, another exception occurred:

Traceback (most recent call last):
  File "/home/taoshu/anaconda3/lib/python3.5/site-packages/django/core/handlers/exception.py", line 41, in inner
    response = get_response(request)
  File "/home/taoshu/anaconda3/lib/python3.5/site-packages/django/utils/deprecation.py", line 140, in __call__
    response = self.get_response(request)
  File "/home/taoshu/anaconda3/lib/python3.5/site-packages/django/core/handlers/exception.py", line 43, in inner
    response = response_for_exception(request, exc)
  File "/home/taoshu/anaconda3/lib/python3.5/site-packages/django/core/handlers/exception.py", line 93, in response_for_exception
    response = handle_uncaught_exception(request, get_resolver(get_urlconf()), sys.exc_info())
  File "/home/taoshu/anaconda3/lib/python3.5/site-packages/django/core/handlers/exception.py", line 142, in handle_uncaught_exception
    callback, param_dict = resolver.resolve_error_handler(500)
  File "/home/taoshu/anaconda3/lib/python3.5/site-packages/django/urls/resolvers.py", line 418, in resolve_error_handler
    callback = getattr(self.urlconf_module, 'handler%s' % view_type, None)
  File "/home/taoshu/anaconda3/lib/python3.5/site-packages/django/utils/functional.py", line 35, in __get__
    res = instance.__dict__[self.name] = self.func(instance)
  File "/home/taoshu/anaconda3/lib/python3.5/site-packages/django/urls/resolvers.py", line 398, in urlconf_module
    return import_module(self.urlconf_name)
  File "/home/taoshu/anaconda3/lib/python3.5/importlib/__init__.py", line 126, in import_module
    return _bootstrap._gcd_import(name[level:], package, level)
  File "<frozen importlib._bootstrap>", line 986, in _gcd_import
  File "<frozen importlib._bootstrap>", line 969, in _find_and_load
  File "<frozen importlib._bootstrap>", line 958, in _find_and_load_unlocked
  File "<frozen importlib._bootstrap>", line 673, in _load_unlocked
  File "<frozen importlib._bootstrap_external>", line 662, in exec_module
  File "<frozen importlib._bootstrap>", line 222, in _call_with_frames_removed
  File "/home/taoshu/tzb_databrain/engine/db_engine/db_engine/urls.py", line 20, in <module>
    from db_engine import component, hive_reader, io, robotx_spark, xml, executor, self_defined_feature, feature_combine, \
  File "/home/taoshu/tzb_databrain/engine/db_engine/db_engine/component.py", line 11, in <module>
    from executor.components.RobotXSpark import RobotXSpark
  File "/home/taoshu/tzb_databrain/engine/db_engine/executor/components/RobotXSpark.py", line 6, in <module>
    from F_SETTING import HDFS_URL
ImportError: cannot import name 'HDFS_URL'
ERROR 2018-03-21 15:00:32,308 exception 2017 140483409185832 Internal Server Error: /mydata/list_table
Traceback (most recent call last):
  File "/home/taoshu/anaconda3/lib/python3.5/site-packages/django/core/handlers/exception.py", line 41, in inner
    response = get_response(request)
  File "/home/taoshu/anaconda3/lib/python3.5/site-packages/django/utils/deprecation.py", line 138, in __call__
    response = self.process_request(request)
  File "/home/taoshu/anaconda3/lib/python3.5/site-packages/django/middleware/common.py", line 62, in process_request
    if self.should_redirect_with_slash(request):
  File "/home/taoshu/anaconda3/lib/python3.5/site-packages/django/middleware/common.py", line 80, in should_redirect_with_slash
    not is_valid_path(request.path_info, urlconf) and
  File "/home/taoshu/anaconda3/lib/python3.5/site-packages/django/urls/base.py", line 158, in is_valid_path
    resolve(path, urlconf)
  File "/home/taoshu/anaconda3/lib/python3.5/site-packages/django/urls/base.py", line 27, in resolve
    return get_resolver(urlconf).resolve(path)
  File "/home/taoshu/anaconda3/lib/python3.5/site-packages/django/urls/resolvers.py", line 362, in resolve
    for pattern in self.url_patterns:
  File "/home/taoshu/anaconda3/lib/python3.5/site-packages/django/utils/functional.py", line 35, in __get__
    res = instance.__dict__[self.name] = self.func(instance)
  File "/home/taoshu/anaconda3/lib/python3.5/site-packages/django/urls/resolvers.py", line 405, in url_patterns
    patterns = getattr(self.urlconf_module, "urlpatterns", self.urlconf_module)
  File "/home/taoshu/anaconda3/lib/python3.5/site-packages/django/utils/functional.py", line 35, in __get__
    res = instance.__dict__[self.name] = self.func(instance)
  File "/home/taoshu/anaconda3/lib/python3.5/site-packages/django/urls/resolvers.py", line 398, in urlconf_module
    return import_module(self.urlconf_name)
  File "/home/taoshu/anaconda3/lib/python3.5/importlib/__init__.py", line 126, in import_module
    return _bootstrap._gcd_import(name[level:], package, level)
  File "<frozen importlib._bootstrap>", line 986, in _gcd_import
  File "<frozen importlib._bootstrap>", line 969, in _find_and_load
  File "<frozen importlib._bootstrap>", line 958, in _find_and_load_unlocked
  File "<frozen importlib._bootstrap>", line 673, in _load_unlocked
  File "<frozen importlib._bootstrap_external>", line 662, in exec_module
  File "<frozen importlib._bootstrap>", line 222, in _call_with_frames_removed
  File "/home/taoshu/tzb_databrain/engine/db_engine/db_engine/urls.py", line 20, in <module>
    from db_engine import component, hive_reader, io, robotx_spark, xml, executor, self_defined_feature, feature_combine, \
  File "/home/taoshu/tzb_databrain/engine/db_engine/db_engine/component.py", line 11, in <module>
    from executor.components.RobotXSpark import RobotXSpark
  File "/home/taoshu/tzb_databrain/engine/db_engine/executor/components/RobotXSpark.py", line 6, in <module>
    from F_SETTING import HDFS_URL
ImportError: cannot import name 'HDFS_URL'

During handling of the above exception, another exception occurred:

Traceback (most recent call last):
  File "/home/taoshu/anaconda3/lib/python3.5/site-packages/django/core/handlers/exception.py", line 41, in inner
    response = get_response(request)
  File "/home/taoshu/anaconda3/lib/python3.5/site-packages/django/utils/deprecation.py", line 140, in __call__
    response = self.get_response(request)
  File "/home/taoshu/anaconda3/lib/python3.5/site-packages/django/core/handlers/exception.py", line 43, in inner
    response = response_for_exception(request, exc)
  File "/home/taoshu/anaconda3/lib/python3.5/site-packages/django/core/handlers/exception.py", line 93, in response_for_exception
    response = handle_uncaught_exception(request, get_resolver(get_urlconf()), sys.exc_info())
  File "/home/taoshu/anaconda3/lib/python3.5/site-packages/django/core/handlers/exception.py", line 142, in handle_uncaught_exception
    callback, param_dict = resolver.resolve_error_handler(500)
  File "/home/taoshu/anaconda3/lib/python3.5/site-packages/django/urls/resolvers.py", line 418, in resolve_error_handler
    callback = getattr(self.urlconf_module, 'handler%s' % view_type, None)
  File "/home/taoshu/anaconda3/lib/python3.5/site-packages/django/utils/functional.py", line 35, in __get__
    res = instance.__dict__[self.name] = self.func(instance)
  File "/home/taoshu/anaconda3/lib/python3.5/site-packages/django/urls/resolvers.py", line 398, in urlconf_module
    return import_module(self.urlconf_name)
  File "/home/taoshu/anaconda3/lib/python3.5/importlib/__init__.py", line 126, in import_module
    return _bootstrap._gcd_import(name[level:], package, level)
  File "<frozen importlib._bootstrap>", line 986, in _gcd_import
  File "<frozen importlib._bootstrap>", line 969, in _find_and_load
  File "<frozen importlib._bootstrap>", line 958, in _find_and_load_unlocked
  File "<frozen importlib._bootstrap>", line 673, in _load_unlocked
  File "<frozen importlib._bootstrap_external>", line 662, in exec_module
  File "<frozen importlib._bootstrap>", line 222, in _call_with_frames_removed
  File "/home/taoshu/tzb_databrain/engine/db_engine/db_engine/urls.py", line 20, in <module>
    from db_engine import component, hive_reader, io, robotx_spark, xml, executor, self_defined_feature, feature_combine, \
  File "/home/taoshu/tzb_databrain/engine/db_engine/db_engine/component.py", line 11, in <module>
    from executor.components.RobotXSpark import RobotXSpark
  File "/home/taoshu/tzb_databrain/engine/db_engine/executor/components/RobotXSpark.py", line 6, in <module>
    from F_SETTING import HDFS_URL
ImportError: cannot import name 'HDFS_URL'

During handling of the above exception, another exception occurred:

Traceback (most recent call last):
  File "/home/taoshu/anaconda3/lib/python3.5/site-packages/django/core/handlers/exception.py", line 41, in inner
    response = get_response(request)
  File "/home/taoshu/anaconda3/lib/python3.5/site-packages/django/utils/deprecation.py", line 140, in __call__
    response = self.get_response(request)
  File "/home/taoshu/anaconda3/lib/python3.5/site-packages/django/core/handlers/exception.py", line 43, in inner
    response = response_for_exception(request, exc)
  File "/home/taoshu/anaconda3/lib/python3.5/site-packages/django/core/handlers/exception.py", line 93, in response_for_exception
    response = handle_uncaught_exception(request, get_resolver(get_urlconf()), sys.exc_info())
  File "/home/taoshu/anaconda3/lib/python3.5/site-packages/django/core/handlers/exception.py", line 142, in handle_uncaught_exception
    callback, param_dict = resolver.resolve_error_handler(500)
  File "/home/taoshu/anaconda3/lib/python3.5/site-packages/django/urls/resolvers.py", line 418, in resolve_error_handler
    callback = getattr(self.urlconf_module, 'handler%s' % view_type, None)
  File "/home/taoshu/anaconda3/lib/python3.5/site-packages/django/utils/functional.py", line 35, in __get__
    res = instance.__dict__[self.name] = self.func(instance)
  File "/home/taoshu/anaconda3/lib/python3.5/site-packages/django/urls/resolvers.py", line 398, in urlconf_module
    return import_module(self.urlconf_name)
  File "/home/taoshu/anaconda3/lib/python3.5/importlib/__init__.py", line 126, in import_module
    return _bootstrap._gcd_import(name[level:], package, level)
  File "<frozen importlib._bootstrap>", line 986, in _gcd_import
  File "<frozen importlib._bootstrap>", line 969, in _find_and_load
  File "<frozen importlib._bootstrap>", line 958, in _find_and_load_unlocked
  File "<frozen importlib._bootstrap>", line 673, in _load_unlocked
  File "<frozen importlib._bootstrap_external>", line 662, in exec_module
  File "<frozen importlib._bootstrap>", line 222, in _call_with_frames_removed
  File "/home/taoshu/tzb_databrain/engine/db_engine/db_engine/urls.py", line 20, in <module>
    from db_engine import component, hive_reader, io, robotx_spark, xml, executor, self_defined_feature, feature_combine, \
  File "/home/taoshu/tzb_databrain/engine/db_engine/db_engine/component.py", line 11, in <module>
    from executor.components.RobotXSpark import RobotXSpark
  File "/home/taoshu/tzb_databrain/engine/db_engine/executor/components/RobotXSpark.py", line 6, in <module>
    from F_SETTING import HDFS_URL
ImportError: cannot import name 'HDFS_URL'
ERROR 2018-03-21 15:00:32,311 exception 2017 140483409185832 Internal Server Error: /mydata/list_table
Traceback (most recent call last):
  File "/home/taoshu/anaconda3/lib/python3.5/site-packages/django/core/handlers/exception.py", line 41, in inner
    response = get_response(request)
  File "/home/taoshu/anaconda3/lib/python3.5/site-packages/django/utils/deprecation.py", line 138, in __call__
    response = self.process_request(request)
  File "/home/taoshu/anaconda3/lib/python3.5/site-packages/django/middleware/common.py", line 62, in process_request
    if self.should_redirect_with_slash(request):
  File "/home/taoshu/anaconda3/lib/python3.5/site-packages/django/middleware/common.py", line 80, in should_redirect_with_slash
    not is_valid_path(request.path_info, urlconf) and
  File "/home/taoshu/anaconda3/lib/python3.5/site-packages/django/urls/base.py", line 158, in is_valid_path
    resolve(path, urlconf)
  File "/home/taoshu/anaconda3/lib/python3.5/site-packages/django/urls/base.py", line 27, in resolve
    return get_resolver(urlconf).resolve(path)
  File "/home/taoshu/anaconda3/lib/python3.5/site-packages/django/urls/resolvers.py", line 362, in resolve
    for pattern in self.url_patterns:
  File "/home/taoshu/anaconda3/lib/python3.5/site-packages/django/utils/functional.py", line 35, in __get__
    res = instance.__dict__[self.name] = self.func(instance)
  File "/home/taoshu/anaconda3/lib/python3.5/site-packages/django/urls/resolvers.py", line 405, in url_patterns
    patterns = getattr(self.urlconf_module, "urlpatterns", self.urlconf_module)
  File "/home/taoshu/anaconda3/lib/python3.5/site-packages/django/utils/functional.py", line 35, in __get__
    res = instance.__dict__[self.name] = self.func(instance)
  File "/home/taoshu/anaconda3/lib/python3.5/site-packages/django/urls/resolvers.py", line 398, in urlconf_module
    return import_module(self.urlconf_name)
  File "/home/taoshu/anaconda3/lib/python3.5/importlib/__init__.py", line 126, in import_module
    return _bootstrap._gcd_import(name[level:], package, level)
  File "<frozen importlib._bootstrap>", line 986, in _gcd_import
  File "<frozen importlib._bootstrap>", line 969, in _find_and_load
  File "<frozen importlib._bootstrap>", line 958, in _find_and_load_unlocked
  File "<frozen importlib._bootstrap>", line 673, in _load_unlocked
  File "<frozen importlib._bootstrap_external>", line 662, in exec_module
  File "<frozen importlib._bootstrap>", line 222, in _call_with_frames_removed
  File "/home/taoshu/tzb_databrain/engine/db_engine/db_engine/urls.py", line 20, in <module>
    from db_engine import component, hive_reader, io, robotx_spark, xml, executor, self_defined_feature, feature_combine, \
  File "/home/taoshu/tzb_databrain/engine/db_engine/db_engine/component.py", line 11, in <module>
    from executor.components.RobotXSpark import RobotXSpark
  File "/home/taoshu/tzb_databrain/engine/db_engine/executor/components/RobotXSpark.py", line 6, in <module>
    from F_SETTING import HDFS_URL
ImportError: cannot import name 'HDFS_URL'

During handling of the above exception, another exception occurred:

Traceback (most recent call last):
  File "/home/taoshu/anaconda3/lib/python3.5/site-packages/django/core/handlers/exception.py", line 41, in inner
    response = get_response(request)
  File "/home/taoshu/anaconda3/lib/python3.5/site-packages/django/utils/deprecation.py", line 140, in __call__
    response = self.get_response(request)
  File "/home/taoshu/anaconda3/lib/python3.5/site-packages/django/core/handlers/exception.py", line 43, in inner
    response = response_for_exception(request, exc)
  File "/home/taoshu/anaconda3/lib/python3.5/site-packages/django/core/handlers/exception.py", line 93, in response_for_exception
    response = handle_uncaught_exception(request, get_resolver(get_urlconf()), sys.exc_info())
  File "/home/taoshu/anaconda3/lib/python3.5/site-packages/django/core/handlers/exception.py", line 142, in handle_uncaught_exception
    callback, param_dict = resolver.resolve_error_handler(500)
  File "/home/taoshu/anaconda3/lib/python3.5/site-packages/django/urls/resolvers.py", line 418, in resolve_error_handler
    callback = getattr(self.urlconf_module, 'handler%s' % view_type, None)
  File "/home/taoshu/anaconda3/lib/python3.5/site-packages/django/utils/functional.py", line 35, in __get__
    res = instance.__dict__[self.name] = self.func(instance)
  File "/home/taoshu/anaconda3/lib/python3.5/site-packages/django/urls/resolvers.py", line 398, in urlconf_module
    return import_module(self.urlconf_name)
  File "/home/taoshu/anaconda3/lib/python3.5/importlib/__init__.py", line 126, in import_module
    return _bootstrap._gcd_import(name[level:], package, level)
  File "<frozen importlib._bootstrap>", line 986, in _gcd_import
  File "<frozen importlib._bootstrap>", line 969, in _find_and_load
  File "<frozen importlib._bootstrap>", line 958, in _find_and_load_unlocked
  File "<frozen importlib._bootstrap>", line 673, in _load_unlocked
  File "<frozen importlib._bootstrap_external>", line 662, in exec_module
  File "<frozen importlib._bootstrap>", line 222, in _call_with_frames_removed
  File "/home/taoshu/tzb_databrain/engine/db_engine/db_engine/urls.py", line 20, in <module>
    from db_engine import component, hive_reader, io, robotx_spark, xml, executor, self_defined_feature, feature_combine, \
  File "/home/taoshu/tzb_databrain/engine/db_engine/db_engine/component.py", line 11, in <module>
    from executor.components.RobotXSpark import RobotXSpark
  File "/home/taoshu/tzb_databrain/engine/db_engine/executor/components/RobotXSpark.py", line 6, in <module>
    from F_SETTING import HDFS_URL
ImportError: cannot import name 'HDFS_URL'

During handling of the above exception, another exception occurred:

Traceback (most recent call last):
  File "/home/taoshu/anaconda3/lib/python3.5/site-packages/django/core/handlers/exception.py", line 41, in inner
    response = get_response(request)
  File "/home/taoshu/anaconda3/lib/python3.5/site-packages/django/utils/deprecation.py", line 140, in __call__
    response = self.get_response(request)
  File "/home/taoshu/anaconda3/lib/python3.5/site-packages/django/core/handlers/exception.py", line 43, in inner
    response = response_for_exception(request, exc)
  File "/home/taoshu/anaconda3/lib/python3.5/site-packages/django/core/handlers/exception.py", line 93, in response_for_exception
    response = handle_uncaught_exception(request, get_resolver(get_urlconf()), sys.exc_info())
  File "/home/taoshu/anaconda3/lib/python3.5/site-packages/django/core/handlers/exception.py", line 142, in handle_uncaught_exception
    callback, param_dict = resolver.resolve_error_handler(500)
  File "/home/taoshu/anaconda3/lib/python3.5/site-packages/django/urls/resolvers.py", line 418, in resolve_error_handler
    callback = getattr(self.urlconf_module, 'handler%s' % view_type, None)
  File "/home/taoshu/anaconda3/lib/python3.5/site-packages/django/utils/functional.py", line 35, in __get__
    res = instance.__dict__[self.name] = self.func(instance)
  File "/home/taoshu/anaconda3/lib/python3.5/site-packages/django/urls/resolvers.py", line 398, in urlconf_module
    return import_module(self.urlconf_name)
  File "/home/taoshu/anaconda3/lib/python3.5/importlib/__init__.py", line 126, in import_module
    return _bootstrap._gcd_import(name[level:], package, level)
  File "<frozen importlib._bootstrap>", line 986, in _gcd_import
  File "<frozen importlib._bootstrap>", line 969, in _find_and_load
  File "<frozen importlib._bootstrap>", line 958, in _find_and_load_unlocked
  File "<frozen importlib._bootstrap>", line 673, in _load_unlocked
  File "<frozen importlib._bootstrap_external>", line 662, in exec_module
  File "<frozen importlib._bootstrap>", line 222, in _call_with_frames_removed
  File "/home/taoshu/tzb_databrain/engine/db_engine/db_engine/urls.py", line 20, in <module>
    from db_engine import component, hive_reader, io, robotx_spark, xml, executor, self_defined_feature, feature_combine, \
  File "/home/taoshu/tzb_databrain/engine/db_engine/db_engine/component.py", line 11, in <module>
    from executor.components.RobotXSpark import RobotXSpark
  File "/home/taoshu/tzb_databrain/engine/db_engine/executor/components/RobotXSpark.py", line 6, in <module>
    from F_SETTING import HDFS_URL
ImportError: cannot import name 'HDFS_URL'

During handling of the above exception, another exception occurred:

Traceback (most recent call last):
  File "/home/taoshu/anaconda3/lib/python3.5/site-packages/django/core/handlers/exception.py", line 41, in inner
    response = get_response(request)
  File "/home/taoshu/anaconda3/lib/python3.5/site-packages/django/utils/deprecation.py", line 140, in __call__
    response = self.get_response(request)
  File "/home/taoshu/anaconda3/lib/python3.5/site-packages/django/core/handlers/exception.py", line 43, in inner
    response = response_for_exception(request, exc)
  File "/home/taoshu/anaconda3/lib/python3.5/site-packages/django/core/handlers/exception.py", line 93, in response_for_exception
    response = handle_uncaught_exception(request, get_resolver(get_urlconf()), sys.exc_info())
  File "/home/taoshu/anaconda3/lib/python3.5/site-packages/django/core/handlers/exception.py", line 142, in handle_uncaught_exception
    callback, param_dict = resolver.resolve_error_handler(500)
  File "/home/taoshu/anaconda3/lib/python3.5/site-packages/django/urls/resolvers.py", line 418, in resolve_error_handler
    callback = getattr(self.urlconf_module, 'handler%s' % view_type, None)
  File "/home/taoshu/anaconda3/lib/python3.5/site-packages/django/utils/functional.py", line 35, in __get__
    res = instance.__dict__[self.name] = self.func(instance)
  File "/home/taoshu/anaconda3/lib/python3.5/site-packages/django/urls/resolvers.py", line 398, in urlconf_module
    return import_module(self.urlconf_name)
  File "/home/taoshu/anaconda3/lib/python3.5/importlib/__init__.py", line 126, in import_module
    return _bootstrap._gcd_import(name[level:], package, level)
  File "<frozen importlib._bootstrap>", line 986, in _gcd_import
  File "<frozen importlib._bootstrap>", line 969, in _find_and_load
  File "<frozen importlib._bootstrap>", line 958, in _find_and_load_unlocked
  File "<frozen importlib._bootstrap>", line 673, in _load_unlocked
  File "<frozen importlib._bootstrap_external>", line 662, in exec_module
  File "<frozen importlib._bootstrap>", line 222, in _call_with_frames_removed
  File "/home/taoshu/tzb_databrain/engine/db_engine/db_engine/urls.py", line 20, in <module>
    from db_engine import component, hive_reader, io, robotx_spark, xml, executor, self_defined_feature, feature_combine, \
  File "/home/taoshu/tzb_databrain/engine/db_engine/db_engine/component.py", line 11, in <module>
    from executor.components.RobotXSpark import RobotXSpark
  File "/home/taoshu/tzb_databrain/engine/db_engine/executor/components/RobotXSpark.py", line 6, in <module>
    from F_SETTING import HDFS_URL
ImportError: cannot import name 'HDFS_URL'
ERROR 2018-03-21 15:00:32,780 exception 2017 140483409185832 Internal Server Error: /mydata/list_table
Traceback (most recent call last):
  File "/home/taoshu/anaconda3/lib/python3.5/site-packages/django/core/handlers/exception.py", line 41, in inner
    response = get_response(request)
  File "/home/taoshu/anaconda3/lib/python3.5/site-packages/django/utils/deprecation.py", line 138, in __call__
    response = self.process_request(request)
  File "/home/taoshu/anaconda3/lib/python3.5/site-packages/django/middleware/common.py", line 62, in process_request
    if self.should_redirect_with_slash(request):
  File "/home/taoshu/anaconda3/lib/python3.5/site-packages/django/middleware/common.py", line 80, in should_redirect_with_slash
    not is_valid_path(request.path_info, urlconf) and
  File "/home/taoshu/anaconda3/lib/python3.5/site-packages/django/urls/base.py", line 158, in is_valid_path
    resolve(path, urlconf)
  File "/home/taoshu/anaconda3/lib/python3.5/site-packages/django/urls/base.py", line 27, in resolve
    return get_resolver(urlconf).resolve(path)
  File "/home/taoshu/anaconda3/lib/python3.5/site-packages/django/urls/resolvers.py", line 362, in resolve
    for pattern in self.url_patterns:
  File "/home/taoshu/anaconda3/lib/python3.5/site-packages/django/utils/functional.py", line 35, in __get__
    res = instance.__dict__[self.name] = self.func(instance)
  File "/home/taoshu/anaconda3/lib/python3.5/site-packages/django/urls/resolvers.py", line 405, in url_patterns
    patterns = getattr(self.urlconf_module, "urlpatterns", self.urlconf_module)
  File "/home/taoshu/anaconda3/lib/python3.5/site-packages/django/utils/functional.py", line 35, in __get__
    res = instance.__dict__[self.name] = self.func(instance)
  File "/home/taoshu/anaconda3/lib/python3.5/site-packages/django/urls/resolvers.py", line 398, in urlconf_module
    return import_module(self.urlconf_name)
  File "/home/taoshu/anaconda3/lib/python3.5/importlib/__init__.py", line 126, in import_module
    return _bootstrap._gcd_import(name[level:], package, level)
  File "<frozen importlib._bootstrap>", line 986, in _gcd_import
  File "<frozen importlib._bootstrap>", line 969, in _find_and_load
  File "<frozen importlib._bootstrap>", line 958, in _find_and_load_unlocked
  File "<frozen importlib._bootstrap>", line 673, in _load_unlocked
  File "<frozen importlib._bootstrap_external>", line 662, in exec_module
  File "<frozen importlib._bootstrap>", line 222, in _call_with_frames_removed
  File "/home/taoshu/tzb_databrain/engine/db_engine/db_engine/urls.py", line 20, in <module>
    from db_engine import component, hive_reader, io, robotx_spark, xml, executor, self_defined_feature, feature_combine, \
  File "/home/taoshu/tzb_databrain/engine/db_engine/db_engine/component.py", line 11, in <module>
    from executor.components.RobotXSpark import RobotXSpark
  File "/home/taoshu/tzb_databrain/engine/db_engine/executor/components/RobotXSpark.py", line 6, in <module>
    from F_SETTING import HDFS_URL
ImportError: cannot import name 'HDFS_URL'
ERROR 2018-03-21 15:00:32,783 exception 2017 140483409185832 Internal Server Error: /mydata/list_table
Traceback (most recent call last):
  File "/home/taoshu/anaconda3/lib/python3.5/site-packages/django/core/handlers/exception.py", line 41, in inner
    response = get_response(request)
  File "/home/taoshu/anaconda3/lib/python3.5/site-packages/django/utils/deprecation.py", line 138, in __call__
    response = self.process_request(request)
  File "/home/taoshu/anaconda3/lib/python3.5/site-packages/django/middleware/common.py", line 62, in process_request
    if self.should_redirect_with_slash(request):
  File "/home/taoshu/anaconda3/lib/python3.5/site-packages/django/middleware/common.py", line 80, in should_redirect_with_slash
    not is_valid_path(request.path_info, urlconf) and
  File "/home/taoshu/anaconda3/lib/python3.5/site-packages/django/urls/base.py", line 158, in is_valid_path
    resolve(path, urlconf)
  File "/home/taoshu/anaconda3/lib/python3.5/site-packages/django/urls/base.py", line 27, in resolve
    return get_resolver(urlconf).resolve(path)
  File "/home/taoshu/anaconda3/lib/python3.5/site-packages/django/urls/resolvers.py", line 362, in resolve
    for pattern in self.url_patterns:
  File "/home/taoshu/anaconda3/lib/python3.5/site-packages/django/utils/functional.py", line 35, in __get__
    res = instance.__dict__[self.name] = self.func(instance)
  File "/home/taoshu/anaconda3/lib/python3.5/site-packages/django/urls/resolvers.py", line 405, in url_patterns
    patterns = getattr(self.urlconf_module, "urlpatterns", self.urlconf_module)
  File "/home/taoshu/anaconda3/lib/python3.5/site-packages/django/utils/functional.py", line 35, in __get__
    res = instance.__dict__[self.name] = self.func(instance)
  File "/home/taoshu/anaconda3/lib/python3.5/site-packages/django/urls/resolvers.py", line 398, in urlconf_module
    return import_module(self.urlconf_name)
  File "/home/taoshu/anaconda3/lib/python3.5/importlib/__init__.py", line 126, in import_module
    return _bootstrap._gcd_import(name[level:], package, level)
  File "<frozen importlib._bootstrap>", line 986, in _gcd_import
  File "<frozen importlib._bootstrap>", line 969, in _find_and_load
  File "<frozen importlib._bootstrap>", line 958, in _find_and_load_unlocked
  File "<frozen importlib._bootstrap>", line 673, in _load_unlocked
  File "<frozen importlib._bootstrap_external>", line 662, in exec_module
  File "<frozen importlib._bootstrap>", line 222, in _call_with_frames_removed
  File "/home/taoshu/tzb_databrain/engine/db_engine/db_engine/urls.py", line 20, in <module>
    from db_engine import component, hive_reader, io, robotx_spark, xml, executor, self_defined_feature, feature_combine, \
  File "/home/taoshu/tzb_databrain/engine/db_engine/db_engine/component.py", line 11, in <module>
    from executor.components.RobotXSpark import RobotXSpark
  File "/home/taoshu/tzb_databrain/engine/db_engine/executor/components/RobotXSpark.py", line 6, in <module>
    from F_SETTING import HDFS_URL
ImportError: cannot import name 'HDFS_URL'

During handling of the above exception, another exception occurred:

Traceback (most recent call last):
  File "/home/taoshu/anaconda3/lib/python3.5/site-packages/django/core/handlers/exception.py", line 41, in inner
    response = get_response(request)
  File "/home/taoshu/anaconda3/lib/python3.5/site-packages/django/utils/deprecation.py", line 140, in __call__
    response = self.get_response(request)
  File "/home/taoshu/anaconda3/lib/python3.5/site-packages/django/core/handlers/exception.py", line 43, in inner
    response = response_for_exception(request, exc)
  File "/home/taoshu/anaconda3/lib/python3.5/site-packages/django/core/handlers/exception.py", line 93, in response_for_exception
    response = handle_uncaught_exception(request, get_resolver(get_urlconf()), sys.exc_info())
  File "/home/taoshu/anaconda3/lib/python3.5/site-packages/django/core/handlers/exception.py", line 142, in handle_uncaught_exception
    callback, param_dict = resolver.resolve_error_handler(500)
  File "/home/taoshu/anaconda3/lib/python3.5/site-packages/django/urls/resolvers.py", line 418, in resolve_error_handler
    callback = getattr(self.urlconf_module, 'handler%s' % view_type, None)
  File "/home/taoshu/anaconda3/lib/python3.5/site-packages/django/utils/functional.py", line 35, in __get__
    res = instance.__dict__[self.name] = self.func(instance)
  File "/home/taoshu/anaconda3/lib/python3.5/site-packages/django/urls/resolvers.py", line 398, in urlconf_module
    return import_module(self.urlconf_name)
  File "/home/taoshu/anaconda3/lib/python3.5/importlib/__init__.py", line 126, in import_module
    return _bootstrap._gcd_import(name[level:], package, level)
  File "<frozen importlib._bootstrap>", line 986, in _gcd_import
  File "<frozen importlib._bootstrap>", line 969, in _find_and_load
  File "<frozen importlib._bootstrap>", line 958, in _find_and_load_unlocked
  File "<frozen importlib._bootstrap>", line 673, in _load_unlocked
  File "<frozen importlib._bootstrap_external>", line 662, in exec_module
  File "<frozen importlib._bootstrap>", line 222, in _call_with_frames_removed
  File "/home/taoshu/tzb_databrain/engine/db_engine/db_engine/urls.py", line 20, in <module>
    from db_engine import component, hive_reader, io, robotx_spark, xml, executor, self_defined_feature, feature_combine, \
  File "/home/taoshu/tzb_databrain/engine/db_engine/db_engine/component.py", line 11, in <module>
    from executor.components.RobotXSpark import RobotXSpark
  File "/home/taoshu/tzb_databrain/engine/db_engine/executor/components/RobotXSpark.py", line 6, in <module>
    from F_SETTING import HDFS_URL
ImportError: cannot import name 'HDFS_URL'
ERROR 2018-03-21 15:00:32,786 exception 2017 140483409185832 Internal Server Error: /mydata/list_table
Traceback (most recent call last):
  File "/home/taoshu/anaconda3/lib/python3.5/site-packages/django/core/handlers/exception.py", line 41, in inner
    response = get_response(request)
  File "/home/taoshu/anaconda3/lib/python3.5/site-packages/django/utils/deprecation.py", line 138, in __call__
    response = self.process_request(request)
  File "/home/taoshu/anaconda3/lib/python3.5/site-packages/django/middleware/common.py", line 62, in process_request
    if self.should_redirect_with_slash(request):
  File "/home/taoshu/anaconda3/lib/python3.5/site-packages/django/middleware/common.py", line 80, in should_redirect_with_slash
    not is_valid_path(request.path_info, urlconf) and
  File "/home/taoshu/anaconda3/lib/python3.5/site-packages/django/urls/base.py", line 158, in is_valid_path
    resolve(path, urlconf)
  File "/home/taoshu/anaconda3/lib/python3.5/site-packages/django/urls/base.py", line 27, in resolve
    return get_resolver(urlconf).resolve(path)
  File "/home/taoshu/anaconda3/lib/python3.5/site-packages/django/urls/resolvers.py", line 362, in resolve
    for pattern in self.url_patterns:
  File "/home/taoshu/anaconda3/lib/python3.5/site-packages/django/utils/functional.py", line 35, in __get__
    res = instance.__dict__[self.name] = self.func(instance)
  File "/home/taoshu/anaconda3/lib/python3.5/site-packages/django/urls/resolvers.py", line 405, in url_patterns
    patterns = getattr(self.urlconf_module, "urlpatterns", self.urlconf_module)
  File "/home/taoshu/anaconda3/lib/python3.5/site-packages/django/utils/functional.py", line 35, in __get__
    res = instance.__dict__[self.name] = self.func(instance)
  File "/home/taoshu/anaconda3/lib/python3.5/site-packages/django/urls/resolvers.py", line 398, in urlconf_module
    return import_module(self.urlconf_name)
  File "/home/taoshu/anaconda3/lib/python3.5/importlib/__init__.py", line 126, in import_module
    return _bootstrap._gcd_import(name[level:], package, level)
  File "<frozen importlib._bootstrap>", line 986, in _gcd_import
  File "<frozen importlib._bootstrap>", line 969, in _find_and_load
  File "<frozen importlib._bootstrap>", line 958, in _find_and_load_unlocked
  File "<frozen importlib._bootstrap>", line 673, in _load_unlocked
  File "<frozen importlib._bootstrap_external>", line 662, in exec_module
  File "<frozen importlib._bootstrap>", line 222, in _call_with_frames_removed
  File "/home/taoshu/tzb_databrain/engine/db_engine/db_engine/urls.py", line 20, in <module>
    from db_engine import component, hive_reader, io, robotx_spark, xml, executor, self_defined_feature, feature_combine, \
  File "/home/taoshu/tzb_databrain/engine/db_engine/db_engine/component.py", line 11, in <module>
    from executor.components.RobotXSpark import RobotXSpark
  File "/home/taoshu/tzb_databrain/engine/db_engine/executor/components/RobotXSpark.py", line 6, in <module>
    from F_SETTING import HDFS_URL
ImportError: cannot import name 'HDFS_URL'

During handling of the above exception, another exception occurred:

Traceback (most recent call last):
  File "/home/taoshu/anaconda3/lib/python3.5/site-packages/django/core/handlers/exception.py", line 41, in inner
    response = get_response(request)
  File "/home/taoshu/anaconda3/lib/python3.5/site-packages/django/utils/deprecation.py", line 140, in __call__
    response = self.get_response(request)
  File "/home/taoshu/anaconda3/lib/python3.5/site-packages/django/core/handlers/exception.py", line 43, in inner
    response = response_for_exception(request, exc)
  File "/home/taoshu/anaconda3/lib/python3.5/site-packages/django/core/handlers/exception.py", line 93, in response_for_exception
    response = handle_uncaught_exception(request, get_resolver(get_urlconf()), sys.exc_info())
  File "/home/taoshu/anaconda3/lib/python3.5/site-packages/django/core/handlers/exception.py", line 142, in handle_uncaught_exception
    callback, param_dict = resolver.resolve_error_handler(500)
  File "/home/taoshu/anaconda3/lib/python3.5/site-packages/django/urls/resolvers.py", line 418, in resolve_error_handler
    callback = getattr(self.urlconf_module, 'handler%s' % view_type, None)
  File "/home/taoshu/anaconda3/lib/python3.5/site-packages/django/utils/functional.py", line 35, in __get__
    res = instance.__dict__[self.name] = self.func(instance)
  File "/home/taoshu/anaconda3/lib/python3.5/site-packages/django/urls/resolvers.py", line 398, in urlconf_module
    return import_module(self.urlconf_name)
  File "/home/taoshu/anaconda3/lib/python3.5/importlib/__init__.py", line 126, in import_module
    return _bootstrap._gcd_import(name[level:], package, level)
  File "<frozen importlib._bootstrap>", line 986, in _gcd_import
  File "<frozen importlib._bootstrap>", line 969, in _find_and_load
  File "<frozen importlib._bootstrap>", line 958, in _find_and_load_unlocked
  File "<frozen importlib._bootstrap>", line 673, in _load_unlocked
  File "<frozen importlib._bootstrap_external>", line 662, in exec_module
  File "<frozen importlib._bootstrap>", line 222, in _call_with_frames_removed
  File "/home/taoshu/tzb_databrain/engine/db_engine/db_engine/urls.py", line 20, in <module>
    from db_engine import component, hive_reader, io, robotx_spark, xml, executor, self_defined_feature, feature_combine, \
  File "/home/taoshu/tzb_databrain/engine/db_engine/db_engine/component.py", line 11, in <module>
    from executor.components.RobotXSpark import RobotXSpark
  File "/home/taoshu/tzb_databrain/engine/db_engine/executor/components/RobotXSpark.py", line 6, in <module>
    from F_SETTING import HDFS_URL
ImportError: cannot import name 'HDFS_URL'

During handling of the above exception, another exception occurred:

Traceback (most recent call last):
  File "/home/taoshu/anaconda3/lib/python3.5/site-packages/django/core/handlers/exception.py", line 41, in inner
    response = get_response(request)
  File "/home/taoshu/anaconda3/lib/python3.5/site-packages/django/utils/deprecation.py", line 140, in __call__
    response = self.get_response(request)
  File "/home/taoshu/anaconda3/lib/python3.5/site-packages/django/core/handlers/exception.py", line 43, in inner
    response = response_for_exception(request, exc)
  File "/home/taoshu/anaconda3/lib/python3.5/site-packages/django/core/handlers/exception.py", line 93, in response_for_exception
    response = handle_uncaught_exception(request, get_resolver(get_urlconf()), sys.exc_info())
  File "/home/taoshu/anaconda3/lib/python3.5/site-packages/django/core/handlers/exception.py", line 142, in handle_uncaught_exception
    callback, param_dict = resolver.resolve_error_handler(500)
  File "/home/taoshu/anaconda3/lib/python3.5/site-packages/django/urls/resolvers.py", line 418, in resolve_error_handler
    callback = getattr(self.urlconf_module, 'handler%s' % view_type, None)
  File "/home/taoshu/anaconda3/lib/python3.5/site-packages/django/utils/functional.py", line 35, in __get__
    res = instance.__dict__[self.name] = self.func(instance)
  File "/home/taoshu/anaconda3/lib/python3.5/site-packages/django/urls/resolvers.py", line 398, in urlconf_module
    return import_module(self.urlconf_name)
  File "/home/taoshu/anaconda3/lib/python3.5/importlib/__init__.py", line 126, in import_module
    return _bootstrap._gcd_import(name[level:], package, level)
  File "<frozen importlib._bootstrap>", line 986, in _gcd_import
  File "<frozen importlib._bootstrap>", line 969, in _find_and_load
  File "<frozen importlib._bootstrap>", line 958, in _find_and_load_unlocked
  File "<frozen importlib._bootstrap>", line 673, in _load_unlocked
  File "<frozen importlib._bootstrap_external>", line 662, in exec_module
  File "<frozen importlib._bootstrap>", line 222, in _call_with_frames_removed
  File "/home/taoshu/tzb_databrain/engine/db_engine/db_engine/urls.py", line 20, in <module>
    from db_engine import component, hive_reader, io, robotx_spark, xml, executor, self_defined_feature, feature_combine, \
  File "/home/taoshu/tzb_databrain/engine/db_engine/db_engine/component.py", line 11, in <module>
    from executor.components.RobotXSpark import RobotXSpark
  File "/home/taoshu/tzb_databrain/engine/db_engine/executor/components/RobotXSpark.py", line 6, in <module>
    from F_SETTING import HDFS_URL
ImportError: cannot import name 'HDFS_URL'
ERROR 2018-03-21 15:00:32,789 exception 2017 140483409185832 Internal Server Error: /mydata/list_table
Traceback (most recent call last):
  File "/home/taoshu/anaconda3/lib/python3.5/site-packages/django/core/handlers/exception.py", line 41, in inner
    response = get_response(request)
  File "/home/taoshu/anaconda3/lib/python3.5/site-packages/django/utils/deprecation.py", line 138, in __call__
    response = self.process_request(request)
  File "/home/taoshu/anaconda3/lib/python3.5/site-packages/django/middleware/common.py", line 62, in process_request
    if self.should_redirect_with_slash(request):
  File "/home/taoshu/anaconda3/lib/python3.5/site-packages/django/middleware/common.py", line 80, in should_redirect_with_slash
    not is_valid_path(request.path_info, urlconf) and
  File "/home/taoshu/anaconda3/lib/python3.5/site-packages/django/urls/base.py", line 158, in is_valid_path
    resolve(path, urlconf)
  File "/home/taoshu/anaconda3/lib/python3.5/site-packages/django/urls/base.py", line 27, in resolve
    return get_resolver(urlconf).resolve(path)
  File "/home/taoshu/anaconda3/lib/python3.5/site-packages/django/urls/resolvers.py", line 362, in resolve
    for pattern in self.url_patterns:
  File "/home/taoshu/anaconda3/lib/python3.5/site-packages/django/utils/functional.py", line 35, in __get__
    res = instance.__dict__[self.name] = self.func(instance)
  File "/home/taoshu/anaconda3/lib/python3.5/site-packages/django/urls/resolvers.py", line 405, in url_patterns
    patterns = getattr(self.urlconf_module, "urlpatterns", self.urlconf_module)
  File "/home/taoshu/anaconda3/lib/python3.5/site-packages/django/utils/functional.py", line 35, in __get__
    res = instance.__dict__[self.name] = self.func(instance)
  File "/home/taoshu/anaconda3/lib/python3.5/site-packages/django/urls/resolvers.py", line 398, in urlconf_module
    return import_module(self.urlconf_name)
  File "/home/taoshu/anaconda3/lib/python3.5/importlib/__init__.py", line 126, in import_module
    return _bootstrap._gcd_import(name[level:], package, level)
  File "<frozen importlib._bootstrap>", line 986, in _gcd_import
  File "<frozen importlib._bootstrap>", line 969, in _find_and_load
  File "<frozen importlib._bootstrap>", line 958, in _find_and_load_unlocked
  File "<frozen importlib._bootstrap>", line 673, in _load_unlocked
  File "<frozen importlib._bootstrap_external>", line 662, in exec_module
  File "<frozen importlib._bootstrap>", line 222, in _call_with_frames_removed
  File "/home/taoshu/tzb_databrain/engine/db_engine/db_engine/urls.py", line 20, in <module>
    from db_engine import component, hive_reader, io, robotx_spark, xml, executor, self_defined_feature, feature_combine, \
  File "/home/taoshu/tzb_databrain/engine/db_engine/db_engine/component.py", line 11, in <module>
    from executor.components.RobotXSpark import RobotXSpark
  File "/home/taoshu/tzb_databrain/engine/db_engine/executor/components/RobotXSpark.py", line 6, in <module>
    from F_SETTING import HDFS_URL
ImportError: cannot import name 'HDFS_URL'

During handling of the above exception, another exception occurred:

Traceback (most recent call last):
  File "/home/taoshu/anaconda3/lib/python3.5/site-packages/django/core/handlers/exception.py", line 41, in inner
    response = get_response(request)
  File "/home/taoshu/anaconda3/lib/python3.5/site-packages/django/utils/deprecation.py", line 140, in __call__
    response = self.get_response(request)
  File "/home/taoshu/anaconda3/lib/python3.5/site-packages/django/core/handlers/exception.py", line 43, in inner
    response = response_for_exception(request, exc)
  File "/home/taoshu/anaconda3/lib/python3.5/site-packages/django/core/handlers/exception.py", line 93, in response_for_exception
    response = handle_uncaught_exception(request, get_resolver(get_urlconf()), sys.exc_info())
  File "/home/taoshu/anaconda3/lib/python3.5/site-packages/django/core/handlers/exception.py", line 142, in handle_uncaught_exception
    callback, param_dict = resolver.resolve_error_handler(500)
  File "/home/taoshu/anaconda3/lib/python3.5/site-packages/django/urls/resolvers.py", line 418, in resolve_error_handler
    callback = getattr(self.urlconf_module, 'handler%s' % view_type, None)
  File "/home/taoshu/anaconda3/lib/python3.5/site-packages/django/utils/functional.py", line 35, in __get__
    res = instance.__dict__[self.name] = self.func(instance)
  File "/home/taoshu/anaconda3/lib/python3.5/site-packages/django/urls/resolvers.py", line 398, in urlconf_module
    return import_module(self.urlconf_name)
  File "/home/taoshu/anaconda3/lib/python3.5/importlib/__init__.py", line 126, in import_module
    return _bootstrap._gcd_import(name[level:], package, level)
  File "<frozen importlib._bootstrap>", line 986, in _gcd_import
  File "<frozen importlib._bootstrap>", line 969, in _find_and_load
  File "<frozen importlib._bootstrap>", line 958, in _find_and_load_unlocked
  File "<frozen importlib._bootstrap>", line 673, in _load_unlocked
  File "<frozen importlib._bootstrap_external>", line 662, in exec_module
  File "<frozen importlib._bootstrap>", line 222, in _call_with_frames_removed
  File "/home/taoshu/tzb_databrain/engine/db_engine/db_engine/urls.py", line 20, in <module>
    from db_engine import component, hive_reader, io, robotx_spark, xml, executor, self_defined_feature, feature_combine, \
  File "/home/taoshu/tzb_databrain/engine/db_engine/db_engine/component.py", line 11, in <module>
    from executor.components.RobotXSpark import RobotXSpark
  File "/home/taoshu/tzb_databrain/engine/db_engine/executor/components/RobotXSpark.py", line 6, in <module>
    from F_SETTING import HDFS_URL
ImportError: cannot import name 'HDFS_URL'

During handling of the above exception, another exception occurred:

Traceback (most recent call last):
  File "/home/taoshu/anaconda3/lib/python3.5/site-packages/django/core/handlers/exception.py", line 41, in inner
    response = get_response(request)
  File "/home/taoshu/anaconda3/lib/python3.5/site-packages/django/utils/deprecation.py", line 140, in __call__
    response = self.get_response(request)
  File "/home/taoshu/anaconda3/lib/python3.5/site-packages/django/core/handlers/exception.py", line 43, in inner
    response = response_for_exception(request, exc)
  File "/home/taoshu/anaconda3/lib/python3.5/site-packages/django/core/handlers/exception.py", line 93, in response_for_exception
    response = handle_uncaught_exception(request, get_resolver(get_urlconf()), sys.exc_info())
  File "/home/taoshu/anaconda3/lib/python3.5/site-packages/django/core/handlers/exception.py", line 142, in handle_uncaught_exception
    callback, param_dict = resolver.resolve_error_handler(500)
  File "/home/taoshu/anaconda3/lib/python3.5/site-packages/django/urls/resolvers.py", line 418, in resolve_error_handler
    callback = getattr(self.urlconf_module, 'handler%s' % view_type, None)
  File "/home/taoshu/anaconda3/lib/python3.5/site-packages/django/utils/functional.py", line 35, in __get__
    res = instance.__dict__[self.name] = self.func(instance)
  File "/home/taoshu/anaconda3/lib/python3.5/site-packages/django/urls/resolvers.py", line 398, in urlconf_module
    return import_module(self.urlconf_name)
  File "/home/taoshu/anaconda3/lib/python3.5/importlib/__init__.py", line 126, in import_module
    return _bootstrap._gcd_import(name[level:], package, level)
  File "<frozen importlib._bootstrap>", line 986, in _gcd_import
  File "<frozen importlib._bootstrap>", line 969, in _find_and_load
  File "<frozen importlib._bootstrap>", line 958, in _find_and_load_unlocked
  File "<frozen importlib._bootstrap>", line 673, in _load_unlocked
  File "<frozen importlib._bootstrap_external>", line 662, in exec_module
  File "<frozen importlib._bootstrap>", line 222, in _call_with_frames_removed
  File "/home/taoshu/tzb_databrain/engine/db_engine/db_engine/urls.py", line 20, in <module>
    from db_engine import component, hive_reader, io, robotx_spark, xml, executor, self_defined_feature, feature_combine, \
  File "/home/taoshu/tzb_databrain/engine/db_engine/db_engine/component.py", line 11, in <module>
    from executor.components.RobotXSpark import RobotXSpark
  File "/home/taoshu/tzb_databrain/engine/db_engine/executor/components/RobotXSpark.py", line 6, in <module>
    from F_SETTING import HDFS_URL
ImportError: cannot import name 'HDFS_URL'

During handling of the above exception, another exception occurred:

Traceback (most recent call last):
  File "/home/taoshu/anaconda3/lib/python3.5/site-packages/django/core/handlers/exception.py", line 41, in inner
    response = get_response(request)
  File "/home/taoshu/anaconda3/lib/python3.5/site-packages/django/utils/deprecation.py", line 140, in __call__
    response = self.get_response(request)
  File "/home/taoshu/anaconda3/lib/python3.5/site-packages/django/core/handlers/exception.py", line 43, in inner
    response = response_for_exception(request, exc)
  File "/home/taoshu/anaconda3/lib/python3.5/site-packages/django/core/handlers/exception.py", line 93, in response_for_exception
    response = handle_uncaught_exception(request, get_resolver(get_urlconf()), sys.exc_info())
  File "/home/taoshu/anaconda3/lib/python3.5/site-packages/django/core/handlers/exception.py", line 142, in handle_uncaught_exception
    callback, param_dict = resolver.resolve_error_handler(500)
  File "/home/taoshu/anaconda3/lib/python3.5/site-packages/django/urls/resolvers.py", line 418, in resolve_error_handler
    callback = getattr(self.urlconf_module, 'handler%s' % view_type, None)
  File "/home/taoshu/anaconda3/lib/python3.5/site-packages/django/utils/functional.py", line 35, in __get__
    res = instance.__dict__[self.name] = self.func(instance)
  File "/home/taoshu/anaconda3/lib/python3.5/site-packages/django/urls/resolvers.py", line 398, in urlconf_module
    return import_module(self.urlconf_name)
  File "/home/taoshu/anaconda3/lib/python3.5/importlib/__init__.py", line 126, in import_module
    return _bootstrap._gcd_import(name[level:], package, level)
  File "<frozen importlib._bootstrap>", line 986, in _gcd_import
  File "<frozen importlib._bootstrap>", line 969, in _find_and_load
  File "<frozen importlib._bootstrap>", line 958, in _find_and_load_unlocked
  File "<frozen importlib._bootstrap>", line 673, in _load_unlocked
  File "<frozen importlib._bootstrap_external>", line 662, in exec_module
  File "<frozen importlib._bootstrap>", line 222, in _call_with_frames_removed
  File "/home/taoshu/tzb_databrain/engine/db_engine/db_engine/urls.py", line 20, in <module>
    from db_engine import component, hive_reader, io, robotx_spark, xml, executor, self_defined_feature, feature_combine, \
  File "/home/taoshu/tzb_databrain/engine/db_engine/db_engine/component.py", line 11, in <module>
    from executor.components.RobotXSpark import RobotXSpark
  File "/home/taoshu/tzb_databrain/engine/db_engine/executor/components/RobotXSpark.py", line 6, in <module>
    from F_SETTING import HDFS_URL
ImportError: cannot import name 'HDFS_URL'
ERROR 2018-03-21 15:13:17,379 exception 2456 140036845803368 Internal Server Error: /mydata/csv_into_hive
Traceback (most recent call last):
  File "/home/taoshu/anaconda3/lib/python3.5/site-packages/django/core/handlers/exception.py", line 41, in inner
    response = get_response(request)
  File "/home/taoshu/anaconda3/lib/python3.5/site-packages/django/core/handlers/base.py", line 187, in _get_response
    response = self.process_exception_by_middleware(e, request)
  File "/home/taoshu/anaconda3/lib/python3.5/site-packages/django/core/handlers/base.py", line 185, in _get_response
    response = wrapped_callback(request, *callback_args, **callback_kwargs)
  File "/home/taoshu/tzb_databrain/engine/db_engine/common/UTIL.py", line 47, in wrapper
    return func(*arg, **kwargs)
  File "/home/taoshu/tzb_databrain/engine/db_engine/db_engine/my_data.py", line 337, in csv_into_hive
    raise e
  File "/home/taoshu/tzb_databrain/engine/db_engine/db_engine/my_data.py", line 334, in csv_into_hive
    load_into_hive(hive_filename, new_csv_saving_path, hdfs_path, field_list)
  File "/home/taoshu/tzb_databrain/engine/db_engine/db_engine/my_data.py", line 113, in load_into_hive
    raise e
  File "/home/taoshu/tzb_databrain/engine/db_engine/db_engine/my_data.py", line 111, in load_into_hive
    func(table_name, csv_path, hdfs_path, ff)
  File "/home/taoshu/anaconda3/lib/python3.5/site-packages/py4j/java_gateway.py", line 1160, in __call__
    answer, self.gateway_client, self.target_id, self.name)
  File "/home/taoshu/anaconda3/lib/python3.5/site-packages/py4j/protocol.py", line 320, in get_return_value
    format(target_id, ".", name), value)
py4j.protocol.Py4JJavaError: An error occurred while calling o3031.uploadToHive.
: org.apache.hive.service.cli.HiveSQLException: Error while compiling statement: FAILED: SemanticException [Error 10036]: Duplicate column name: 1
	at org.apache.hive.jdbc.Utils.verifySuccess(Utils.java:231)
	at org.apache.hive.jdbc.Utils.verifySuccessWithInfo(Utils.java:217)
	at org.apache.hive.jdbc.HiveStatement.execute(HiveStatement.java:244)
	at com.taodatarobot.engine.py4j.hive.HiveUtil.uploadToHive(HiveUtil.java:297)
	at sun.reflect.NativeMethodAccessorImpl.invoke0(Native Method)
	at sun.reflect.NativeMethodAccessorImpl.invoke(NativeMethodAccessorImpl.java:62)
	at sun.reflect.DelegatingMethodAccessorImpl.invoke(DelegatingMethodAccessorImpl.java:43)
	at java.lang.reflect.Method.invoke(Method.java:498)
	at py4j.reflection.MethodInvoker.invoke(MethodInvoker.java:244)
	at py4j.reflection.ReflectionEngine.invoke(ReflectionEngine.java:357)
	at py4j.Gateway.invoke(Gateway.java:282)
	at py4j.commands.AbstractCommand.invokeMethod(AbstractCommand.java:132)
	at py4j.commands.CallCommand.execute(CallCommand.java:79)
	at py4j.GatewayConnection.run(GatewayConnection.java:214)
	at java.lang.Thread.run(Thread.java:748)
Caused by: org.apache.hive.service.cli.HiveSQLException: Error while compiling statement: FAILED: SemanticException [Error 10036]: Duplicate column name: 1
	at org.apache.hive.service.cli.operation.Operation.toSQLException(Operation.java:400)
	at org.apache.hive.service.cli.operation.SQLOperation.prepare(SQLOperation.java:187)
	at org.apache.hive.service.cli.operation.SQLOperation.runInternal(SQLOperation.java:271)
	at org.apache.hive.service.cli.operation.Operation.run(Operation.java:337)
	at org.apache.hive.service.cli.session.HiveSessionImpl.executeStatementInternal(HiveSessionImpl.java:439)
	at org.apache.hive.service.cli.session.HiveSessionImpl.executeStatementAsync(HiveSessionImpl.java:416)
	at sun.reflect.GeneratedMethodAccessor24.invoke(Unknown Source)
	at sun.reflect.DelegatingMethodAccessorImpl.invoke(DelegatingMethodAccessorImpl.java:43)
	at java.lang.reflect.Method.invoke(Method.java:498)
	at org.apache.hive.service.cli.session.HiveSessionProxy.invoke(HiveSessionProxy.java:78)
	at org.apache.hive.service.cli.session.HiveSessionProxy.access$000(HiveSessionProxy.java:36)
	at org.apache.hive.service.cli.session.HiveSessionProxy$1.run(HiveSessionProxy.java:63)
	at java.security.AccessController.doPrivileged(Native Method)
	at javax.security.auth.Subject.doAs(Subject.java:422)
	at org.apache.hadoop.security.UserGroupInformation.doAs(UserGroupInformation.java:1917)
	at org.apache.hive.service.cli.session.HiveSessionProxy.invoke(HiveSessionProxy.java:59)
	at com.sun.proxy.$Proxy22.executeStatementAsync(Unknown Source)
	at org.apache.hive.service.cli.CLIService.executeStatementAsync(CLIService.java:282)
	at org.apache.hive.service.cli.thrift.ThriftCLIService.ExecuteStatement(ThriftCLIService.java:501)
	at org.apache.hive.service.cli.thrift.TCLIService$Processor$ExecuteStatement.getResult(TCLIService.java:1313)
	at org.apache.hive.service.cli.thrift.TCLIService$Processor$ExecuteStatement.getResult(TCLIService.java:1298)
	at org.apache.thrift.ProcessFunction.process(ProcessFunction.java:39)
	at org.apache.thrift.TBaseProcessor.process(TBaseProcessor.java:39)
	at org.apache.hive.service.auth.TSetIpAddressProcessor.process(TSetIpAddressProcessor.java:56)
	at org.apache.thrift.server.TThreadPoolServer$WorkerProcess.run(TThreadPoolServer.java:286)
	at java.util.concurrent.ThreadPoolExecutor.runWorker(ThreadPoolExecutor.java:1142)
	at java.util.concurrent.ThreadPoolExecutor$Worker.run(ThreadPoolExecutor.java:617)
	at java.lang.Thread.run(Thread.java:745)
Caused by: java.lang.RuntimeException: org.apache.hadoop.hive.ql.parse.SemanticException:Duplicate column name: 1
	at org.apache.hadoop.hive.ql.parse.ParseUtils.validateColumnNameUniqueness(ParseUtils.java:100)
	at org.apache.hadoop.hive.ql.plan.CreateTableDesc.validate(CreateTableDesc.java:435)
	at org.apache.hadoop.hive.ql.parse.SemanticAnalyzer.analyzeCreateTable(SemanticAnalyzer.java:11077)
	at org.apache.hadoop.hive.ql.parse.SemanticAnalyzer.genResolvedParseTree(SemanticAnalyzer.java:10142)
	at org.apache.hadoop.hive.ql.parse.SemanticAnalyzer.analyzeInternal(SemanticAnalyzer.java:10223)
	at org.apache.hadoop.hive.ql.parse.SemanticAnalyzer.analyzeInternal(SemanticAnalyzer.java:10108)
	at org.apache.hadoop.hive.ql.parse.BaseSemanticAnalyzer.analyze(BaseSemanticAnalyzer.java:223)
	at org.apache.hadoop.hive.ql.Driver.compile(Driver.java:558)
	at org.apache.hadoop.hive.ql.Driver.compileInternal(Driver.java:1356)
	at org.apache.hadoop.hive.ql.Driver.compileAndRespond(Driver.java:1343)
	at org.apache.hive.service.cli.operation.SQLOperation.prepare(SQLOperation.java:185)
	... 26 more

ERROR 2018-03-21 15:23:02,597 exception 2456 140036845803368 Internal Server Error: /mydata/csv_into_hive
Traceback (most recent call last):
  File "/home/taoshu/anaconda3/lib/python3.5/site-packages/django/core/handlers/exception.py", line 41, in inner
    response = get_response(request)
  File "/home/taoshu/anaconda3/lib/python3.5/site-packages/django/core/handlers/base.py", line 187, in _get_response
    response = self.process_exception_by_middleware(e, request)
  File "/home/taoshu/anaconda3/lib/python3.5/site-packages/django/core/handlers/base.py", line 185, in _get_response
    response = wrapped_callback(request, *callback_args, **callback_kwargs)
  File "/home/taoshu/tzb_databrain/engine/db_engine/common/UTIL.py", line 47, in wrapper
    return func(*arg, **kwargs)
  File "/home/taoshu/tzb_databrain/engine/db_engine/db_engine/my_data.py", line 337, in csv_into_hive
    raise e
  File "/home/taoshu/tzb_databrain/engine/db_engine/db_engine/my_data.py", line 334, in csv_into_hive
    load_into_hive(hive_filename, new_csv_saving_path, hdfs_path, field_list)
  File "/home/taoshu/tzb_databrain/engine/db_engine/db_engine/my_data.py", line 113, in load_into_hive
    raise e
  File "/home/taoshu/tzb_databrain/engine/db_engine/db_engine/my_data.py", line 111, in load_into_hive
    func(table_name, csv_path, hdfs_path, ff)
  File "/home/taoshu/anaconda3/lib/python3.5/site-packages/py4j/java_gateway.py", line 1160, in __call__
    answer, self.gateway_client, self.target_id, self.name)
  File "/home/taoshu/anaconda3/lib/python3.5/site-packages/py4j/protocol.py", line 320, in get_return_value
    format(target_id, ".", name), value)
py4j.protocol.Py4JJavaError: An error occurred while calling o3048.uploadToHive.
: org.apache.hive.service.cli.HiveSQLException: Error while compiling statement: FAILED: SemanticException [Error 10036]: Duplicate column name: 1
	at org.apache.hive.jdbc.Utils.verifySuccess(Utils.java:231)
	at org.apache.hive.jdbc.Utils.verifySuccessWithInfo(Utils.java:217)
	at org.apache.hive.jdbc.HiveStatement.execute(HiveStatement.java:244)
	at com.taodatarobot.engine.py4j.hive.HiveUtil.uploadToHive(HiveUtil.java:297)
	at sun.reflect.NativeMethodAccessorImpl.invoke0(Native Method)
	at sun.reflect.NativeMethodAccessorImpl.invoke(NativeMethodAccessorImpl.java:62)
	at sun.reflect.DelegatingMethodAccessorImpl.invoke(DelegatingMethodAccessorImpl.java:43)
	at java.lang.reflect.Method.invoke(Method.java:498)
	at py4j.reflection.MethodInvoker.invoke(MethodInvoker.java:244)
	at py4j.reflection.ReflectionEngine.invoke(ReflectionEngine.java:357)
	at py4j.Gateway.invoke(Gateway.java:282)
	at py4j.commands.AbstractCommand.invokeMethod(AbstractCommand.java:132)
	at py4j.commands.CallCommand.execute(CallCommand.java:79)
	at py4j.GatewayConnection.run(GatewayConnection.java:214)
	at java.lang.Thread.run(Thread.java:748)
Caused by: org.apache.hive.service.cli.HiveSQLException: Error while compiling statement: FAILED: SemanticException [Error 10036]: Duplicate column name: 1
	at org.apache.hive.service.cli.operation.Operation.toSQLException(Operation.java:400)
	at org.apache.hive.service.cli.operation.SQLOperation.prepare(SQLOperation.java:187)
	at org.apache.hive.service.cli.operation.SQLOperation.runInternal(SQLOperation.java:271)
	at org.apache.hive.service.cli.operation.Operation.run(Operation.java:337)
	at org.apache.hive.service.cli.session.HiveSessionImpl.executeStatementInternal(HiveSessionImpl.java:439)
	at org.apache.hive.service.cli.session.HiveSessionImpl.executeStatementAsync(HiveSessionImpl.java:416)
	at sun.reflect.GeneratedMethodAccessor24.invoke(Unknown Source)
	at sun.reflect.DelegatingMethodAccessorImpl.invoke(DelegatingMethodAccessorImpl.java:43)
	at java.lang.reflect.Method.invoke(Method.java:498)
	at org.apache.hive.service.cli.session.HiveSessionProxy.invoke(HiveSessionProxy.java:78)
	at org.apache.hive.service.cli.session.HiveSessionProxy.access$000(HiveSessionProxy.java:36)
	at org.apache.hive.service.cli.session.HiveSessionProxy$1.run(HiveSessionProxy.java:63)
	at java.security.AccessController.doPrivileged(Native Method)
	at javax.security.auth.Subject.doAs(Subject.java:422)
	at org.apache.hadoop.security.UserGroupInformation.doAs(UserGroupInformation.java:1917)
	at org.apache.hive.service.cli.session.HiveSessionProxy.invoke(HiveSessionProxy.java:59)
	at com.sun.proxy.$Proxy22.executeStatementAsync(Unknown Source)
	at org.apache.hive.service.cli.CLIService.executeStatementAsync(CLIService.java:282)
	at org.apache.hive.service.cli.thrift.ThriftCLIService.ExecuteStatement(ThriftCLIService.java:501)
	at org.apache.hive.service.cli.thrift.TCLIService$Processor$ExecuteStatement.getResult(TCLIService.java:1313)
	at org.apache.hive.service.cli.thrift.TCLIService$Processor$ExecuteStatement.getResult(TCLIService.java:1298)
	at org.apache.thrift.ProcessFunction.process(ProcessFunction.java:39)
	at org.apache.thrift.TBaseProcessor.process(TBaseProcessor.java:39)
	at org.apache.hive.service.auth.TSetIpAddressProcessor.process(TSetIpAddressProcessor.java:56)
	at org.apache.thrift.server.TThreadPoolServer$WorkerProcess.run(TThreadPoolServer.java:286)
	at java.util.concurrent.ThreadPoolExecutor.runWorker(ThreadPoolExecutor.java:1142)
	at java.util.concurrent.ThreadPoolExecutor$Worker.run(ThreadPoolExecutor.java:617)
	at java.lang.Thread.run(Thread.java:745)
Caused by: java.lang.RuntimeException: org.apache.hadoop.hive.ql.parse.SemanticException:Duplicate column name: 1
	at org.apache.hadoop.hive.ql.parse.ParseUtils.validateColumnNameUniqueness(ParseUtils.java:100)
	at org.apache.hadoop.hive.ql.plan.CreateTableDesc.validate(CreateTableDesc.java:435)
	at org.apache.hadoop.hive.ql.parse.SemanticAnalyzer.analyzeCreateTable(SemanticAnalyzer.java:11077)
	at org.apache.hadoop.hive.ql.parse.SemanticAnalyzer.genResolvedParseTree(SemanticAnalyzer.java:10142)
	at org.apache.hadoop.hive.ql.parse.SemanticAnalyzer.analyzeInternal(SemanticAnalyzer.java:10223)
	at org.apache.hadoop.hive.ql.parse.SemanticAnalyzer.analyzeInternal(SemanticAnalyzer.java:10108)
	at org.apache.hadoop.hive.ql.parse.BaseSemanticAnalyzer.analyze(BaseSemanticAnalyzer.java:223)
	at org.apache.hadoop.hive.ql.Driver.compile(Driver.java:558)
	at org.apache.hadoop.hive.ql.Driver.compileInternal(Driver.java:1356)
	at org.apache.hadoop.hive.ql.Driver.compileAndRespond(Driver.java:1343)
	at org.apache.hive.service.cli.operation.SQLOperation.prepare(SQLOperation.java:185)
	... 26 more

ERROR 2018-03-21 15:31:18,082 exception 3200 140626552006048 Internal Server Error: /mydata/csv_into_hive
Traceback (most recent call last):
  File "/home/taoshu/anaconda3/lib/python3.5/site-packages/django/core/handlers/exception.py", line 41, in inner
    response = get_response(request)
  File "/home/taoshu/anaconda3/lib/python3.5/site-packages/django/core/handlers/base.py", line 187, in _get_response
    response = self.process_exception_by_middleware(e, request)
  File "/home/taoshu/anaconda3/lib/python3.5/site-packages/django/core/handlers/base.py", line 185, in _get_response
    response = wrapped_callback(request, *callback_args, **callback_kwargs)
  File "/home/taoshu/tzb_databrain/engine/db_engine/common/UTIL.py", line 47, in wrapper
    return func(*arg, **kwargs)
  File "/home/taoshu/tzb_databrain/engine/db_engine/db_engine/my_data.py", line 335, in csv_into_hive
    raise e
  File "/home/taoshu/tzb_databrain/engine/db_engine/db_engine/my_data.py", line 332, in csv_into_hive
    load_into_hive(hive_filename, new_csv_saving_path, hdfs_path, field_list)
  File "/home/taoshu/tzb_databrain/engine/db_engine/db_engine/my_data.py", line 114, in load_into_hive
    raise e
  File "/home/taoshu/tzb_databrain/engine/db_engine/db_engine/my_data.py", line 112, in load_into_hive
    func(table_name, csv_path, hdfs_path, ff)
  File "/home/taoshu/anaconda3/lib/python3.5/site-packages/py4j/java_gateway.py", line 1160, in __call__
    answer, self.gateway_client, self.target_id, self.name)
  File "/home/taoshu/anaconda3/lib/python3.5/site-packages/py4j/protocol.py", line 320, in get_return_value
    format(target_id, ".", name), value)
py4j.protocol.Py4JJavaError: An error occurred while calling o3059.uploadToHive.
: org.apache.hive.service.cli.HiveSQLException: Error while compiling statement: FAILED: SemanticException [Error 10036]: Duplicate column name: 1
	at org.apache.hive.jdbc.Utils.verifySuccess(Utils.java:231)
	at org.apache.hive.jdbc.Utils.verifySuccessWithInfo(Utils.java:217)
	at org.apache.hive.jdbc.HiveStatement.execute(HiveStatement.java:244)
	at com.taodatarobot.engine.py4j.hive.HiveUtil.uploadToHive(HiveUtil.java:297)
	at sun.reflect.NativeMethodAccessorImpl.invoke0(Native Method)
	at sun.reflect.NativeMethodAccessorImpl.invoke(NativeMethodAccessorImpl.java:62)
	at sun.reflect.DelegatingMethodAccessorImpl.invoke(DelegatingMethodAccessorImpl.java:43)
	at java.lang.reflect.Method.invoke(Method.java:498)
	at py4j.reflection.MethodInvoker.invoke(MethodInvoker.java:244)
	at py4j.reflection.ReflectionEngine.invoke(ReflectionEngine.java:357)
	at py4j.Gateway.invoke(Gateway.java:282)
	at py4j.commands.AbstractCommand.invokeMethod(AbstractCommand.java:132)
	at py4j.commands.CallCommand.execute(CallCommand.java:79)
	at py4j.GatewayConnection.run(GatewayConnection.java:214)
	at java.lang.Thread.run(Thread.java:748)
Caused by: org.apache.hive.service.cli.HiveSQLException: Error while compiling statement: FAILED: SemanticException [Error 10036]: Duplicate column name: 1
	at org.apache.hive.service.cli.operation.Operation.toSQLException(Operation.java:400)
	at org.apache.hive.service.cli.operation.SQLOperation.prepare(SQLOperation.java:187)
	at org.apache.hive.service.cli.operation.SQLOperation.runInternal(SQLOperation.java:271)
	at org.apache.hive.service.cli.operation.Operation.run(Operation.java:337)
	at org.apache.hive.service.cli.session.HiveSessionImpl.executeStatementInternal(HiveSessionImpl.java:439)
	at org.apache.hive.service.cli.session.HiveSessionImpl.executeStatementAsync(HiveSessionImpl.java:416)
	at sun.reflect.GeneratedMethodAccessor24.invoke(Unknown Source)
	at sun.reflect.DelegatingMethodAccessorImpl.invoke(DelegatingMethodAccessorImpl.java:43)
	at java.lang.reflect.Method.invoke(Method.java:498)
	at org.apache.hive.service.cli.session.HiveSessionProxy.invoke(HiveSessionProxy.java:78)
	at org.apache.hive.service.cli.session.HiveSessionProxy.access$000(HiveSessionProxy.java:36)
	at org.apache.hive.service.cli.session.HiveSessionProxy$1.run(HiveSessionProxy.java:63)
	at java.security.AccessController.doPrivileged(Native Method)
	at javax.security.auth.Subject.doAs(Subject.java:422)
	at org.apache.hadoop.security.UserGroupInformation.doAs(UserGroupInformation.java:1917)
	at org.apache.hive.service.cli.session.HiveSessionProxy.invoke(HiveSessionProxy.java:59)
	at com.sun.proxy.$Proxy22.executeStatementAsync(Unknown Source)
	at org.apache.hive.service.cli.CLIService.executeStatementAsync(CLIService.java:282)
	at org.apache.hive.service.cli.thrift.ThriftCLIService.ExecuteStatement(ThriftCLIService.java:501)
	at org.apache.hive.service.cli.thrift.TCLIService$Processor$ExecuteStatement.getResult(TCLIService.java:1313)
	at org.apache.hive.service.cli.thrift.TCLIService$Processor$ExecuteStatement.getResult(TCLIService.java:1298)
	at org.apache.thrift.ProcessFunction.process(ProcessFunction.java:39)
	at org.apache.thrift.TBaseProcessor.process(TBaseProcessor.java:39)
	at org.apache.hive.service.auth.TSetIpAddressProcessor.process(TSetIpAddressProcessor.java:56)
	at org.apache.thrift.server.TThreadPoolServer$WorkerProcess.run(TThreadPoolServer.java:286)
	at java.util.concurrent.ThreadPoolExecutor.runWorker(ThreadPoolExecutor.java:1142)
	at java.util.concurrent.ThreadPoolExecutor$Worker.run(ThreadPoolExecutor.java:617)
	at java.lang.Thread.run(Thread.java:745)
Caused by: java.lang.RuntimeException: org.apache.hadoop.hive.ql.parse.SemanticException:Duplicate column name: 1
	at org.apache.hadoop.hive.ql.parse.ParseUtils.validateColumnNameUniqueness(ParseUtils.java:100)
	at org.apache.hadoop.hive.ql.plan.CreateTableDesc.validate(CreateTableDesc.java:435)
	at org.apache.hadoop.hive.ql.parse.SemanticAnalyzer.analyzeCreateTable(SemanticAnalyzer.java:11077)
	at org.apache.hadoop.hive.ql.parse.SemanticAnalyzer.genResolvedParseTree(SemanticAnalyzer.java:10142)
	at org.apache.hadoop.hive.ql.parse.SemanticAnalyzer.analyzeInternal(SemanticAnalyzer.java:10223)
	at org.apache.hadoop.hive.ql.parse.SemanticAnalyzer.analyzeInternal(SemanticAnalyzer.java:10108)
	at org.apache.hadoop.hive.ql.parse.BaseSemanticAnalyzer.analyze(BaseSemanticAnalyzer.java:223)
	at org.apache.hadoop.hive.ql.Driver.compile(Driver.java:558)
	at org.apache.hadoop.hive.ql.Driver.compileInternal(Driver.java:1356)
	at org.apache.hadoop.hive.ql.Driver.compileAndRespond(Driver.java:1343)
	at org.apache.hive.service.cli.operation.SQLOperation.prepare(SQLOperation.java:185)
	... 26 more

